Workbook
Name cursos: '[1]Lista 1ºP - 6ºP'!$BG$3:$BH$20

Sheet RECIBO INGRESOS
D2: RECIBO DE CAJA | F2: No. | H2: {=MAX(('FLUJO DE CAJA'!D:D<>0)*ROW(('FLUJO DE CAJA'!D:D)))-1} -> 2
D4: INGRESOS | F4: Bs.(Efect.) | H4: 2341.56 | P4: BUSCAR CODIGO POR APELLIDO
E5: t.c. (6,97) | F5: Bs.(Tr.-QR) | P5: APELLIDO
B6: Hemos recibido de : | C6: Rafucho Rafuchin | E6: CODIGO | F6: $us. | P6: Galindo Puña Sara
E7: 2018088 | F7: PENSIONES | P7: CODIGO
B8: La suma de : | C8: {=IF(H4="", IF(H5="",IF(H6="","",[2]!cMoneda2(H6,"DOLAR AMERICANO","DOLARES AMERICANOS",0)),[2]!cMoneda2(H5,"BOLIVIANO","BOLIVIANOS",0)),[2]!cMoneda2(H4,"BOLIVIANO","BOLIVIANOS",0))} -> DOS MIL TRESCIENTOS CUARENTA Y UN BOLIVIANOS 56/100 | F8: 1a | H8: 2a | J8: 3a | P8: =VLOOKUP(P6,Códigos!C2:M858,11,FALSE) -> 2018088
F9: 4a | H9: 5a | J9: 6a
B10: Por concepto de : | C10: INGRESOS MENSUALIDAD COLEGIO DESPERTAD | F10: 7a | H10: 8a | J10: 9a
F11: 10a | H11: Unic.
B12: Observaciones :
C13: =IF(E7="","",CONCATENATE("Alumnos : ",VLOOKUP(E7,Códigos!A2:L858,3,FALSE)," - Padres : ",VLOOKUP(E7,Códigos!A2:L858,4,FALSE)," - Cursos : ",VLOOKUP(E7,Códigos!A2:L858,2,FALSE)," - Pensión : ",VLOOKUP(E7,Códigos!A2:L858,9,FALSE),," - Pensión KADI : ",VLOOKUP(E7,Códigos!A2:L858,10,FALSE))) -> Alumnos : Galindo Puña Sara - Padres : MARCELA - HENRY - Cursos : 4º Prim - Pensión : 823 - Pensión KADI : 364
C16: Cochabamba, | D16: 45308
B20: FIRMA DEL CAJERO | E20: FIRMA DEL INTERESADO
D24: RECIBO DE CAJA | F24: No. | H24: =H2 -> 2
D26: INGRESOS | F26: Bs.(Efect.) | H26: 1456.2
E27: t.c. (6,97) | F27: Bs.(Tr.-QR)
B28: Hemos recibido de : | C28: =C6 -> Rafucho Rafuchin | E28: CODIGO | F28: $us.
E29: =E7 -> 2018088 | F29: PENSIONES
B30: La suma de : | C30: =C8 -> DOS MIL TRESCIENTOS CUARENTA Y UN BOLIVIANOS 56/100 | F30: 1a | H30: 2a | J30: 3a
F31: 4a | H31: 5a | J31: 6a
B32: Por concepto de : | C32: =C10 -> INGRESOS MENSUALIDAD COLEGIO DESPERTAD | F32: 7a | H32: 8a | J32: 9a
F33: 10a | H33: Unic.
B34: Observaciones : | C34: =C12 -> 0
C35: =C13 -> Alumnos : Galindo Puña Sara - Padres : MARCELA - HENRY - Cursos : 4º Prim - Pensión : 823 - Pensión KADI : 364
C38: Cochabamba, | D38: =D16 -> 45308
B42: FIRMA DEL CAJERO | E42: FIRMA DEL INTERESADO
O1048565: FALSE
O1048566: FALSE
O1048567: FALSE
O1048568: FALSE
O1048569: FALSE
O1048570: FALSE
O1048571: FALSE
O1048572: FALSE
O1048573: FALSE
O1048574: FALSE
O1048575: FALSE

Sheet FLUJO DE CAJA
A1: FLUJO DE CAJA DE INGRESOS Y EGRESOS
A2: OP No. | B2: FECHA | C2: CODIGO | D2: DETALLE | E2: INGRESO EFECTIVO | F2: INGRESO TRANS.ó QR | G2: EGRESO | H2: OBSERVACIONES
A3: 1 | B3: 45292 | D3: REGISTRO INICIAL SIN VALORES OFICIALES | E3: 0 | F3: 0 | G3: 0
A3001: Total INGRESOS & EGRESOS | E3001: =SUBTOTAL(109,Tabla1[INGRESO EFECTIVO]) -> 0 | F3001: =SUBTOTAL(109,Tabla1[INGRESO TRANS.ó QR]) -> 0 | G3001: =SUBTOTAL(109,Tabla1[EGRESO]) -> 0
A3002: SALDO | E3002: =Tabla1[[#Totals],[INGRESO EFECTIVO]]+Tabla1[[#Totals],[INGRESO TRANS.ó QR]]-Tabla1[[#Totals],[EGRESO]] -> 0

Sheet LISTAS
A1: listas
A3: Detalle Ingresos Egresos
A4: INGRESOS CLASES IDIOMAS - ALEMAN
A5: INGRESOS CLASES IDIOMAS - IDIOMA2
A6: INGRESOS CLASES IDIOMAS - IDIOMA3
A7: INGRESOS CUOTA UNICA DE COLEGIO
A8: INGRESOS DE KIOSKO
A9: INGRESOS DEPORTES - DEPORTE4
A10: INGRESOS DEPORTES - DEPORTE5
A11: INGRESOS DEPORTES - FUTBOL
A12: INGRESOS DEPORTES - TENNIS DE MESA
A13: INGRESOS DEPORTES - VOLLEY BALL
... A42: EGRESOS SUELDOS Y SALARIOS

Sheet tarj ANVERSO
A1: CONTROL DE PENSIONES GESTION 2021
A3: Codigo del estudiante : | E3: 2018042
A4: Fecha de inscripción : | E4: =TODAY() -> 45309 | K4: Telefono - Celular | L4: =VLOOKUP(E3,Códigos!A1:L858,7,) -> 62616711m/68462255p/4795082c
A5: Nombre para la factura : | E5: =VLOOKUP(E3,Códigos!A1:L858,5,) -> SUAZNABAR | K5: NIT o CI: | L5: =VLOOKUP(E3,Códigos!A1:L858,6,) -> 4560429
A6: Nombre de Mamá o Papá : | E6: =VLOOKUP(E3,Códigos!A1:L858,4,) -> GISELLE - ESTEBAN | K6: Curso(s) : | L6: =VLOOKUP(E3,Códigos!A1:L858,2,) -> 3ºp-6ºp
A7: Pension mensual : | D7: =VLOOKUP(E3,Códigos!A1:L858,9,) | F7: No. Hermanos(as) : | I7: =VLOOKUP(E3,Códigos!A1:L858,8,) -> 3 | K7: Nivel : | L7: =VLOOKUP(E3,Códigos!A1:L858,12,) -> PRIM - SEC
A8: Nombre del estudiante : | E8: =VLOOKUP(E3,Códigos!A1:L858,3,) -> Mercado Suaznabar Cecilia - Sofia
A9: Rbo...….……Fact……….. | D9: Rbo...….……Fact……….. | G9: Rbo...….……Fact……….. | J9: Rbo...….……Fact……….. | M9: Rbo...….……Fact………..
A10: Bs. ………………….. | D10: Bs. ………………….. | G10: Bs. ………………….. | J10: Bs. ………………….. | M10: Bs. …………………..
A11: Primera Cuota - Feb | D11: Segunda Cuota - Mar | G11: Tercera Cuota - Abril | J11: Cuarta Cuota - Mayo | M11: Quinta Cuota - Junio
A12: Firma P. | D12: Firma P. | G12: Firma P. | J12: Firma P. | M12: Firma P.
A13: _______________________ | D13: _______________________ | G13: _______________________ | J13: _______________________ | M13: _______________________
A16: Rbo...….……Fact……….. | D16: Rbo...….……Fact……….. | G16: Rbo...….……Fact……….. | J16: Rbo...….……Fact……….. | M16: Rbo...….……Fact………..
A17: Bs. ………………….. | D17: Bs. ………………….. | G17: Bs. ………………….. | J17: Bs. ………………….. | M17: Bs. …………………..
A18: Sexta Cuota - Julio | D18: Septima Cuota - Agosto | G18: Octava Cuota - Sept. | J18: Novena Cuota - Octubre | M18: Decima Cuota - Noviem.
A19: Firma P. | D19: Firma P. | G19: Firma P. | J19: Firma P. | M19: Firma P.
A20: _______________________ | D20: _______________________ | G20: _______________________ | J20: _______________________ | M20: _______________________
A26: CONTROL DE PROGRAMA EXTENSIVO DE INGLES Y PROGRAMA
A27: EXTENSIVO MONTESSORI GESTION 2021
A28: Codigo del estudiante : | E28: =+E3 -> 2018042 | H28: CLASES EXTRA : | K28: CH | L28: AL | M28: FR | N28: INS
A29: Fecha de inscripción : | E29: =+E4 -> 45309 | G29: =VLOOKUP(#REF!,Códigos!#REF!,2,) -> #REF! | L29: Curso(s) : | M29: =VLOOKUP(E3,Códigos!A1:L858,2,) -> 3ºp-6ºp
A30: Monto mensual Prog Extensivo Ingles/Montessori : | G30: =VLOOKUP(E28,Códigos!A1:L837,10,) | I30: No. Hnos(as) : | K30: =VLOOKUP(E28,Códigos!A1:L837,8,) -> 3 | L30: Nivel : | M30: =VLOOKUP(E28,Códigos!A1:L837,12,) -> PRIM - SEC
A31: Nombre del estudiante : | E31: =VLOOKUP(E28,Códigos!A1:L837,3,) -> Mercado Suaznabar Cecilia - Sofia
A32: Rbo...….……Fact……….. | D32: Rbo...….……Fact……….. | G32: Rbo...….……Fact……….. | J32: Rbo...….……Fact……….. | M32: Rbo...….……Fact………..
A33: Bs. ………………….. | D33: Bs. ………………….. | G33: Bs. ………………….. | J33: Bs. ………………….. | M33: Bs. …………………..
A34: Primera Cuota - Feb | D34: Segunda Cuota - Mar | G34: Tercera Cuota - Abril | J34: Cuarta Cuota - Mayo | M34: Quinta Cuota - Junio
A35: Firma P. | D35: Firma P. | G35: Firma P. | J35: Firma P. | M35: Firma P.
A36: _______________________ | D36: _______________________ | G36: _______________________ | J36: _______________________ | M36: _______________________
A39: Rbo...….……Fact……….. | D39: Rbo...….……Fact……….. | G39: Rbo...….……Fact……….. | J39: Rbo...….……Fact……….. | M39: Rbo...….……Fact………..
A40: Bs. ………………….. | D40: Bs. ………………….. | G40: Bs. ………………….. | J40: Bs. ………………….. | M40: Bs. …………………..
A41: Sexta Cuota - Julio | D41: Septima Cuota - Agosto | G41: Octava Cuota - Sept. | J41: Novena Cuota - Octubre | M41: Decima Cuota - Noviem.
A42: Firma P. | D42: Firma P. | G42: Firma P. | J42: Firma P. | M42: Firma P.
A43: _______________________ | D43: _______________________ | G43: _______________________ | J43: _______________________ | M43: _______________________

Sheet tarj REVERSO
A4: CURSOS | B4: FECHA | C4: FEBRERO | E4: MARZO | G4: ABRIL | I4: MAYO | K4: JUNIO
A5: Varios | B5: Inicio de clases | C5: Rcbo. | D5: Bs. | E5: Rcbo. | F5: Bs. | G5: Rcbo. | H5: Bs. | I5: Rcbo. | J5: Bs. | K5: Rcbo. | L5: Bs.
A6: ALEMAN
A7: REP. MAT. MONTESSORI
A8: VARIOS 1
A9: VARIOS 2
A12: CURSOS | B12: FECHA | C12: JULIO | E12: AGOSTO | G12: SEPTIEMBRE | I12: OCTUBRE | K12: NOVIEMBRE
A13: Varios | B13: Inicio de clases | C13: Rcbo. | D13: Bs. | E13: Rcbo. | F13: Bs. | G13: Rcbo. | H13: Bs. | I13: Rcbo. | J13: Bs. | K13: Rcbo. | L13: Bs.
A14: ALEMAN
A15: REP. MAT. MONTESSORI
A16: VARIOS 1
A17: VARIOS 2

Sheet Códigos
A1: CODIGO | B1: CURSO | C1: NOMBRE DEL ESTUDIANTE | D1: NOMBRE DE MAMA O PAPA | E1: NOMBRE PARA LA FACTURA | F1: NIT | G1: TELEFONO | H1: HERMANOS | I1: PENSION | J1: PENSION KADI | K1: FECHA DE INSCRIPCION | L1: NIVEL | M1: CODIGO
A2: 2020010 | B2: 3º - 5º Prim | C2: Bayá García Alejandro - Leonardo | D2: KAREN - RAMIRO | E2: BAYA | F2: 4534980 | G2: 77960090m/78331228p | I2: 839 | J2: 371 | L2: PRIMARIA | M2: =A2 -> 2020010
A3: 2018053 | B3: I2 - 4ºp | C3: Aguila Sejas Adrian - Matias Hernan | D3: STEPHANIE - HERNAN | G3: 75497897m/77424577p/4240497c | H3: 2 | K3: 43482 | L3: INIC - PRIM | M3: =A3 -> 2018053
A4: 2018322 | B4: 6º Sec | C4: Aldunate Eterovic Cristian | D4: DRINA - OSCAR | E4: ´ | F4: 3622159 | G4: 70734118m/70757269p | I4: 807 | J4: 598 | K4: 43483 | L4: SECUNDARIA | M4: =A4 -> 2018322
A5: 2018208 | B5: 2ºB SEC | C5: Aldunate Santi Luciana Thais | D5: NORMA - JOSE MIGUEL | G5: 72207433m/70752267p/4507831c | I5: 823 | J5: 610 | L5: SECUNDARIA | M5: =A5 -> 2018208
A6: 2020020 | B6: Inicial 2 | C6: Almanza Merida Alejandra | D6: ZELMY - RODRIGO | E6: MERIDA | F6: 3615014 | G6: 79794429m/70743793p | I6: 839 | J6: 371 | L6: INICIAL | M6: =A6 -> 2020020
A7: 2018079 | B7: 4º - 6º Prim | C7: Almanza Orihuela Carlos Gabriel - Camila Gabriela | D7: GABRIELA - CARLOS | E7: ORIHUELA | F7: 4044384 | G7: 72768653m/68581473p/4247151c | I7: 823 | J7: 364 | K7: 43480 | L7: PRIMARIA | M7: =A7 -> 2018079
A8: 2018027 | B8: 2ºB Prim | C8: Altieri Laserna Florencia | D8: ALEJANDRA - JAVIER | E8: JAVIER ALTIERI | F8: 2878695 | G8: 70713114m/76401410p | I8: 807 | J8: 357 | K8: 43483 | L8: PRIMARIA | M8: =A8 -> 2018027
A9: 2018409 | B9: INICIAL 1 | C9: Alvarez Chaira Vivian Alicia | D9: FABIOLA - JULIO | E9: BEATRIZ LIA | F9: 3036522 | G9: 4351366c/76453202P/76945653M | I9: 823 | J9: 364 | L9: INICIAL | M9: =A9 -> 2018409
A10: 2018444 | B10: INICIAL I | C10: Alvarez Sejas Julio Gabriel | D10: DANIEL-MARCELA | E10: MARCELA SEJAS | F10: 6482564 | G10: 77805759p/79790719m/4236688 | I10: 807 | J10: 357 | K10: 43483 | L10: INICIAL | M10: =A10 -> 2018444
A11: 2018054 | B11: 3ºA Prim | C11: Andia Gonzales Mateo | D11: FABIOLA - ROBERTO | L11: PRIMARIA | M11: =A11 -> 2018054
A12: 2018396 | B12: 4º Prim | C12: Andia Saucedo Maria Jose | D12: MERCEDES - RODRIGO | E12: MERCEDES SAUCEDO | F12: 4185892 | G12: 77490065m/77493206p/4281981p | I12: 823 | J12: 364 | K12: 43483 | L12: PRIMARIA | M12: =A12 -> 2018396
A13: 2018080 | B13: 2ºp - 2ºs | C13: Angulo Balderrama Fabricio Fernando - Santiago Fernando | D13: KAREN - GUIDO | E13: WALDO RODRIGUEZ | F13: 823629 | G13: 70766863m/70360540p/4248931c | H13: 2 | I13: 1646 | J13: 974 | L13: PRIM - SEC | M13: =A13 -> 2018080
A14: 2018149 | B14: I2-6ºp-2ºs | C14: Angulo Cespedes Letizia - Daniel - Alejandra | D14: SILVANA - DOUGLAS | G14: 74305899m/67492168p | H14: 3 | K14: 43483 | L14: INIC-PRIM-SEC | M14: =A14 -> 2018149
A15: 2020070 | B15: 2do-3ro SEC | C15: Antezana Rojas Ariana Guadalupe-Andrea Abril | D15: JAVIER-KARINA | G15: 78333017P/78333019M/4424066C | H15: 2 | L15: SECUNDARIA | M15: =A15 -> 2020070
A16: 2018150 | B16: 6ºp - 1º Sec | C16: Antezana Rojas Santiago Israel - Angela Erika | D16: ERIKA - ISRAEL | G16: 70749010m/70750393p/4365560c | H16: 2 | K16: 43482 | L16: PRIM - SEC | M16: =A16 -> 2018150
A17: 2018350 | B17: 1ro- 4ºp | C17: Antezana Torrez Maite Valentina - Matias Andre | D17: MARIA - MIGUEL | E17: TABORGA | F17: 771441014 | G17: 70342380m/70725450p/4549901c | I17: 1646 | J17: 728 | L17: PRIMARIA | M17: =A17 -> 2018350
A18: 2018276 | B18: 4º Sec | C18: Anzoleaga Nicolas | D18: LORENA | E18: LORENA ANZOLEAGA | F18: 5153524 | G18: 78300066m/4229461c | I18: 823 | J18: 610 | K18: 43483 | L18: SECUNDARIA | M18: =A18 -> 2018276
A19: 2018244 | B19: 2º Sec B | C19: Apaza Ucharico Micaela Araceli | D19: MARINA - FREDDY | E19: UCHARICO | F19: 3361774 | G19: 79978872m/65306708p | I19: 839 | J19: 371 | K19: lunes, 20 de enero de 2020 | L19: SECUNDARIA | M19: =A19 -> 2018244
A20: 2018305 | B20: 4º - 6º Sec | C20: Arandia Cahuana Sigrid Marlene - Elias Sigfrido | D20: MARLENE - SIGFRIDO | E20: SIGFRIDO ARANDIA | F20: 3088967 | G20: 76400295m/77900040p/4458284c | H20: 2 | I20: 1646 | J20: 1220 | K20: 43483 | L20: SECUNDARIA | M20: =A20 -> 2018305
A21: 2020061 | B21: 3ro de SEC | C21: Araoz Covarrubias Mateo Alejandro | D21: HENRY-CAROLA | E21: ARAOZ | F21: 3120919 | G21: 79706668P/70795685M | H21: 0 | I21: 823 | J21: 610 | L21: SECUNDARIA | M21: =A21 -> 2020061
A22: 2018391 | B22: 3º - 6º Prim | C22: Arce Bustos Bianka Melissa - Kevin Freddy | D22: BLANCA - FREDDY | E22: FREDDY ARCE | F22: 1070861 | G22: 76404570m/61791901p/4038158c | H22: 2 | I22: 1646 | J22: 728 | K22: 43482 | L22: PRIMARIA | M22: =A22 -> 2018391
A23: 2020059 | B23: 2do PRIM | C23: Arellano Soliz Amy Fabiola | D23: AMILCAR-FAVIOLA | E23: FAVIOLA SOLIZ | F23: 3148343013 | G23: 70738020P/70799025M | H23: 0 | I23: 823 | J23: 364 | L23: PRIMARIA | M23: =A23 -> 2020059
A24: 2018055 | B24: 2º - 4º Prim | C24: Arias Mancilla Renata Sabrina - Fernanda Antonella | D24: YRENE - AMERICO | E24: YRENE MANCILLA | F24: 3817777 | G24: 71779887m/67573940p/4023654c | H24: 2 | I24: 2(823) | J24: 2(364) | K24: 43483 | L24: PRIMARIA | M24: =A24 -> 2018055
A25: 2020086 | B25: 1ro Prim | C25: Ariel Sotomayor | L25: PRIMARIA | M25: =A25 -> 2020086
A26: 2018223 | B26: 2º Sec | C26: Arispe Salaverry Andre Daniel | D26: DANIEL-SUSANA | G26: 65195354p/72264000m/4452340c | I26: 1646 | J26: 974 | L26: INI-PRIM | M26: =A26 -> 2018223
A27: 2018190 | B27: 1º Sec | C27: Arnez Vallejo Mariana | D27: M. RENEE - RONALD | E27: RONALD ARNEZ | F27: 3143281 | G27: 70384338m/75495723p/4715673c | I27: 839 | J27: 622 | K27: 43479 | L27: SECUNDARIA | M27: =A27 -> 2018190
A28: 2018245 | B28: 2º Sec | C28: Arnez Vergara Rodrigo Hernan | D28: CAROLA - ROGER | E28: ROGER ARNEZ | F28: 949885 | G28: 76470045m/76470046p/4423382c | I28: 839 | J28: 622 | K28: 43483 | L28: SECUNDARIA | M28: =A28 -> 2018245
A29: 2018306 | B29: 6º Sec | C29: Arze Isabella | D29: YIN LING - JORGE | E29: RICARDO ARZE | F29: 3614256010 | G29: 67581249p/72784849m/4487345 | I29: 823 | J29: 610 | K29: 43483 | L29: SECUNDARIA | M29: =A29 -> 2018306
A30: 2020075 | B30: 6to Primaria | C30: Arze Puri Luis Diego | D30: EDWARD-JHOVANA | E30: S/F | F30: S/F | G30: 79755556P/79737191M | H30: 0 | I30: 823 | J30: 364 | L30: PRIMARIA | M30: =A30 -> 2020075
A31: 2018209 | B31: 1º - 6º Prim | C31: Ascarrunz Pereira Isela - Rafaela - Monserrat | D31: KATIUSKA - JAIME | E31: ´ | F31: ´ | G31: 76411152m/79997207p | H31: 3 | I31: ´ | J31: ´ | K31: 43482 | L31: PRIMARIA | M31: =A31 -> 2018209
A32: 2018288 | B32: 5º Sec | C32: Aviles Coll Avril Janelle | D32: JHANNA - GABRIEL | E32: MARISCAL | F32: 3765324 | G32: 77497367m | I32: 823 | J32: 610 | K32: 43482 | L32: SECUNDARIA | M32: =A32 -> 2018288
A33: 2018002 | B33: 3º Prim | C33: Ayala Del Barco Benjamín | D33: CAROLINA - HERNAN | E33: HERNAN AYALA | F33: 3748118 | G33: 76462671m/71466531p/4582301c | I33: 823 | J33: 364 | L33: PRIMARIA | M33: =A33 -> 2018002
A34: 2018127 | B34: 5º Prim | C34: Ayala Gonzales Diana Victoria | D34: CARLA - FREDDY | E34: GONZALES | F34: 3808783013 | G34: 79730401m/70733130p/4422406c | I34: 823 | J34: 364 | K34: 43481 | L34: PRIMARIA | M34: =A34 -> 2018127
A35: 2018210 | B35: 1º Sec | C35: Ayo Fernandez Diego Gabriel | D35: MARCIA - DIEGO | E35: MUKLED | F35: 3390188016 | G35: 77290849m/70612862p/4020400c | I35: 823 | J35: 364 | K35: 43483 | L35: SECUNDARIA | M35: =A35 -> 2018210
A36: 2018028 | B36: 2ºA Prim | C36: Barco Antesana Benjamin | D36: ROBERTO-GRACE | E36: ANTEZANA | F36: 4406840 | G36: 67405642p/70760531M/4257502 | I36: 807 | J36: 357 | K36: 43483 | L36: PRIMARIA | M36: =A36 -> 2018028
A37: 2018447 | B37: 4º Sec | C37: Barrera Aguirre Estefanie | D37: MARIANELA | E37: MARIANELA AGUIRRE | F37: 3753285 | G37: 70716204 | K37: 43483 | L37: SECUNDARIA | M37: =A37 -> 2018447
A38: 2018081 | B38: 4º - 5º Prim | C38: Bautista Jaramillo Rodrigo Enrique - Camila Antonette | D38: ESTELA - ENRIQUE | E38: ENRIQUE BAUTISTA | F38: 5032188 | G38: 76401066m/76401269p/67479267o | H38: 2 | K38: 43481 | L38: PRIMARIA | M38: =A38 -> 2018081
A39: 2018029 | B39: 3º Prim | C39: Becerra Soria Addie Renata | D39: VIVIAN - LUDWING | E39: BECERRA LUDWING | F39: 3599727 | G39: 70768677m/76401141p/4443067c | I39: 823 | J39: 364 | K39: 43482 | L39: PRIMARIA | M39: =A39 -> 2018029
A40: 2020011 | B40: 1º SEC | C40: Bellido Villegas Dasha | D40: CLAUDIA - RAMIRO | G40: 69814291m | L40: SECUNDARIA | M40: =A40 -> 2020011
...

Sheet SUELDOS
B1: PLANILLA DE SUELDOS DOCENTES
B2: MES | E2: No. | F2: Bs. | G2: - Horas X | H2: Bs. DESC. | I2: Bs. DESC.
B3: 2024 | E3: Horas | F3: HABER | G3: Atra y Faltas | H3: Por F/Atrs | I3: ADELANTO | J3: LIQUIDO
A4: Nro | B4: APELLIDOS Y NOMBRE | C4: MATERIA | D4: Nro. C.I. | E4: MENSUAL | F4: MENSUAL | G4: MENSUAL | H4: MENSUAL | I4: MENSUAL | J4: PAGABLE
A5: 1 | B5: Vesna Lazaneo | C5: Directora | D5: 3603941 CB. | E5: 160 | F5: 6000 | G5: 0 | H5: =IF(B5="","",(F5/E5)*G5) -> 0 | I5: 0 | J5: =IF(B5="","",F5-H5-I5) -> 6000
A6: =A5+1 -> 2 | B6: David Antequera | C6: Director | D6: 3375300 CB. | E6: 160 | F6: 6000 | G6: 0 | H6: =IF(B6="","",(F6/E6)*G6) -> 0 | I6: 0 | J6: =IF(B6="","",F6-H6-I6) -> 6000
A7: =A6+1 -> 3 | B7: Felicidad Benito | C7: Secretaria | D7: 2797745 Or. | E7: 160 | F7: 4500 | G7: 0 | H7: =IF(B7="","",(F7/E7)*G7) -> 0 | I7: 0 | J7: =IF(B7="","",F7-H7-I7) -> 4500
A8: =A7+1 -> 4 | B8: Carmen Gomez | C8: Psicóloga | D8: 3109973 Or. | E8: 160 | F8: 4500 | G8: 0 | H8: =IF(B8="","",(F8/E8)*G8) -> 0 | I8: 0 | J8: =IF(B8="","",F8-H8-I8) -> 4500
A9: =A8+1 -> 5 | B9: Rocio Janette Cruz | C9: Maternal | D9: 7908651CB. | E9: 160 | F9: 2092 | G9: 0 | H9: =IF(B9="","",(F9/E9)*G9) -> 0 | I9: 0 | J9: =IF(B9="","",F9-H9-I9) -> 2092
A10: =A9+1 -> 6 | B10: Fabiola Herrera | C10: Aux Inicial 1 | D10: 7929725 CB. | E10: 160 | F10: 1160.5 | G10: 0 | H10: =IF(B10="","",(F10/E10)*G10) -> 0 | I10: 0 | J10: =IF(B10="","",F10-H10-I10) -> 1160.5
A11: =A10+1 -> 7 | B11: Lucy Rodriguez | C11: Maternal B | D11: 3800831 Lp. | E11: 160 | F11: 2000 | G11: 0 | H11: =IF(B11="","",(F11/E11)*G11) -> 0 | I11: 0 | J11: =IF(B11="","",F11-H11-I11) -> 2000
A12: =A11+1 -> 8 | B12: Marlene Quiñonez | C12: Prof. Mater. | D12: 5238814 CB. | E12: 160 | F12: 1350 | G12: 0 | H12: =IF(B12="","",(F12/E12)*G12) -> 0 | I12: 0 | J12: =IF(B12="","",F12-H12-I12) -> 1350
A13: =A12+1 -> 9 | B13: Lilian Herrera | C13: Prof Inicial 3 | D13: 7881370 CB. | E13: 160 | F13: 2077 | G13: 0 | H13: =IF(B13="","",(F13/E13)*G13) -> 0 | I13: 0 | J13: =IF(B13="","",F13-H13-I13) -> 2077
A14: =A13+1 -> 10 | B14: Romina Edith Mamani Cruz | C14: Aux Inicial 3 | D14: 12874630 CB. | E14: 160 | F14: 1287 | G14: 0 | H14: =IF(B14="","",(F14/E14)*G14) -> 0 | I14: 0 | J14: =IF(B14="","",F14-H14-I14) -> 1287
A15: =A14+1 -> 11 | B15: Nancy Soria | C15: Prof Inicial 2 | D15: 2337042 Lp. | E15: 160 | F15: 3571 | G15: 0 | H15: =IF(B15="","",(F15/E15)*G15) -> 0 | I15: 0 | J15: =IF(B15="","",F15-H15-I15) -> 3571
A16: =A15+1 -> 12 | B16: Thelma Cortez | C16: Aux Inicial 2 | D16: 5107060 CB. | E16: 160 | F16: 1656 | G16: 0 | H16: =IF(B16="","",(F16/E16)*G16) -> 0 | I16: 0 | J16: =IF(B16="","",F16-H16-I16) -> 1656
A17: =A16+1 -> 13 | B17: Karina Velasquez | C17: Prof. Inicial 4 | D17: 5253008 CB. | E17: 160 | F17: 3000 | G17: 0 | H17: =IF(B17="","",(F17/E17)*G17) -> 0 | I17: 0 | J17: =IF(B17="","",F17-H17-I17) -> 3000
... A28: =A27+1 -> 24 | B28: Ana Claudia Lafuente | C28: Prof. Ingles | D28: 6442423 CB. | E28: 160 | F28: 3387 | G28: 0 | H28: =IF(B28="","",(F28/E28)*G28) -> 0 | I28: 0 | J28: =IF(B28="","",F28-H28-I28) -> 3387
A29: =A28+1 -> 25 | B29: Cecilia Fernandez | C29: Prof, 4to A | D29: 0 | E29: 160 | F29: 2500 | G29: 0 | H29: =IF(B29="","",(F29/E29)*G29) -> 0 | I29: 0 | J29: =IF(B29="","",F29-H29-I29) -> 2500
A30: =A29+1 -> 26 | B30: Susana Marcus | C30: Sociales Ingles | D30: 5234822 CB. | E30: 160 | F30: 3000 | G30: 0 | H30: =IF(B30="","",(F30/E30)*G30) -> 0 | I30: 0 | J30: =IF(B30="","",F30-H30-I30) -> 3000
A31: =A30+1 -> 27 | B31: Vanessa Bustillos | C31: Ciencias | D31: 4400632 CB. | E31: 160 | F31: 4538 | G31: 0 | H31: =IF(B31="","",(F31/E31)*G31) -> 0 | I31: 0 | J31: =IF(B31="","",F31-H31-I31) -> 4538
A32: =A31+1 -> 28 | B32: Carmen Zambrana | C32: Inglés | D32: 2475663 CB. | E32: 160 | F32: 3400 | G32: 0 | H32: =IF(B32="","",(F32/E32)*G32) -> 0 | I32: 0 | J32: =IF(B32="","",F32-H32-I32) -> 3400
A33: =A32+1 -> 29 | B33: Eugenia Condori | C33: Matemáticas | D33: 5240336 CB. | E33: 160 | F33: 3100 | G33: 0 | H33: =IF(B33="","",(F33/E33)*G33) -> 0 | I33: 0 | J33: =IF(B33="","",F33-H33-I33) -> 3100
A34: =A33+1 -> 30 | B34: Ana Gabriela Villarroel | C34: Lenguaje | D34: 6551091 CB. | E34: 160 | F34: 2200 | G34: 0 | H34: =IF(B34="","",(F34/E34)*G34) -> 0 | I34: 0 | J34: =IF(B34="","",F34-H34-I34) -> 2200
A35: =A34+1 -> 31 | B35: Milena Solares | C35: Manualidades | D35: 969916 CB. | E35: 160 | F35: 1000 | G35: 0 | H35: =IF(B35="","",(F35/E35)*G35) -> 0 | I35: 0 | J35: =IF(B35="","",F35-H35-I35) -> 1000
A36: =A35+1 -> 32 | B36: Rafael Antequera | C36: Fisica | D36: 3399098 CB. | E36: 160 | F36: 3900 | G36: 0 | H36: =IF(B36="","",(F36/E36)*G36) -> 0 | I36: 0 | J36: =IF(B36="","",F36-H36-I36) -> 3900
A37: =A36+1 -> 33 | B37: Margaret Giancalone | C37: Inglés | D37: 0 | E37: 160 | F37: 3000 | G37: 0 | H37: =IF(B37="","",(F37/E37)*G37) -> 0 | I37: 0 | J37: =IF(B37="","",F37-H37-I37) -> 3000
A38: =A37+1 -> 34 | B38: Mariela Reyna | C38: Bio.Español | D38: 3117036 CB. | E38: 160 | F38: 2600 | G38: 0 | H38: =IF(B38="","",(F38/E38)*G38) -> 0 | I38: 0 | J38: =IF(B38="","",F38-H38-I38) -> 2600
A39: =A38+1 -> 35 | B39: Paola Luzio | C39: Lenguaje | D39: 3764931 CB. | E39: 160 | F39: 1944 | G39: 0 | H39: =IF(B39="","",(F39/E39)*G39) -> 0 | I39: 0 | J39: =IF(B39="","",F39-H39-I39) -> 1944
A40: =A39+1 -> 36 | B40: Marcelo Rodriguez | C40: Historia | D40: 4401361 CB. | E40: 160 | F40: 4220 | G40: 0 | H40: =IF(B40="","",(F40/E40)*G40) -> 0 | I40: 0 | J40: =IF(B40="","",F40-H40-I40) -> 4220
A41: =A40+1 -> 37 | B41: Deyna Castro | C41: Secr Secundaria | D41: 6550274CB. | E41: 160 | F41: 2637.5 | G41: 0 | H41: =IF(B41="","",(F41/E41)*G41) -> 0 | I41: 0 | J41: =IF(B41="","",F41-H41-I41) -> 2637.5
A42: =A41+1 -> 38 | B42: Victor Velarde | C42: Mantenimi. | D42: 0 | E42: 160 | F42: 3050 | G42: 0 | H42: =IF(B42="","",(F42/E42)*G42) -> 0 | I42: 0 | J42: =IF(B42="","",F42-H42-I42) -> 3050
A43: =A42+1 -> 39 | B43: Simon Martinez | C43: Regente | D43: 0 | E43: 160 | F43: 2900 | G43: 0 | H43: =IF(B43="","",(F43/E43)*G43) -> 0 | I43: 0 | J43: =IF(B43="","",F43-H43-I43) -> 2900
A44: =A43+1 -> 40 | B44: Osvaldo Terán | C44: Jardinería | D44: 0 | E44: 160 | F44: 1800 | G44: 0 | H44: =IF(B44="","",(F44/E44)*G44) -> 0 | I44: 0 | J44: =IF(B44="","",F44-H44-I44) -> 1800
A45: =A44+1 -> 41 | B45: Martha Condori | C45: Cocina | D45: 0 | E45: 160 | F45: 2215.5 | G45: 0 | H45: =IF(B45="","",(F45/E45)*G45) -> 0 | I45: 0 | J45: =IF(B45="","",F45-H45-I45) -> 2215.5
A46: =A45+1 -> 42 | B46: Rosmery Mercado | C46: Cocina | D46: 0 | E46: 160 | F46: 2005 | G46: 0 | H46: =IF(B46="","",(F46/E46)*G46) -> 0 | I46: 0 | J46: =IF(B46="","",F46-H46-I46) -> 2005
A47: =A46+1 -> 43 | B47: Ana Maria Goitia | C47: Cocina | D47: 0 | E47: 160 | F47: 1750 | G47: 0 | H47: =IF(B47="","",(F47/E47)*G47) -> 0 | I47: 0 | J47: =IF(B47="","",F47-H47-I47) -> 1750
A48: =A47+1 -> 44 | B48: Enrriqueta Pinaya | C48: Cocina | D48: 0 | E48: 160 | F48: 1900 | G48: 0 | H48: =IF(B48="","",(F48/E48)*G48) -> 0 | I48: 0 | J48: =IF(B48="","",F48-H48-I48) -> 1900
A49: =A48+1 -> 45 | B49: Betty Colquehuanca | C49: Portera | D49: 0 | E49: 160 | F49: 1741 | G49: 0 | H49: =IF(B49="","",(F49/E49)*G49) -> 0 | I49: 0 | J49: =IF(B49="","",F49-H49-I49) -> 1741
A50: =A49+1 -> 46 | B50: Carla Balderrama | C50: limpieza | D50: 4390163 CB. | E50: 160 | F50: 1800 | G50: 0 | H50: =IF(B50="","",(F50/E50)*G50) -> 0 | I50: 0 | J50: =IF(B50="","",F50-H50-I50) -> 1800
...

Sheet HOJA DE COBRO DEL SEGURO
A1: ADQUISICIÓN DE SEGURO CONTRA ACCIDENTES
A2: GESTIÓN 2020
A3: N° | B3: FAMILIA | C3: CANTIDAD | D3: MONTO | E3: OBSERVACIONES
A4: 1 | B4: Aguila Sejas Adrian - Matias Hernan
A5: 2 | B5: Aldunate Eterovic Cristian
A6: 3 | B6: Aldunate Santi Luciana Thais
A7: 4 | B7: Almanza Orihuela Carlos Gabriel - Camila Gabriela
A8: 5 | B8: Altieri Laserna Florencia
A9: 6 | B9: Alvarez Chaira Vivian Alicia
A10: 7 | B10: Alvarez Sejas Julio Gabriel
A11: 8 | B11: Andia Gonzales Mateo
A12: 9 | B12: Andia Saucedo Maria Jose
A13: 10 | B13: Angulo Balderrama Fabricio Fernando - Santiago Fernando
A14: 11 | B14: Angulo Cespedes Letizia - Daniel - Alejandra
A15: 12 | B15: Antezana Rojas Santiago Israel - Angela Erika
... A374: 371 | B374: Vidaurre Galindo Salvador
A375: 372
A376: 373
A377: 374
A378: 375
A379: 376
A380: 377
A381: 378
A382: 379
A383: 380
A384: 381
A385: 382
A386: 383
... A465: 462
