Workbook

Sheet Costo M.P.yMat.
A1: ANALISIS DE COSTOS Y DETERMINACION DE PRECIOS DE VENTA (/i1,1/,84)
A3: PRODUCTO | B3: Unidad | C3: Precio de | D3: Precio de | E3: Costo oper. | G3: Proveedor
C4: venta CF | D4: venta SF | E4: CF | F4: SF
C5: $us/unid. | D5: $us/unid. | E5: $us/unid. | F5: $us/unid.
A6: MATERIALES COMUNES PARA EL VIDRIO TEMPLADO Y LA CARPINTERIA DE ALUMINIO
A7: Silicona transparente, blanca o negra | B7: Tubo | C7: =ROUNDUP(E7*0.87*1.1/0.84,2) -> 2.76 | D7: =ROUNDUP(F7*1.1,2) -> 2.67 | E7: 2.42 | F7: 2.42 | G7: Amerix | H7: =(-D7+C7)/C7 -> 0.032608696
A8: Silicona estructural | B8: Tubo | C8: =ROUNDUP(E8*0.87*1.1/0.84,2) -> 7.98 | D8: =ROUNDUP(F8*1.1,2) -> 7.4 | E8: 7 | F8: =+E8*0.96 -> 6.72 | G8: Amerix | H8: =(-D8+C8)/C8 -> 0.072681704
A9: Cinta masking 1/2 " (rollo de 20) | B9: Rollo | C9: =ROUNDUP(E9*0.87*1.1/0.84,2) -> 0.75 | D9: =ROUNDUP(F9*1.1,2) -> 0.72 | E9: 0.65 | F9: 0.65 | G9: Ribepar | H9: =(-D9+C9)/C9 -> 0.04
A10: "U" 15 x 15 ( 16x16 ) - 0,159 Kg/Mt. | B10: Mt lineal | C10: =ROUNDUP(E10*0.87*1.1/0.84,2) -> 1.41 | D10: =ROUNDUP(F10*1.1,2) -> 1.3 | E10: =+K10/6 -> 1.2305805 | F10: =0.96*E10 -> 1.1813573 | G10: Alcoa 6,73 + 15% | H10: =(-D10+C10)/C10 -> 0.078014184 | I10: =6*0.159 -> 0.954 | J10: Kgr./barra | K10: =6.73*1.15*I10 -> 7.383483 | L10: $us./barra
A11: "U" 15 x 25 - 0,20 Kg/Mt. | B11: Mt lineal | C11: =ROUNDUP(E11*0.87*1.1/0.84,2) -> 1.77 | D11: =ROUNDUP(F11*1.1,2) -> 1.64 | E11: =+K11/6 -> 1.5479 | F11: =0.96*E11 -> 1.485984 | G11: Alcoa 6,73 + 15% | H11: =(-D11+C11)/C11 -> 0.073446328 | I11: =6*0.2 -> 1.2 | J11: Kgr./barra | K11: =6.73*1.15*I11 -> 9.2874 | L11: $us./barra
A12: Tubo 50 x 50 - 1,037 Kg/Mt. | B12: Mt lineal | C12: =ROUNDUP(E12*0.87*1.1/0.84,2) -> 9.15 | D12: =ROUNDUP(F12*1.1,2) -> 8.48 | E12: =+K12/6 -> 8.0258615 | F12: =0.96*E12 -> 7.704827 | G12: Alcoa 6,73 + 15% | H12: =(-D12+C12)/C12 -> 0.073224044 | I12: =6*1.037 -> 6.222 | J12: Kgr./barra | K12: =6.73*1.15*I12 -> 48.155169 | L12: $us./barra
A13: Tubo 40 x 40 - 0,624 Kg/Mt. | B13: Mt lineal | C13: =ROUNDUP(E13*0.87*1.1/0.84,2) -> 5.51 | D13: =ROUNDUP(F13*1.1,2) -> 5.1 | E13: =+K13/6 -> 4.829448 | F13: =0.96*E13 -> 4.6362701 | G13: Alcoa 6,73 + 15% | H13: =(-D13+C13)/C13 -> 0.074410163 | I13: =6*0.624 -> 3.744 | J13: Kgr./barra | K13: =6.73*1.15*I13 -> 28.976688 | L13: $us./barra
A14: Tubo 80 x 40 - 0,948 Kg/Mt. | B14: Mt lineal | C14: =ROUNDUP(E14*0.87*1.1/0.84,2) -> 8.36 | D14: =ROUNDUP(F14*1.1,2) -> 7.75 | E14: =+K14/6 -> 7.337046 | F14: =0.96*E14 -> 7.0435642 | G14: Alcoa 6,73 + 15% | H14: =(-D14+C14)/C14 -> 0.072966507 | I14: =6*0.948 -> 5.688 | J14: Kgr./barra | K14: =6.73*1.15*I14 -> 44.022276 | L14: $us./barra
A15: Tubo 60 x 30 - 0,705 Kg/Mt. | B15: Mt lineal | C15: =ROUNDUP(E15*0.87*1.1/0.84,2) -> 6.22 | D15: =ROUNDUP(F15*1.1,2) -> 5.77 | E15: =+K15/6 -> 5.4563475 | F15: =0.96*E15 -> 5.2380936 | G15: Alcoa 6,73 + 15% | H15: =(-D15+C15)/C15 -> 0.072347267 | I15: =6*0.705 -> 4.23 | J15: Kgr./barra | K15: =6.73*1.15*I15 -> 32.738085 | L15: $us./barra
A16: Tubo 75 x 25 - 0,786 Kg/Mt. | B16: Mt lineal | C16: =ROUNDUP(E16*0.87*1.1/0.84,2) -> 6.94 | D16: =ROUNDUP(F16*1.1,2) -> 6.43 | E16: =+K16/6 -> 6.083247 | F16: =0.96*E16 -> 5.8399171 | G16: Alcoa 6,73 + 15% | H16: =(-D16+C16)/C16 -> 0.073487032 | I16: =6*0.786 -> 4.716 | J16: Kgr./barra | K16: =6.73*1.15*I16 -> 36.499482 | L16: $us./barra
A17: Felpa | B17: Mt lineal | C17: =ROUNDUP(E17*0.87*1.1/0.84,2) -> 0.18 | D17: =ROUNDUP(F17*1.1,2) -> 0.17 | E17: 0.15 | F17: 0.15 | G17: Indalum | H17: =(-D17+C17)/C17 -> 0.055555556
A18: Remache 4 x 10 | B18: Pza. | C18: =ROUNDUP(E18*0.87*1.1/0.84,2) -> 0.04 | D18: =ROUNDUP(F18*1.1,2) -> 0.04 | E18: 0.03 | F18: 0.03 | G18: Perbol | H18: =(-D18+C18)/C18 -> 0
A19: Tarugos No. 6 | B19: Pza. | C19: =ROUNDUP(E19*0.87*1.1/0.84,2) -> 0.04 | D19: =ROUNDUP(F19*1.1,2) -> 0.04 | E19: 0.03 | F19: 0.03 | G19: Perbol | H19: =(-D19+C19)/C19 -> 0
A20: Tornillos 8 x 1 1/2 | B20: Pza. | C20: =ROUNDUP(E20*0.87*1.1/0.84,2) -> 0.04 | D20: =ROUNDUP(F20*1.1,2) -> 0.04 | E20: 0.03 | F20: 0.03 | G20: Perbol | H20: =(-D20+C20)/C20 -> 0
A21: Tornillos 8 x 1/2 | B21: Pza. | C21: =ROUNDUP(E21*0.87*1.1/0.84,2) -> 0.03 | D21: =ROUNDUP(F21*1.1,2) -> 0.03 | E21: 0.02 | F21: 0.02 | G21: Perbol | H21: =(-D21+C21)/C21 -> 0
A22: Tubo Galvanizado de 4" | B22: Mt lineal | C22: =ROUNDUP(E22*0.87*1.1/0.84,2) -> 29.91 | D22: =ROUNDUP(F22*1.1,2) -> 27.72 | E22: =150*1.05/6 -> 26.25 | F22: =+E22*0.96 -> 25.2 | G22: Las Lomas ( 150+5%uniones) | H22: =(-D22+C22)/C22 -> 0.073219659
A25: PARA EL VIDRIO TEMPLADO
A26: Vidrio Templado 10mm Incoloro | B26: Mt² | C26: =ROUNDUP(E26*0.87*1.1/0.84,2) -> 36.46 | D26: =ROUNDUP(F26*1.1,2) -> 33 | E26: 32 | F26: 30 | G26: Oriental | H26: =(-D26+C26)/C26 -> 0.094898519
A27: Vidrio Templado 8mm Incoloro | B27: Mt² | C27: =ROUNDUP(E27*0.87*1.1/0.84,2) -> 34.18 | D27: =ROUNDUP(F27*1.1,2) -> 30.8 | E27: 30 | F27: 28 | G27: Oriental | H27: =(-D27+C27)/C27 -> 0.098888239
A28: Vidrio Templado 6mm Incoloro | B28: Mt² | C28: =ROUNDUP(E28*0.87*1.1/0.84,2) -> 31.9 | D28: =ROUNDUP(F28*1.1,2) -> 30.8 | E28: 28 | F28: 28 | G28: Revibol | H28: =(-D28+C28)/C28 -> 0.034482759
A29: Vidrio Templado 5mm Incoloro | B29: Mt² | C29: =ROUNDUP(E29*0.87*1.1/0.84,2) -> 27.35 | D29: =ROUNDUP(F29*1.1,2) -> 26.4 | E29: 24 | F29: 24 | G29: Revibol | H29: =(-D29+C29)/C29 -> 0.034734918
A30: Vidrio Templado 4mm Incoloro | B30: Mt² | C30: =ROUNDUP(E30*0.87*1.1/0.84,2) -> 23.93 | D30: =ROUNDUP(F30*1.1,2) -> 23.1 | E30: 21 | F30: 21 | G30: Revibol | H30: =(-D30+C30)/C30 -> 0.034684496
A31: Vidrio Templado 10mm Color | B31: Mt² | C31: =ROUNDUP(E31*0.87*1.1/0.84,2) -> 52.41 | D31: =ROUNDUP(F31*1.1,2) -> 48.4 | E31: 46 | F31: 44 | G31: Oriental | H31: =(-D31+C31)/C31 -> 0.076512116
A32: Vidrio Templado 8mm Color | B32: Mt² | C32: =ROUNDUP(E32*0.87*1.1/0.84,2) -> 50.13 | D32: =ROUNDUP(F32*1.1,2) -> 46.2 | E32: 44 | F32: 42 | G32: Oriental | H32: =(-D32+C32)/C32 -> 0.07839617
A33: Vidrio Templado 6mm Color | B33: Mt² | C33: =ROUNDUP(E33*0.87*1.1/0.84,2) -> 33.04 | D33: =ROUNDUP(F33*1.1,2) -> 31.9 | E33: 29 | F33: 29 | G33: Revibol | H33: =(-D33+C33)/C33 -> 0.034503632
A34: Vidrio Templado 5mm Color | B34: Mt² | C34: =ROUNDUP(E34*0.87*1.1/0.84,2) -> 30.77 | D34: =ROUNDUP(F34*1.1,2) -> 29.7 | E34: 27 | F34: 27 | G34: Revibol | H34: =(-D34+C34)/C34 -> 0.034774131
A35: Vidrio Templado 4mm Color | B35: Mt² | C35: =ROUNDUP(E35*0.87*1.1/0.84,2) -> 26.21 | D35: =ROUNDUP(F35*1.1,2) -> 25.3 | E35: 23 | F35: 23 | G35: Revibol | H35: =(-D35+C35)/C35 -> 0.034719573
A36: Vidrio Templado Catedral 10mm Incoloro | B36: Mt² | C36: =ROUNDUP(E36*0.87*1.1/0.84,2) -> 50.13 | D36: =ROUNDUP(F36*1.1,2) -> 48.4 | E36: 44 | F36: 44 | G36: Revibol | H36: =(-D36+C36)/C36 -> 0.034510273
A37: Vidrio Templado Catedral 10mm Color | B37: Mt² | C37: =ROUNDUP(E37*0.87*1.1/0.84,2) -> 52.41 | D37: =ROUNDUP(F37*1.1,2) -> 50.6 | E37: 46 | F37: 46 | G37: Revibol | H37: =(-D37+C37)/C37 -> 0.034535394
A38: Cabezal Tapa Guia Tapa-guia 1.998 Kg/Mt | B38: Mt lineal | C38: =ROUNDUP(E38*0.87*1.1/0.84,2) -> 17.62 | D38: =ROUNDUP(F38*1.1,2) -> 16.33 | E38: =+K38/6 -> 15.463521 | F38: =+E38*0.96 -> 14.84498 | G38: Alcoa 6,73 + 15% | H38: =(-D38+C38)/C38 -> 0.073212259 | I38: =6*1.998 -> 11.988 | J38: Kgr./barra | K38: =6.73*1.15*I38 -> 92.781126 | L38: $us./barra
A39: Vedapres 001 - h (2,10mt/barra) Inc. | B39: Barra | C39: =ROUNDUP(E39*0.87*1.1/0.84,2) -> 5.99 | D39: =ROUNDUP(F39*1.1,2) -> 5.5 | E39: =+F39*1.05 -> 5.25 | F39: 5 | G39: Florencio Rivero | H39: =(-D39+C39)/C39 -> 0.081803005 | I39: =6*0.257 -> 1.542 | J39: Kgr./barra | K39: =6.73*1.15*I39 -> 11.934309 | L39: $us./barra | M39: =+K39*2.1/6 -> 4.1770081
A40: Vedapres 002 - Uc (2,10mt/barra) Inc. | B40: Barra | C40: =ROUNDUP(E40*0.87*1.1/0.84,2) -> 5.99 | D40: =ROUNDUP(F40*1.1,2) -> 5.5 | E40: =+F40*1.05 -> 5.25 | F40: 5 | G40: Florencio Rivero | H40: =(-D40+C40)/C40 -> 0.081803005 | I40: =6*0.151 -> 0.906 | J40: Kgr./barra | K40: =6.73*1.15*I40 -> 7.011987 | L40: $us./barra | M40: =+K40*2.1/6 -> 2.4541954
A41: Vedapres 003 - H (2,10mt/barra) Inc. | B41: Barra | C41: =ROUNDUP(E41*0.87*1.1/0.84,2) -> 5.99 | D41: =ROUNDUP(F41*1.1,2) -> 5.5 | E41: =+F41*1.05 -> 5.25 | F41: 5 | G41: Florencio Rivero | H41: =(-D41+C41)/C41 -> 0.081803005
A42: Vedapres 001 - h (2,10mt/barra) Bce. | B42: Barra | C42: =ROUNDUP(E42*0.87*1.1/0.84,2) -> 5.99 | D42: =ROUNDUP(F42*1.1,2) -> 5.5 | E42: =+F42*1.05 -> 5.25 | F42: 5 | G42: Florencio Rivero | H42: =(-D42+C42)/C42 -> 0.081803005
A43: Vedapres 002 - Uc (2,10mt/barra) Bce. | B43: Barra | C43: =ROUNDUP(E43*0.87*1.1/0.84,2) -> 5.99 | D43: =ROUNDUP(F43*1.1,2) -> 5.5 | E43: =+F43*1.05 -> 5.25 | F43: 5 | G43: Florencio Rivero | H43: =(-D43+C43)/C43 -> 0.081803005
...

Sheet FORMULAS
F1: B | G1: H | H1: BxH | I1: CANT. | M1: B | N1: H | O1: BxH | P1: (N-1)*H
A2: base | B2: altura | C2: cant | E2: PUERTA CORREDIZA 2 HOJAS | L2: PANO FIJO
A3: 2 | B3: 2.1 | C3: 1 | E3: Vidrio Templado 10mm Incoloro | F3: =+'P-V.Corrediza'!C128 -> 38.51 | G3: =+'P-V.Corrediza'!D128 -> 13.57476 | H3: =+'P-V.Corrediza'!E128 -> 48.54 | I3: =+'P-V.Corrediza'!G128 -> 39.11 | J3: =+F3*$A$3+G3*$B$3+H3*$A$3*$B$3+$C$3*I3 -> 348.505 | L3: Vidrio Templado 10mm Incoloro | M3: =+'Pano Fijo'!C130 -> 20.1892 | N3: =+'Pano Fijo'!D130 -> 20.1892 | O3: =+'Pano Fijo'!F130 -> 49.68 | P3: =+'Pano Fijo'!G130 -> 1.116
E4: Vidrio Templado 10mm Color | F4: =+'P-V.Corrediza'!C129 -> 38.51 | G4: =+'P-V.Corrediza'!D129 -> 13.57476 | H4: =+'P-V.Corrediza'!E129 -> 64.49 | I4: =+'P-V.Corrediza'!G129 -> 39.11 | J4: =+F4*$A$3+G4*$B$3+H4*$A$3*$B$3+$C$3*I4 -> 415.495 | L4: Vidrio Templado 10mm Color | M4: =+'Pano Fijo'!C131 -> 20.1892 | N4: =+'Pano Fijo'!D131 -> 20.1892 | O4: =+'Pano Fijo'!F131 -> 65.63 | P4: =+'Pano Fijo'!G131 -> 1.116
E5: Vidrio Templado 8mm Incoloro | F5: =+'P-V.Corrediza'!C130 -> 38.51 | G5: =+'P-V.Corrediza'!D130 -> 13.57476 | H5: =+'P-V.Corrediza'!E130 -> 46.26 | I5: =+'P-V.Corrediza'!G130 -> 39.11 | J5: =+F5*$A$3+G5*$B$3+H5*$A$3*$B$3+$C$3*I5 -> 338.929 | L5: Vidrio Templado 8mm Incoloro | M5: =+'Pano Fijo'!C132 -> 20.1892 | N5: =+'Pano Fijo'!D132 -> 20.1892 | O5: =+'Pano Fijo'!F132 -> 47.4 | P5: =+'Pano Fijo'!G132 -> 1.116
E6: Vidrio Templado 8mm Color | F6: =+'P-V.Corrediza'!C131 -> 38.51 | G6: =+'P-V.Corrediza'!D131 -> 13.57476 | H6: =+'P-V.Corrediza'!E131 -> 62.21 | I6: =+'P-V.Corrediza'!G131 -> 39.11 | J6: =+F6*$A$3+G6*$B$3+H6*$A$3*$B$3+$C$3*I6 -> 405.919 | L6: Vidrio Templado 8mm Color | M6: =+'Pano Fijo'!C133 -> 20.1892 | N6: =+'Pano Fijo'!D133 -> 20.1892 | O6: =+'Pano Fijo'!F133 -> 63.35 | P6: =+'Pano Fijo'!G133 -> 1.116
E7: PUERTA CORREDIZA 4 HOJAS
E8: Vidrio Templado 10mm Incoloro | F8: =+'P-V.Corrediza'!C162 -> 38.36 | G8: =+'P-V.Corrediza'!D162 -> 9.57036 | H8: =+'P-V.Corrediza'!E162 -> 48.54 | I8: =+'P-V.Corrediza'!G162 -> 59.81 | J8: =+F8*$A$3+G8*$B$3+H8*$A$3*$B$3+$C$3*I8 -> 360.49576 | M8: B | N8: H | O8: BxH | P8: CANT.
E9: Vidrio Templado 10mm Color | F9: =+'P-V.Corrediza'!C163 -> 38.36 | G9: =+'P-V.Corrediza'!D163 -> 9.57036 | H9: =+'P-V.Corrediza'!E163 -> 64.49 | I9: =+'P-V.Corrediza'!G163 -> 59.81 | J9: =+F9*$A$3+G9*$B$3+H9*$A$3*$B$3+$C$3*I9 -> 427.48576 | L9: PUERTA BATIENTE 1 HOJA
E10: Vidrio Templado 8mm Incoloro | F10: =+'P-V.Corrediza'!C164 -> 38.36 | G10: =+'P-V.Corrediza'!D164 -> 9.57036 | H10: =+'P-V.Corrediza'!E164 -> 46.26 | I10: =+'P-V.Corrediza'!G164 -> 59.81 | J10: =+F10*$A$3+G10*$B$3+H10*$A$3*$B$3+$C$3*I10 -> 350.91976 | L10: Vidrio Templado 10mm Incoloro | M10: =+P.Batiente!D157 -> 0 | N10: =+P.Batiente!E157 -> 0 | O10: =+P.Batiente!F157 -> 48.54 | P10: =+P.Batiente!H157 -> 146.07
E11: Vidrio Templado 8mm Color | F11: =+'P-V.Corrediza'!C165 -> 38.36 | G11: =+'P-V.Corrediza'!D165 -> 9.57036 | H11: =+'P-V.Corrediza'!E165 -> 62.21 | I11: =+'P-V.Corrediza'!G165 -> 59.81 | J11: =+F11*$A$3+G11*$B$3+H11*$A$3*$B$3+$C$3*I11 -> 417.90976 | L11: Vidrio Templado 10mm Color | M11: =+P.Batiente!D158 -> 0 | N11: =+P.Batiente!E158 -> 0 | O11: =+P.Batiente!F158 -> 64.49 | P11: =+P.Batiente!H158 -> 146.07
E12: VENTANA CORREDIZA 2 HOJAS | L12: PUERTA BATIENTE 2 HOJAS
E13: Vidrio Templado 10mm Incoloro | F13: =+'P-V.Corrediza'!C196 -> 38.36 | G13: =+'P-V.Corrediza'!D196 -> 13.27476 | H13: =+'P-V.Corrediza'!E196 -> 48.54 | I13: =+'P-V.Corrediza'!G196 -> 18.54 | J13: =+F13*$A$3+G13*$B$3+H13*$A$3*$B$3+$C$3*I13 -> 327.005 | L13: Vidrio Templado 10mm Incoloro | M13: =+P.Batiente!D139 -> 0 | N13: =+P.Batiente!E139 -> 9 | O13: =+P.Batiente!F139 -> 48.54 | P13: =+P.Batiente!H139 -> 290.43
E14: Vidrio Templado 10mm Color | F14: =+'P-V.Corrediza'!C197 -> 38.36 | G14: =+'P-V.Corrediza'!D197 -> 13.27476 | H14: =+'P-V.Corrediza'!E197 -> 64.49 | I14: =+'P-V.Corrediza'!G197 -> 18.54 | J14: =+F14*$A$3+G14*$B$3+H14*$A$3*$B$3+$C$3*I14 -> 393.995 | L14: Vidrio Templado 10mm Color | M14: =+P.Batiente!D140 -> 0 | N14: =+P.Batiente!E140 -> 9 | O14: =+P.Batiente!F140 -> 64.49 | P14: =+P.Batiente!H140 -> 290.43
E15: Vidrio Templado 8mm Incoloro | F15: =+'P-V.Corrediza'!C198 -> 38.36 | G15: =+'P-V.Corrediza'!D198 -> 13.27476 | H15: =+'P-V.Corrediza'!E198 -> 46.26 | I15: =+'P-V.Corrediza'!G198 -> 18.54 | J15: =+F15*$A$3+G15*$B$3+H15*$A$3*$B$3+$C$3*I15 -> 317.429 | L15: PUERTA BATIENTE 2 HOJAS+FIJOS
E16: Vidrio Templado 8mm Color | F16: =+'P-V.Corrediza'!C199 -> 38.36 | G16: =+'P-V.Corrediza'!D199 -> 13.27476 | H16: =+'P-V.Corrediza'!E199 -> 62.21 | I16: =+'P-V.Corrediza'!G199 -> 18.54 | J16: =+F16*$A$3+G16*$B$3+H16*$A$3*$B$3+$C$3*I16 -> 384.419 | L16: Vidrio Templado 10mm Incoloro | M16: =+P.Batiente!D117 -> 4.0239 | N16: =+P.Batiente!E117 -> 11.29195 | O16: =+P.Batiente!F117 -> 48.54 | P16: =+P.Batiente!H117 -> 290.43
E17: VENTANA CORREDIZA 4 HOJAS | L17: Vidrio Templado 10mm Color | M17: =+P.Batiente!D118 -> 4.0239 | N17: =+P.Batiente!E118 -> 11.29195 | O17: =+P.Batiente!F118 -> 64.49 | P17: =+P.Batiente!H118 -> 290.43
E18: Vidrio Templado 10mm Incoloro | F18: =+'P-V.Corrediza'!C230 -> 38.36 | G18: =+'P-V.Corrediza'!D230 -> 9.57036 | H18: =+'P-V.Corrediza'!E230 -> 48.54 | I18: =+'P-V.Corrediza'!G230 -> 37.08 | J18: =+F18*$A$3+G18*$B$3+H18*$A$3*$B$3+$C$3*I18 -> 337.76576
E19: Vidrio Templado 10mm Color | F19: =+'P-V.Corrediza'!C231 -> 38.36 | G19: =+'P-V.Corrediza'!D231 -> 9.57036 | H19: =+'P-V.Corrediza'!E231 -> 64.49 | I19: =+'P-V.Corrediza'!G231 -> 37.08 | J19: =+F19*$A$3+G19*$B$3+H19*$A$3*$B$3+$C$3*I19 -> 404.75576
E20: Vidrio Templado 8mm Incoloro | F20: =+'P-V.Corrediza'!C232 -> 38.36 | G20: =+'P-V.Corrediza'!D232 -> 9.57036 | H20: =+'P-V.Corrediza'!E232 -> 46.26 | I20: =+'P-V.Corrediza'!G232 -> 37.08 | J20: =+F20*$A$3+G20*$B$3+H20*$A$3*$B$3+$C$3*I20 -> 328.18976
E21: Vidrio Templado 8mm Color | F21: =+'P-V.Corrediza'!C233 -> 38.36 | G21: =+'P-V.Corrediza'!D233 -> 9.57036 | H21: =+'P-V.Corrediza'!E233 -> 62.21 | I21: =+'P-V.Corrediza'!G233 -> 37.08 | J21: =+F21*$A$3+G21*$B$3+H21*$A$3*$B$3+$C$3*I21 -> 395.17976
F23: B | G23: H | H23: BXH | I23: (N-1)*(M-1) | J23: (N-1) | K23: (N-1)*H | L23: (M-1)*B
E24: FACHADA CON ARANAS
E25: Vidrio Templado 10mm Incoloro | F25: =+'Fachada tub.herr.'!C107 -> 4.44316 | G25: =+'Fachada tub.herr.'!E107 -> 4.44316 | H25: =+'Fachada tub.herr.'!I107 -> 49.68 | I25: =+'Fachada tub.herr.'!J107 -> 159.51 | J25: =+'Fachada tub.herr.'!B132 -> 27.36 | K25: =+'Fachada tub.herr.'!C132 -> 30.445 | L25: =+'Fachada tub.herr.'!E132 -> 0.5442
E26: Vidrio Templado 10mm Color | F26: =+'Fachada tub.herr.'!C108 -> 4.44316 | G26: =+'Fachada tub.herr.'!E108 -> 4.44316 | H26: =+'Fachada tub.herr.'!I108 -> 65.63 | I26: =+'Fachada tub.herr.'!J108 -> 159.51 | J26: =+'Fachada tub.herr.'!B133 -> 27.36 | K26: =+'Fachada tub.herr.'!C133 -> 30.445 | L26: =+'Fachada tub.herr.'!E133 -> 0.5442
E27: Vidrio Templado 8mm Incoloro | F27: =+'Fachada tub.herr.'!C109 -> 4.44316 | G27: =+'Fachada tub.herr.'!E109 -> 4.44316 | H27: =+'Fachada tub.herr.'!I109 -> 47.4 | I27: =+'Fachada tub.herr.'!J109 -> 159.51 | J27: =+'Fachada tub.herr.'!B134 -> 27.36 | K27: =+'Fachada tub.herr.'!C134 -> 30.445 | L27: =+'Fachada tub.herr.'!E134 -> 0.5442
E28: Vidrio Templado 8mm Color | F28: =+'Fachada tub.herr.'!C110 -> 4.44316 | G28: =+'Fachada tub.herr.'!E110 -> 4.44316 | H28: =+'Fachada tub.herr.'!I110 -> 63.35 | I28: =+'Fachada tub.herr.'!J110 -> 159.51 | J28: =+'Fachada tub.herr.'!B135 -> 27.36 | K28: =+'Fachada tub.herr.'!C135 -> 30.445 | L28: =+'Fachada tub.herr.'!E135 -> 0.5442
E29: FACHADA CON HERRAJES Y VIENTOS
E30: Vidrio Templado 10mm Incoloro | F30: =+'Fachada tub.herr.'!C158 -> 4.44316 | G30: =+'Fachada tub.herr.'!E158 -> 4.44316 | H30: =+'Fachada tub.herr.'!I158 -> 49.68 | I30: =+'Fachada tub.herr.'!J158 -> 17.06 | J30: =+'Fachada tub.herr.'!B183 -> 35.54 | K30: =+'Fachada tub.herr.'!C183 -> 2.347 | L30: =+'Fachada tub.herr.'!E183 -> 0.5442
E31: Vidrio Templado 10mm Color | F31: =+'Fachada tub.herr.'!C159 -> 4.44316 | G31: =+'Fachada tub.herr.'!E159 -> 4.44316 | H31: =+'Fachada tub.herr.'!I159 -> 65.63 | I31: =+'Fachada tub.herr.'!J159 -> 17.06 | J31: =+'Fachada tub.herr.'!B184 -> 35.54 | K31: =+'Fachada tub.herr.'!C184 -> 2.347 | L31: =+'Fachada tub.herr.'!E184 -> 0.5442
E32: Vidrio Templado 8mm Incoloro | F32: =+'Fachada tub.herr.'!C160 -> 4.44316 | G32: =+'Fachada tub.herr.'!E160 -> 4.44316 | H32: =+'Fachada tub.herr.'!I160 -> 47.4 | I32: =+'Fachada tub.herr.'!J160 -> 17.06 | J32: =+'Fachada tub.herr.'!B185 -> 35.54 | K32: =+'Fachada tub.herr.'!C185 -> 2.347 | L32: =+'Fachada tub.herr.'!E185 -> 0.5442
E33: Vidrio Templado 8mm Color | F33: =+'Fachada tub.herr.'!C161 -> 4.44316 | G33: =+'Fachada tub.herr.'!E161 -> 4.44316 | H33: =+'Fachada tub.herr.'!I161 -> 63.35 | I33: =+'Fachada tub.herr.'!J161 -> 17.06 | J33: =+'Fachada tub.herr.'!B186 -> 35.54 | K33: =+'Fachada tub.herr.'!C186 -> 2.347 | L33: =+'Fachada tub.herr.'!E186 -> 0.5442

Sheet Fachada tub.herr.
A2: FACHADA EN VIDRIO TEMPLADO | D2: PF | E2: PF | F2: PF | G2: PF | I2: Total | K2: PF | L2: PF
A3: HERRAJES Y VIENTOS VIDRIO o TUBULAR 4" CON ARANA | D3: =IF(D11=8,"8 mm.","10 mm.") -> 10 mm. | E3: =IF(E11=8,"8 mm.","10 mm.") -> 10 mm. | F3: =IF(F11=8,"8 mm.","10 mm.") -> 8 mm. | G3: =IF(G11=8,"8 mm.","10 mm.") -> 8 mm. | K3: =IF(K11=8,"8 mm.","10 mm.") -> 10 mm. | L3: =IF(L11=8,"8 mm.","10 mm.") -> 10 mm.
A4: DATOS BASE PARA EL ANALISIS | D4: =IF(D10=1,"INCOLORO","COLOR") -> INCOLORO | E4: =IF(E10=1,"INCOLORO","COLOR") -> COLOR | F4: =IF(F10=1,"INCOLORO","COLOR") -> INCOLORO | G4: =IF(G10=1,"INCOLORO","COLOR") -> COLOR | K4: =IF(K10=1,"INCOLORO","COLOR") -> INCOLORO | L4: =IF(L10=1,"INCOLORO","COLOR") -> INCOLORO
A5: BASE ( Metros ) | B5: B | D5: 6 | E5: 6 | F5: 6 | G5: 6 | K5: 6 | L5: 6
A6: ALTURA ( Metros ) | B6: H | D6: 6 | E6: 6 | F6: 6 | G6: 6 | K6: 6 | L6: 6
A7: CANTIDAD DE PIEZAS | B7: N | D7: 1 | E7: 1 | F7: 1 | G7: 1 | I7: =SUM(K7:IV7) -> 32 | J7: Pzas. | K7: 16 | L7: 16
A8: n = div. Verticales | B8: NV | D8: 4 | E8: 4 | F8: 4 | G8: 4 | K8: 5 | L8: 5
A9: m = div. Horizontales | B9: NM | D9: 4 | E9: 4 | F9: 4 | G9: 4 | K9: 3 | L9: 3
A10: INCOLORO = 1 ; COLOR =2 | B10: C | D10: 1 | E10: 2 | F10: 1 | G10: 2 | K10: 1 | L10: 1
A11: ESPESOR DEL VIDRIO = 8 ó 10 mm. | B11: E | D11: 10 | E11: 10 | F11: 8 | G11: 8 | K11: 10 | L11: 10
A12: ESMERILADO = E | B12: ES
A13: VIENTOS VIDRIO ( 1 ) o TUBULAR + ARANA ( 2 ) | D13: 2 | E13: 1 | F13: 2 | G13: 2 | K13: 1 | L13: 2
A14: MODULOS
A15: ANCHO ( metros ) | D15: =+D5/D8 -> 1.5 | E15: =+E5/E8 -> 1.5 | F15: =+F5/F8 -> 1.5 | G15: =+G5/G8 -> 1.5 | K15: =+K5/K8 -> 1.2 | L15: =+L5/L8 -> 1.2
A16: ALTO ( metros ) | D16: =+D6/D9 -> 1.5 | E16: =+E6/E9 -> 1.5 | F16: =+F6/F9 -> 1.5 | G16: =+G6/G9 -> 1.5 | K16: =+K6/K9 -> 2 | L16: =+L6/L9 -> 2
A17: Total Precio c/factura | C17: pn | D17: =+D46 -> 4008.864 | E17: =+E46 -> 2944.233 | F17: =+F46 -> 3926.1 | G17: =+G46 -> 4490.046 | I17: =SUM(K17:IV17) -> 150891.84 | J17: $us. | K17: =+K46 -> 40178.336 | L17: =+L46 -> 110713.5
A18: Superficie Mt² | D18: =+D5*D6*D$7+IF(D13=1,D7*D6*(D8-1)*0.2,0) -> 36 | E18: =+E5*E6*E$7+IF(E13=1,E7*E6*(E8-1)*0.2,0) -> 39.6 | F18: =+F5*F6*F$7+IF(F13=1,F7*F6*(F8-1)*0.2,0) -> 36 | G18: =+G5*G6*G$7+IF(G13=1,G7*G6*(G8-1)*0.2,0) -> 36 | I18: =SUM(K18:IV18) -> 1228.8 | J18: Mt² | K18: =+K5*K6*K$7+IF(K13=1,K7*K6*(K8-1)*0.2,0) -> 652.8 | L18: =+L5*L6*L$7+IF(L13=1,L7*L6*(L8-1)*0.2,0) -> 576
A19: Precio con factura en $us / Mt² | D19: =+D17/D18 -> 111.35733 | E19: =+E17/E18 -> 74.349318 | F19: =+F17/F18 -> 109.05833 | G19: =+G17/G18 -> 124.7235 | I19: =+I17/I18 -> 122.79609 | J19: $us./Mt² | K19: =+K17/K18 -> 61.547696 | L19: =+L17/L18 -> 192.21094
A20: Total Precio s/factura | D20: =+D67 -> 3704.334 | E20: =+E67 -> 2722.014 | F20: =+F67 -> 3624.474 | G20: =+G67 -> 4169.634 | I20: =SUM(K20:IV20) -> 142475.01 | J20: $us. | K20: =+K67 -> 36793.344 | L20: =+L67 -> 105681.66
A21: Precio sin factura en $us / Mt² | D21: =+D20/D18 -> 102.89817 | E21: =+E20/E18 -> 68.737727 | F21: =+F20/F18 -> 100.67983 | G21: =+G20/G18 -> 115.82317 | I21: =+I20/I18 -> 115.94646 | J21: $us./Mt² | K21: =+K20/K18 -> 56.362353 | L21: =+L20/L18 -> 183.47511
A22: % descuento del con al sin | D22: =+(D17-D20)/D17 -> 0.075964163 | E22: =+(E17-E20)/E17 -> 0.075476024 | F22: =+(F17-F20)/F17 -> 0.076825858 | G22: =+(G17-G20)/G17 -> 0.071360516 | I22: =+(I17-I20)/I17 -> 0.055780564 | K22: =+(K17-K20)/K17 -> 0.084249183 | L22: =+(L17-L20)/L17 -> 0.045449198
A24: DETALLE DE MATERIALES A UTILIZAR
A25: MATERIAL | C25: Unidad | D25: =+D2 -> PF | E25: =+E2 -> PF | F25: =+F2 -> PF | G25: =+G2 -> PF | I25: Cantidad | J25: Unidad | K25: =+K2 -> PF | L25: =+L2 -> PF
A26: Vidrio Templado 10mm Incoloro | C26: Mt² | D26: =IF(D$10=1,IF(D$11=10,((D$6*0.05)+(D$5*D$6))*D$7+IF(D13=1,D$7*D6*(D8-1)*0.2,0),0),0) -> 36.3 | E26: =IF(E$10=1,IF(E$11=10,((E$6*0.05)+(E$5*E$6))*E$7+IF(E13=1,E$7*E6*(E8-1)*0.2,0),0),0) -> 0 | F26: =IF(F$10=1,IF(F$11=10,((F$6*0.05)+(F$5*F$6))*F$7+IF(F13=1,F$7*F6*(F8-1)*0.2,0),0),0) -> 0 | G26: =IF(G$10=1,IF(G$11=10,((G$6*0.05)+(G$5*G$6))*G$7+IF(G13=1,G$7*G6*(G8-1)*0.2,0),0),0) -> 0 | I26: =ROUNDUP(SUM(K26:IV26),1) -> 1238.4 | J26: Mt² | K26: =IF(K$10=1,IF(K$11=10,((K$6*0.05)+(K$5*K$6))*K$7+IF(K13=1,K$7*K6*(K8-1)*0.2,0),0),0) -> 657.6 | L26: =IF(L$10=1,IF(L$11=10,((L$6*0.05)+(L$5*L$6))*L$7+IF(L13=1,L$7*L6*(L8-1)*0.2,0),0),0) -> 580.8
A27: Vidrio Templado 10mm Color | C27: Mt² | D27: =IF(D$10=2,IF(D$11=10,((D$6*0.05)+(D$5*D$6))*D$7+IF(D13=1,D7*D6*(D8-1)*0.2,0),0),0) -> 0 | E27: =IF(E$10=2,IF(E$11=10,((E$6*0.05)+(E$5*E$6))*E$7+IF(E13=1,E7*E6*(E8-1)*0.2,0),0),0) -> 39.9 | F27: =IF(F$10=2,IF(F$11=10,((F$6*0.05)+(F$5*F$6))*F$7+IF(F13=1,F7*F6*(F8-1)*0.2,0),0),0) -> 0 | G27: =IF(G$10=2,IF(G$11=10,((G$6*0.05)+(G$5*G$6))*G$7+IF(G13=1,G7*G6*(G8-1)*0.2,0),0),0) -> 0 | I27: =ROUNDUP(SUM(K27:IV27),1) -> 0 | J27: Mt² | K27: =IF(K$10=2,IF(K$11=10,((K$6*0.05)+(K$5*K$6))*K$7+IF(K13=1,K7*K6*(K8-1)*0.2,0),0),0) -> 0 | L27: =IF(L$10=2,IF(L$11=10,((L$6*0.05)+(L$5*L$6))*L$7+IF(L13=1,L7*L6*(L8-1)*0.2,0),0),0) -> 0
A28: Vidrio Templado 8mm Incoloro | C28: Mt² | D28: =IF(D$10=1,IF(D$11=8,((D$6*0.05)+(D$5*D$6))*D$7+IF(D13=1,D7*D6*(D8-1)*0.2,0),0),0) -> 0 | E28: =IF(E$10=1,IF(E$11=8,((E$6*0.05)+(E$5*E$6))*E$7+IF(E13=1,E7*E6*(E8-1)*0.2,0),0),0) -> 0 | F28: =IF(F$10=1,IF(F$11=8,((F$6*0.05)+(F$5*F$6))*F$7+IF(F13=1,F7*F6*(F8-1)*0.2,0),0),0) -> 36.3 | G28: =IF(G$10=1,IF(G$11=8,((G$6*0.05)+(G$5*G$6))*G$7+IF(G13=1,G7*G6*(G8-1)*0.2,0),0),0) -> 0 | I28: =ROUNDUP(SUM(K28:IV28),1) -> 0 | J28: Mt² | K28: =IF(K$10=1,IF(K$11=8,((K$6*0.05)+(K$5*K$6))*K$7+IF(K13=1,K7*K6*(K8-1)*0.2,0),0),0) -> 0 | L28: =IF(L$10=1,IF(L$11=8,((L$6*0.05)+(L$5*L$6))*L$7+IF(L13=1,L7*L6*(L8-1)*0.2,0),0),0) -> 0
A29: Vidrio Templado 8mm Color | C29: Mt² | D29: =IF(D$10=2,IF(D$11=8,((D$5*D$6))*D$7+IF(D13=1,D7*D6*(D8-1)*0.2,0),0),0) -> 0 | E29: =IF(E$10=2,IF(E$11=8,((E$5*E$6))*E$7+IF(E13=1,E7*E6*(E8-1)*0.2,0),0),0) -> 0 | F29: =IF(F$10=2,IF(F$11=8,((F$5*F$6))*F$7+IF(F13=1,F7*F6*(F8-1)*0.2,0),0),0) -> 0 | G29: =IF(G$10=2,IF(G$11=8,((G$5*G$6))*G$7+IF(G13=1,G7*G6*(G8-1)*0.2,0),0),0) -> 36 | I29: =ROUNDUP(SUM(K29:IV29),1) -> 0 | J29: Mt² | K29: =IF(K$10=2,IF(K$11=8,((K$5*K$6))*K$7+IF(K13=1,K7*K6*(K8-1)*0.2,0),0),0) -> 0 | L29: =IF(L$10=2,IF(L$11=8,((L$5*L$6))*L$7+IF(L13=1,L7*L6*(L8-1)*0.2,0),0),0) -> 0
A30: Mano de obra | C30: Mt² | D30: =+D18 -> 36 | E30: =+E18 -> 39.6 | F30: =+F18 -> 36 | G30: =+G18 -> 36 | I30: =ROUNDUP(SUM(K30:IV30),1) -> 1228.8 | J30: Mt² | K30: =+K18 -> 652.8 | L30: =+L18 -> 576
A31: Silicona transp., blanca o negra | C31: Tubo | D31: =D7*(4*D5+4*D6+(D8-1)*D6+(D9-1)*D5)/6 -> 14 | E31: =E7*(4*E5+4*E6+(E8-1)*E6+(E9-1)*E5)/6 -> 14 | F31: =F7*(4*F5+4*F6+(F8-1)*F6+(F9-1)*F5)/6 -> 14 | G31: =G7*(4*G5+4*G6+(G8-1)*G6+(G9-1)*G5)/6 -> 14 | I31: =ROUNDUP(SUM(K31:IV31),1) -> 448 | J31: Tubo | K31: =K7*(4*K5+4*K6+(K8-1)*K6+(K9-1)*K5)/6 -> 224 | L31: =L7*(4*L5+4*L6+(L8-1)*L6+(L9-1)*L5)/6 -> 224
A32: Cinta masking 1/2 " (rollo de 20) | C32: Rollo | D32: =+D7*D31*12/20 -> 8.4 | E32: =+E7*E31*12/20 -> 8.4 | F32: =+F7*F31*12/20 -> 8.4 | G32: =+G7*G31*12/20 -> 8.4 | I32: =ROUNDUP(SUM(K32:IV32),1) -> 4300.8 | J32: Rollo | K32: =+K7*K31*12/20 -> 2150.4 | L32: =+L7*L31*12/20 -> 2150.4
A33: "U" 15x25 - Kg/Mt lineal. | B33: 0.2 | C33: Kgr | D33: =(2*D$6+2*D5)*$B33*D$7 -> 4.8 | E33: =(2*E$6+2*E5)*$B33*E$7 -> 4.8 | F33: =(2*F$6+2*F5)*$B33*F$7 -> 4.8 | G33: =(2*G$6+2*G5)*$B33*G$7 -> 4.8 | I33: =ROUNDUP(SUM(K33:IV33)/(6*B33),1) -> 128 | J33: BARRAS | K33: =(2*K$6+2*K5)*$B33*K$7 -> 76.8 | L33: =(2*L$6+2*L5)*$B33*L$7 -> 76.8
A34: Esmerilado | C34: Mt² | D34: =IF((D12="e"),D18*D7,IF( (D12="E"),D18*D7,0)) -> 0 | E34: =IF((E12="e"),E18*E7,IF( (E12="E"),E18*E7,0)) -> 0 | F34: =IF((F12="e"),F18*F7,IF( (F12="E"),F18*F7,0)) -> 0 | G34: =IF((G12="e"),G18*G7,IF( (G12="E"),G18*G7,0)) -> 0 | I34: =ROUNDUP(SUM(K34:IV34),1) -> 0 | J34: Mt² | K34: =IF((K12="e"),K18*K7,IF( (K12="E"),K18*K7,0)) -> 0 | L34: =IF((L12="e"),L18*L7,IF( (L12="E"),L18*L7,0)) -> 0
A35: Tarugos No. 6 | C35: Pza. | D35: =D$7*(2*D$5+2*D$6)/0.4 -> 60 | E35: =E$7*(2*E$5+2*E$6)/0.4 -> 60 | F35: =F$7*(2*F$5+2*F$6)/0.4 -> 60 | G35: =G$7*(2*G$5+2*G$6)/0.4 -> 60 | I35: =ROUNDUP(SUM(K35:IV35),1) -> 1920 | J35: Pza. | K35: =K$7*(2*K$5+2*K$6)/0.4 -> 960 | L35: =L$7*(2*L$5+2*L$6)/0.4 -> 960
A36: Tornillos 8 x 1 1/2 | C36: Pza. | D36: =D$7*(2*D$5+2*D$6)/0.4 -> 60 | E36: =E$7*(2*E$5+2*E$6)/0.4 -> 60 | F36: =F$7*(2*F$5+2*F$6)/0.4 -> 60 | G36: =G$7*(2*G$5+2*G$6)/0.4 -> 60 | I36: =ROUNDUP(SUM(K36:IV36),1) -> 1920 | J36: Pza. | K36: =K$7*(2*K$5+2*K$6)/0.4 -> 960 | L36: =L$7*(2*L$5+2*L$6)/0.4 -> 960
A37: Tubo galvanizado de 4" | C37: Mt.lin. | D37: =IF(D13=2,D7*(D8-1)*D6,0) -> 18 | E37: =IF(E13=2,E7*(E8-1)*E6,0) -> 0 | F37: =IF(F13=2,F7*(F8-1)*F6,0) -> 18 | G37: =IF(G13=2,G7*(G8-1)*G6,0) -> 18 | I37: =ROUNDUP(SUM(K37:IV37),1) -> 384 | J37: Mt.lin. | K37: =IF(K13=2,K7*(K8-1)*K6,0) -> 0 | L37: =IF(L13=2,L7*(L8-1)*L6,0) -> 384
A38: Herraje arana | C38: Pza. | D38: =IF(D13=2,D7*(D8-1)*(D9-1),0) -> 9 | E38: =IF(E13=2,E7*(E8-1)*(E9-1),0) -> 0 | F38: =IF(F13=2,F7*(F8-1)*(F9-1),0) -> 9 | G38: =IF(G13=2,G7*(G8-1)*(G9-1),0) -> 9 | I38: =ROUNDUP(SUM(K38:IV38),1) -> 128 | J38: Pza. | K38: =IF(K13=2,K7*(K8-1)*(K9-1),0) -> 0 | L38: =IF(L13=2,L7*(L8-1)*(L9-1),0) -> 128
A39: Soporte Herraje - tubo | C39: Pza. | D39: =+D38*D7 -> 9 | E39: =+E38*E7 -> 0 | F39: =+F38*F7 -> 9 | G39: =+G38*G7 -> 9 | I39: =ROUNDUP(SUM(K39:IV39),1) -> 2048 | J39: Pza. | K39: =+K38*K7 -> 0 | L39: =+L38*L7 -> 2048
A40: Anclaje tubo | C40: Pza. | D40: =+(D8-1)*2*D7 -> 6 | E40: =+(E8-1)*2*E7 -> 6 | F40: =+(F8-1)*2*F7 -> 6 | G40: =+(G8-1)*2*G7 -> 6 | I40: =ROUNDUP(SUM(K40:IV40),1) -> 256 | J40: Pza. | K40: =+(K8-1)*2*K7 -> 128 | L40: =+(L8-1)*2*L7 -> 128
A41: 1318 | C41: Pza. | D41: =IF(D13=1,D7*(D8-1)*(D9-1),0) -> 0 | E41: =IF(E13=1,E7*(E8-1)*(E9-1),0) -> 9 | F41: =IF(F13=1,F7*(F8-1)*(F9-1),0) -> 0 | G41: =IF(G13=1,G7*(G8-1)*(G9-1),0) -> 0 | I41: =ROUNDUP(SUM(K41:IV41),1) -> 128 | J41: Pza. | K41: =IF(K13=1,K7*(K8-1)*(K9-1),0) -> 128 | L41: =IF(L13=1,L7*(L8-1)*(L9-1),0) -> 0
A42: 1302 | C42: Pza. | D42: =IF(D13=1,D7*2*(D8-1),0) -> 0 | E42: =IF(E13=1,E7*2*(E8-1),0) -> 6 | F42: =IF(F13=1,F7*2*(F8-1),0) -> 0 | G42: =IF(G13=1,G7*2*(G8-1),0) -> 0 | I42: =ROUNDUP(SUM(K42:IV42),1) -> 128 | J42: Pza. | K42: =IF(K13=1,K7*2*(K8-1),0) -> 128 | L42: =IF(L13=1,L7*2*(L8-1),0) -> 0
...

Sheet P-V.Corrediza
A2: PUERTA / VENTANA CORREDIZA | D2: =IF(D8=1,"PC2H","VC2H") -> PC2H | E2: =IF(E8=1,"PC4H","VC4H") -> PC4H | G2: Total | I2: =IF(I8=1,"PC2H","VC2H") -> VC2H | J2: =IF(J8=1,"PC2H","VC2H") -> VC2H | K2: =IF(K8=1,"PC2H","VC2H") -> VC2H | L2: =IF(L8=1,"PC2H","VC2H") -> VC2H | M2: =IF(M8=1,"PC2H","VC2H") -> VC2H | N2: =IF(N8=1,"PC2H","VC2H") -> VC2H | O2: =IF(O8=1,"PC2H","VC2H") -> VC2H | P2: =IF(P8=1,"PC2H","VC2H") -> VC2H | Q2: =IF(Q8=1,"PC2H","VC2H") -> PC2H
A3: 8 o 10 mm. c/PERFIL U 15x15 DE ALUMINIO | D3: =IF(D10=8,"8 mm.","10 mm.") -> 10 mm. | E3: =IF(E10=8,"8 mm.","10 mm.") -> 8 mm. | I3: =IF(I10=8,"8 mm.","10 mm.") -> 10 mm. | J3: =IF(J10=8,"8 mm.","10 mm.") -> 10 mm. | K3: =IF(K10=8,"8 mm.","10 mm.") -> 10 mm. | L3: =IF(L10=8,"8 mm.","10 mm.") -> 10 mm. | M3: =IF(M10=8,"8 mm.","10 mm.") -> 10 mm. | N3: =IF(N10=8,"8 mm.","10 mm.") -> 10 mm. | O3: =IF(O10=8,"8 mm.","10 mm.") -> 10 mm. | P3: =IF(P10=8,"8 mm.","10 mm.") -> 10 mm. | Q3: =IF(Q10=8,"8 mm.","10 mm.") -> 10 mm.
A4: DATOS BASE PARA EL ANALISIS | D4: =IF(D9=1,"INCOLORO","COLOR") -> INCOLORO | E4: =IF(E9=1,"INCOLORO","COLOR") -> INCOLORO | I4: =IF(I9=1,"INCOLORO","COLOR") -> INCOLORO | J4: =IF(J9=1,"INCOLORO","COLOR") -> INCOLORO | K4: =IF(K9=1,"INCOLORO","COLOR") -> INCOLORO | L4: =IF(L9=1,"INCOLORO","COLOR") -> INCOLORO | M4: =IF(M9=1,"INCOLORO","COLOR") -> INCOLORO | N4: =IF(N9=1,"INCOLORO","COLOR") -> INCOLORO | O4: =IF(O9=1,"INCOLORO","COLOR") -> INCOLORO | P4: =IF(P9=1,"INCOLORO","COLOR") -> INCOLORO | Q4: =IF(Q9=1,"INCOLORO","COLOR") -> INCOLORO
A5: BASE ( Metros ) | D5: 1 | E5: 1 | I5: 1.995 | J5: 2 | K5: 1.2 | L5: 2 | M5: 1.69 | N5: 1.51 | O5: 0.705 | P5: 1.47 | Q5: 1.72
A6: ALTURA ( Metros ) | D6: 1 | E6: 1 | I6: 0.745 | J6: 1.5 | K6: 1.025 | L6: 1.48 | M6: 1.5 | N6: 1.435 | O6: 0.505 | P6: 2 | Q6: 2.1
A7: CANTIDAD DE PIEZAS | D7: 1 | E7: 1 | G7: =SUM(I7:IV7) -> 9 | H7: Pzas. | I7: 1 | J7: 1 | K7: 1 | L7: 1 | M7: 1 | N7: 1 | O7: 1 | P7: 1 | Q7: 1
A8: PUERTA = 1; VENTANA = 2 | D8: 1 | E8: 1 | I8: 2 | J8: 2 | K8: 2 | L8: 2 | M8: 2 | N8: 2 | O8: 2 | P8: 2 | Q8: 1
A9: INCOLORO = 1 ; COLOR =2 | D9: 1 | E9: 1 | I9: 1 | J9: 1 | K9: 1 | L9: 1 | M9: 1 | N9: 1 | O9: 1 | P9: 1 | Q9: 1
A10: ESPESOR DEL VIDRIO = 8 ó 10 mm. | D10: 10 | E10: 8 | I10: 10 | J10: 10 | K10: 10 | L10: 10 | M10: 10 | N10: 10 | O10: 10 | P10: 10 | Q10: 10
A11: Total Precio c/factura | C11: pn | D11: =+D48 -> 116.9145 | E11: =+E48 -> 138.81906 | G11: =SUM(I11:IV11) -> 1573.6438 | H11: $us. | I11: =+I48 -> 138.65044 | J11: =+J48 -> 218.52259 | K11: =+K48 -> 111.90336 | L11: =+L48 -> 216.41433 | M11: =+M48 -> 189.46267 | N11: =+N48 -> 167.28333 | O11: =+O48 -> 54.786362 | P11: =+P48 -> 208.68281 | Q11: =+Q48 -> 267.93789
A12: Superficie Mt² | D12: =+D5*D6*D$7 -> 1 | E12: =+E5*E6*E$7 -> 1 | G12: =SUM(I12:IV12) -> 20.28615 | H12: Mt² | I12: =+I5*I6*I$7 -> 1.486275 | J12: =+J5*J6*J$7 -> 3 | K12: =+K5*K6*K$7 -> 1.23 | L12: =+L5*L6*L$7 -> 2.96 | M12: =+M5*M6*M$7 -> 2.535 | N12: =+N5*N6*N$7 -> 2.16685 | O12: =+O5*O6*O$7 -> 0.356025 | P12: =+P5*P6*P$7 -> 2.94 | Q12: =+Q5*Q6*Q$7 -> 3.612
A13: Precio con factura en $us / Mt² | D13: =+D11/D12 -> 116.9145 | E13: =+E11/E12 -> 138.81906 | G13: =+G11/G12 -> 77.572323 | H13: $us./Mt² | I13: =+I11/I12 -> 93.287205 | J13: =+J11/J12 -> 72.840863 | K13: =+K11/K12 -> 90.978339 | L13: =+L11/L12 -> 73.112951 | M13: =+M11/M12 -> 74.738726 | N13: =+N11/N12 -> 77.20116 | O13: =+O11/O12 -> 153.88347 | P13: =+P11/P12 -> 70.980547 | Q13: =+Q11/Q12 -> 74.179926
A14: Total Precio s/factura | D14: =+D75 -> 108.5535 | E14: =+E75 -> 128.68206 | G14: =SUM(I14:IV14) -> 1460.5356 | H14: $us. | I14: =+I75 -> 129.86611 | J14: =+J75 -> 202.70009 | K14: =+K75 -> 104.30228 | L14: =+L75 -> 200.77781 | M14: =+M75 -> 175.78289 | N14: =+N75 -> 155.30755 | O14: =+O75 -> 51.317503 | P14: =+P75 -> 193.07727 | Q14: =+Q75 -> 247.40407
A15: Precio sin factura en $us / Mt² | D15: =+D14/D12 -> 108.5535 | E15: =+E14/E12 -> 128.68206 | G15: =+G14/G12 -> 71.996686 | H15: $us./Mt² | I15: =+I14/I12 -> 87.376904 | J15: =+J14/J12 -> 67.566697 | K15: =+K14/K12 -> 84.798603 | L15: =+L14/L12 -> 67.830342 | M15: =+M14/M12 -> 69.342363 | N15: =+N14/N12 -> 71.674342 | O15: =+O14/O12 -> 144.14017 | P15: =+P14/P12 -> 65.672541 | Q15: =+Q14/Q12 -> 68.495036
A16: Total Kgr.
A17: % descuento del con al sin | D17: =+(D11-D14)/D11 -> 0.071513799 | E17: =+(E11-E14)/E11 -> 0.073023114 | G17: =ROUNDDOWN(+(G11-G14)/G11,2) -> 0.07 | I17: =+(I11-I14)/I11 -> 0.063355972 | J17: =+(J11-J14)/J11 -> 0.072406702 | K17: =+(K11-K14)/K11 -> 0.067925353 | L17: =+(L11-L14)/L11 -> 0.0722527 | M17: =+(M11-M14)/M11 -> 0.072203036 | N17: =+(N11-N14)/N11 -> 0.071589822 | O17: =+(O11-O14)/O11 -> 0.063316095 | P17: =+(P11-P14)/P11 -> 0.074781148 | Q17: =+(Q11-Q14)/Q11 -> 0.076636492
G18: =+G11+'Pano Fijo'!F12+('Costo M.P.yMat.'!I15*4) -> 1688.52
A19: DETALLE DE MATERIALES A UTILIZAR
A20: MATERIAL | C20: Unidad | D20: =+D2 -> PC2H | E20: =+E2 -> PC4H | G20: Cantidad | H20: Unidad | I20: =+I2 -> VC2H | J20: =+J2 -> VC2H | K20: =+K2 -> VC2H | L20: =+L2 -> VC2H | M20: =+M2 -> VC2H | N20: =+N2 -> VC2H | O20: =+O2 -> VC2H | P20: =+P2 -> VC2H | Q20: =+Q2 -> PC2H
A21: Vidrio Templado 10mm Incoloro | C21: Mt² | D21: =IF(D$9=1,IF(D$10=10,((D$6*0.05)+(D$5*D$6))*D$7,0),0) -> 1.05 | E21: =IF(E$9=1,IF(E$10=10,((E$6*0.05)+(E$5*E$6))*E$7,0),0) -> 0 | G21: =ROUNDUP(SUM(I21:IV21),1) -> 21 | H21: Mt² | I21: =IF(I$9=1,IF(I$10=10,((I$6*0.05)+(I$5*I$6))*I$7,0),0) -> 1.523525 | J21: =IF(J$9=1,IF(J$10=10,((J$6*0.05)+(J$5*J$6))*J$7,0),0) -> 3.075 | K21: =IF(K$9=1,IF(K$10=10,((K$6*0.05)+(K$5*K$6))*K$7,0),0) -> 1.28125 | L21: =IF(L$9=1,IF(L$10=10,((L$6*0.05)+(L$5*L$6))*L$7,0),0) -> 3.034 | M21: =IF(M$9=1,IF(M$10=10,((M$6*0.05)+(M$5*M$6))*M$7,0),0) -> 2.61 | N21: =IF(N$9=1,IF(N$10=10,((N$6*0.05)+(N$5*N$6))*N$7,0),0) -> 2.2386 | O21: =IF(O$9=1,IF(O$10=10,((O$6*0.05)+(O$5*O$6))*O$7,0),0) -> 0.381275 | P21: =IF(P$9=1,IF(P$10=10,((P$6*0.05)+(P$5*P$6))*P$7,0),0) -> 3.04 | Q21: =IF(Q$9=1,IF(Q$10=10,((Q$6*0.05)+(Q$5*Q$6))*Q$7,0),0) -> 3.717
A22: Vidrio Templado 10mm Color | C22: Mt² | D22: =IF(D$9=2,IF(D$10=10,((D$6*0.05)+(D$5*D$6))*D$7,0),0) -> 0 | E22: =IF(E$9=2,IF(E$10=10,((E$6*0.05)+(E$5*E$6))*E$7,0),0) -> 0 | G22: =ROUNDUP(SUM(I22:IV22),1) -> 0 | H22: Mt² | I22: =IF(I$9=2,IF(I$10=10,((I$6*0.05)+(I$5*I$6))*I$7,0),0) -> 0 | J22: =IF(J$9=2,IF(J$10=10,((J$6*0.05)+(J$5*J$6))*J$7,0),0) -> 0 | K22: =IF(K$9=2,IF(K$10=10,((K$6*0.05)+(K$5*K$6))*K$7,0),0) -> 0 | L22: =IF(L$9=2,IF(L$10=10,((L$6*0.05)+(L$5*L$6))*L$7,0),0) -> 0 | M22: =IF(M$9=2,IF(M$10=10,((M$6*0.05)+(M$5*M$6))*M$7,0),0) -> 0 | N22: =IF(N$9=2,IF(N$10=10,((N$6*0.05)+(N$5*N$6))*N$7,0),0) -> 0 | O22: =IF(O$9=2,IF(O$10=10,((O$6*0.05)+(O$5*O$6))*O$7,0),0) -> 0 | P22: =IF(P$9=2,IF(P$10=10,((P$6*0.05)+(P$5*P$6))*P$7,0),0) -> 0 | Q22: =IF(Q$9=2,IF(Q$10=10,((Q$6*0.05)+(Q$5*Q$6))*Q$7,0),0) -> 0
A23: Vidrio Templado 8mm Incoloro | C23: Mt² | D23: =IF(D$9=1,IF(D$10=8,((D$6*0.05)+(D$5*D$6))*D$7,0),0) -> 0 | E23: =IF(E$9=1,IF(E$10=8,((E$6*0.05)+(E$5*E$6))*E$7,0),0) -> 1.05 | G23: =ROUNDUP(SUM(I23:IV23),1) -> 0 | H23: Mt² | I23: =IF(I$9=1,IF(I$10=8,((I$6*0.05)+(I$5*I$6))*I$7,0),0) -> 0 | J23: =IF(J$9=1,IF(J$10=8,((J$6*0.05)+(J$5*J$6))*J$7,0),0) -> 0 | K23: =IF(K$9=1,IF(K$10=8,((K$6*0.05)+(K$5*K$6))*K$7,0),0) -> 0 | L23: =IF(L$9=1,IF(L$10=8,((L$6*0.05)+(L$5*L$6))*L$7,0),0) -> 0 | M23: =IF(M$9=1,IF(M$10=8,((M$6*0.05)+(M$5*M$6))*M$7,0),0) -> 0 | N23: =IF(N$9=1,IF(N$10=8,((N$6*0.05)+(N$5*N$6))*N$7,0),0) -> 0 | O23: =IF(O$9=1,IF(O$10=8,((O$6*0.05)+(O$5*O$6))*O$7,0),0) -> 0 | P23: =IF(P$9=1,IF(P$10=8,((P$6*0.05)+(P$5*P$6))*P$7,0),0) -> 0 | Q23: =IF(Q$9=1,IF(Q$10=8,((Q$6*0.05)+(Q$5*Q$6))*Q$7,0),0) -> 0
A24: Vidrio Templado 8mm Color | C24: Mt² | D24: =IF(D$9=2,IF(D$10=8,((D$6*0.05)+(D$5*D$6))*D$7,0),0) -> 0 | E24: =IF(E$9=2,IF(E$10=8,((E$6*0.05)+(E$5*E$6))*E$7,0),0) -> 0 | G24: =ROUNDUP(SUM(I24:IV24),1) -> 0 | H24: Mt² | I24: =IF(I$9=2,IF(I$10=8,((I$6*0.05)+(I$5*I$6))*I$7,0),0) -> 0 | J24: =IF(J$9=2,IF(J$10=8,((J$6*0.05)+(J$5*J$6))*J$7,0),0) -> 0 | K24: =IF(K$9=2,IF(K$10=8,((K$6*0.05)+(K$5*K$6))*K$7,0),0) -> 0 | L24: =IF(L$9=2,IF(L$10=8,((L$6*0.05)+(L$5*L$6))*L$7,0),0) -> 0 | M24: =IF(M$9=2,IF(M$10=8,((M$6*0.05)+(M$5*M$6))*M$7,0),0) -> 0 | N24: =IF(N$9=2,IF(N$10=8,((N$6*0.05)+(N$5*N$6))*N$7,0),0) -> 0 | O24: =IF(O$9=2,IF(O$10=8,((O$6*0.05)+(O$5*O$6))*O$7,0),0) -> 0 | P24: =IF(P$9=2,IF(P$10=8,((P$6*0.05)+(P$5*P$6))*P$7,0),0) -> 0 | Q24: =IF(Q$9=2,IF(Q$10=8,((Q$6*0.05)+(Q$5*Q$6))*Q$7,0),0) -> 0
A25: Mano de obra | C25: Mt² | D25: =+D12 -> 1 | E25: =+E12 -> 1 | G25: =ROUNDUP(SUM(I25:IV25),1) -> 20.3 | H25: Mt² | I25: =+I12 -> 1.486275 | J25: =+J12 -> 3 | K25: =+K12 -> 1.23 | L25: =+L12 -> 2.96 | M25: =+M12 -> 2.535 | N25: =+N12 -> 2.16685 | O25: =+O12 -> 0.356025 | P25: =+P12 -> 2.94 | Q25: =+Q12 -> 3.612
A26: Silicona transp., blanca o negra | C26: Tubo | D26: =D7*(4*D5+2*D6)/6 -> 1 | E26: =E7*(4*E5+2*E6)/6 -> 1 | G26: =ROUNDUP(SUM(I26:IV26),1) -> 13.7 | H26: Tubo | I26: =I7*(4*I5+2*I6)/6 -> 1.5783333 | J26: =J7*(4*J5+2*J6)/6 -> 1.8333333 | K26: =K7*(4*K5+2*K6)/6 -> 1.1416667 | L26: =L7*(4*L5+2*L6)/6 -> 1.8266667 | M26: =M7*(4*M5+2*M6)/6 -> 1.6266667 | N26: =N7*(4*N5+2*N6)/6 -> 1.485 | O26: =O7*(4*O5+2*O6)/6 -> 0.63833333 | P26: =P7*(4*P5+2*P6)/6 -> 1.6466667 | Q26: =Q7*(4*Q5+2*Q6)/6 -> 1.8466667
A27: Cinta masking 1/2 " (rollo de 20) | C27: Rollo | D27: =+D26*12/20 -> 0.6 | E27: =+E26*12/20 -> 0.6 | G27: =ROUNDUP(SUM(I27:IV27),1) -> 8.2 | H27: Rollo | I27: =+I26*12/20 -> 0.947 | J27: =+J26*12/20 -> 1.1 | K27: =+K26*12/20 -> 0.685 | L27: =+L26*12/20 -> 1.096 | M27: =+M26*12/20 -> 0.976 | N27: =+N26*12/20 -> 0.891 | O27: =+O26*12/20 -> 0.383 | P27: =+P26*12/20 -> 0.988 | Q27: =+Q26*12/20 -> 1.108
A28: "U" 15x25 - Kg/Mt lineal. | B28: 0.2 | C28: Kgr | D28: =2*D$6*$B28*D$7 -> 0.4 | E28: =2*E$6*$B28*E$7 -> 0.4 | G28: =ROUNDUP(SUM(I28:IV28)/(6*B28),1) -> 4.1 | H28: Barras | I28: =2*I$6*$B28*I$7 -> 0.298 | J28: =2*J$6*$B28*J$7 -> 0.6 | K28: =2*K$6*$B28*K$7 -> 0.41 | L28: =2*L$6*$B28*L$7 -> 0.592 | M28: =2*M$6*$B28*M$7 -> 0.6 | N28: =2*N$6*$B28*N$7 -> 0.574 | O28: =2*O$6*$B28*O$7 -> 0.202 | P28: =2*P$6*$B28*P$7 -> 0.8 | Q28: =2*Q$6*$B28*Q$7 -> 0.84
A29: Felpa | C29: Mt lineal | D29: =(D6+3*D5)*D7 -> 4 | E29: =(E6+3*E5)*E7 -> 4 | G29: =ROUNDUP(SUM(I29:IV29),1) -> 55.2 | H29: Mt lineal | I29: =(I6+3*I5)*I7 -> 6.73 | J29: =(J6+3*J5)*J7 -> 7.5 | K29: =(K6+3*K5)*K7 -> 4.625 | L29: =(L6+3*L5)*L7 -> 7.48 | M29: =(M6+3*M5)*M7 -> 6.57 | N29: =(N6+3*N5)*N7 -> 5.965 | O29: =(O6+3*O5)*O7 -> 2.62 | P29: =(P6+3*P5)*P7 -> 6.41 | Q29: =(Q6+3*Q5)*Q7 -> 7.26
A30: Tarugos No. 6 | C30: Pza. | D30: =D$7*(2*D$5+2*D$6)/0.4 -> 10 | E30: =E$7*(2*E$5+2*E$6)/0.4 -> 10 | G30: =ROUNDUP(SUM(I30:IV30),1) -> 132.9 | H30: Pza. | I30: =I$7*(2*I$5+2*I$6)/0.4 -> 13.7 | J30: =J$7*(2*J$5+2*J$6)/0.4 -> 17.5 | K30: =K$7*(2*K$5+2*K$6)/0.4 -> 11.125 | L30: =L$7*(2*L$5+2*L$6)/0.4 -> 17.4 | M30: =M$7*(2*M$5+2*M$6)/0.4 -> 15.95 | N30: =N$7*(2*N$5+2*N$6)/0.4 -> 14.725 | O30: =O$7*(2*O$5+2*O$6)/0.4 -> 6.05 | P30: =P$7*(2*P$5+2*P$6)/0.4 -> 17.35 | Q30: =Q$7*(2*Q$5+2*Q$6)/0.4 -> 19.1
A31: Tornillos 8 x 1 1/2 | C31: Pza. | D31: =D$7*(2*D$5+2*D$6)/0.4 -> 10 | E31: =E$7*(2*E$5+2*E$6)/0.4 -> 10 | G31: =ROUNDUP(SUM(I31:IV31),1) -> 132.9 | H31: Pza. | I31: =I$7*(2*I$5+2*I$6)/0.4 -> 13.7 | J31: =J$7*(2*J$5+2*J$6)/0.4 -> 17.5 | K31: =K$7*(2*K$5+2*K$6)/0.4 -> 11.125 | L31: =L$7*(2*L$5+2*L$6)/0.4 -> 17.4 | M31: =M$7*(2*M$5+2*M$6)/0.4 -> 15.95 | N31: =N$7*(2*N$5+2*N$6)/0.4 -> 14.725 | O31: =O$7*(2*O$5+2*O$6)/0.4 -> 6.05 | P31: =P$7*(2*P$5+2*P$6)/0.4 -> 17.35 | Q31: =Q$7*(2*Q$5+2*Q$6)/0.4 -> 19.1
A32: Vedapres 001 - u - Kg/Mt l. | B32: 0.151 | C32: Kgr | D32: =+D$6*$B32*D$7 -> 0.151 | E32: =2*E$6*$B32*E$7 -> 0.302 | G32: =ROUNDUP(SUM(I32:IV32)/(6*B32),1) -> 2.1 | H32: Barras | I32: =+I$6*$B32*I$7 -> 0.112495 | J32: =+J$6*$B32*J$7 -> 0.2265 | K32: =+K$6*$B32*K$7 -> 0.154775 | L32: =+L$6*$B32*L$7 -> 0.22348 | M32: =+M$6*$B32*M$7 -> 0.2265 | N32: =+N$6*$B32*N$7 -> 0.216685 | O32: =+O$6*$B32*O$7 -> 0.076255 | P32: =+P$6*$B32*P$7 -> 0.302 | Q32: =+Q$6*$B32*Q$7 -> 0.3171
A33: Vedapres 001 - h - Kg/Mt l. | B33: 0.257 | C33: Kgr | E33: =+E$6*$B33*E$7 -> 0.257 | G33: =ROUNDUP(SUM(I33:IV33)/(6*B33),1) -> 0 | H33: Barras
A34: Cabezal 7313 - Kg/Mt l. | B34: 1.013 | C34: Kgr | D34: =D$5*$B34*D$7 -> 1.013 | E34: =E$5*$B34*E$7 -> 1.013 | G34: =ROUNDUP(SUM(I34:IV34)/(6*B34),1) -> 2.4 | H34: Barras | I34: =I$5*$B34*I$7 -> 2.020935 | J34: =J$5*$B34*J$7 -> 2.026 | K34: =K$5*$B34*K$7 -> 1.2156 | L34: =L$5*$B34*L$7 -> 2.026 | M34: =M$5*$B34*M$7 -> 1.71197 | N34: =N$5*$B34*N$7 -> 1.52963 | O34: =O$5*$B34*O$7 -> 0.714165 | P34: =P$5*$B34*P$7 -> 1.48911 | Q34: =Q$5*$B34*Q$7 -> 1.74236
A35: Tapa 7312 - Kg/Mt l. | B35: 0.408 | C35: Kgr | D35: =D$5*$B35*D$7 -> 0.408 | E35: =E$5*$B35*E$7 -> 0.408 | G35: =ROUNDUP(SUM(I35:IV35)/(6*B35),1) -> 2.4 | H35: Barras | I35: =I$5*$B35*I$7 -> 0.81396 | J35: =J$5*$B35*J$7 -> 0.816 | K35: =K$5*$B35*K$7 -> 0.4896 | L35: =L$5*$B35*L$7 -> 0.816 | M35: =M$5*$B35*M$7 -> 0.68952 | N35: =N$5*$B35*N$7 -> 0.61608 | O35: =O$5*$B35*O$7 -> 0.28764 | P35: =P$5*$B35*P$7 -> 0.59976 | Q35: =Q$5*$B35*Q$7 -> 0.70176
A36: Trillo 7314 - Kg/Mt l. | B36: 0.478 | C36: Kgr | D36: =D$5*$B36*D$7 -> 0.478 | E36: =E$5*$B36*E$7 -> 0.478 | G36: =ROUNDUP(SUM(I36:IV36)/(6*B36),1) -> 2.4 | H36: Barras | I36: =I$5*$B36*I$7 -> 0.95361 | J36: =J$5*$B36*J$7 -> 0.956 | K36: =K$5*$B36*K$7 -> 0.5736 | L36: =L$5*$B36*L$7 -> 0.956 | M36: =M$5*$B36*M$7 -> 0.80782 | N36: =N$5*$B36*N$7 -> 0.72178 | O36: =O$5*$B36*O$7 -> 0.33699 | P36: =P$5*$B36*P$7 -> 0.70266 | Q36: =Q$5*$B36*Q$7 -> 0.82216
A37: TapaTrillo Rev. - Kg/Mt l. | B37: 0.125 | C37: Kgr | D37: =D$5*$B37*D$7 -> 0.125 | E37: =E$5*$B37*E$7 -> 0.125 | G37: =ROUNDUP(SUM(I37:IV37)/(6*B37),1) -> 2.4 | H37: Barras | I37: =I$5*$B37*I$7 -> 0.249375 | J37: =J$5*$B37*J$7 -> 0.25 | K37: =K$5*$B37*K$7 -> 0.15 | L37: =L$5*$B37*L$7 -> 0.25 | M37: =M$5*$B37*M$7 -> 0.21125 | N37: =N$5*$B37*N$7 -> 0.18875 | O37: =O$5*$B37*O$7 -> 0.088125 | P37: =P$5*$B37*P$7 -> 0.18375 | Q37: =Q$5*$B37*Q$7 -> 0.215
A38: 1510 | C38: Pza. | D38: =IF(D$8=1,+D$7,0) -> 1 | E38: =IF(E$8=1,+E$7,0) -> 1 | G38: =ROUNDUP(SUM(I38:IV38),1) -> 1 | H38: Pza. | I38: =IF(I$8=1,+I$7,0) -> 0 | J38: =IF(J$8=1,+J$7,0) -> 0 | K38: =IF(K$8=1,+K$7,0) -> 0 | L38: =IF(L$8=1,+L$7,0) -> 0 | M38: =IF(M$8=1,+M$7,0) -> 0 | N38: =IF(N$8=1,+N$7,0) -> 0 | O38: =IF(O$8=1,+O$7,0) -> 0 | P38: =IF(P$8=1,+P$7,0) -> 0 | Q38: =IF(Q$8=1,+Q$7,0) -> 1
A39: 1511 | C39: Pza. | E39: =IF(E$8=1,+E$7,0) -> 1 | G39: =ROUNDUP(SUM(I39:IV39),1) -> 0 | H39: Pza.
A40: 1511a | C40: Pza. | D40: =IF(D$8=1,+D$7,0) -> 1 | G40: =ROUNDUP(SUM(I40:IV40),1) -> 1 | H40: Pza. | I40: =IF(I$8=1,+I$7,0) -> 0 | J40: =IF(J$8=1,+J$7,0) -> 0 | K40: =IF(K$8=1,+K$7,0) -> 0 | L40: =IF(L$8=1,+L$7,0) -> 0 | M40: =IF(M$8=1,+M$7,0) -> 0 | N40: =IF(N$8=1,+N$7,0) -> 0 | O40: =IF(O$8=1,+O$7,0) -> 0 | P40: =IF(P$8=1,+P$7,0) -> 0 | Q40: =IF(Q$8=1,+Q$7,0) -> 1
A41: 1125a | C41: Pza. | D41: =2*D7 -> 2 | E41: =4*E7 -> 4 | G41: =ROUNDUP(SUM(I41:IV41),1) -> 18 | H41: Pza. | I41: =2*I7 -> 2 | J41: =2*J7 -> 2 | K41: =2*K7 -> 2 | L41: =2*L7 -> 2 | M41: =2*M7 -> 2 | N41: =2*N7 -> 2 | O41: =2*O7 -> 2 | P41: =2*P7 -> 2 | Q41: =2*Q7 -> 2
...

Sheet P.Batiente
A2: PUERTAS DE VIDRIO TEMPLADO | D2: PB1H | E2: PB2H | F2: PB4H | H2: Total | J2: PB1H
A3: 8 o 10 mm. c/PERFIL U 15x15 DE ALUMINIO | D3: 10mm. | E3: 10mm. | F3: 10mm. | J3: 10mm.
A4: DATOS BASE PARA EL ANALISIS | D4: =IF(D8=1,"INCOLORO","COLOR") -> INCOLORO | E4: =IF(E8=1,"INCOLORO","COLOR") -> INCOLORO | F4: =IF(F8=1,"INCOLORO","COLOR") -> INCOLORO | J4: =IF(J8=1,"INCOLORO","COLOR") -> COLOR
A5: BASE ( Metros ) | D5: 1 | E5: 1 | F5: 1.2 | J5: 1.01
A6: ALTURA ( Metros ) | D6: 1 | E6: 1 | F6: 2 | J6: 2.1
A7: CANTIDAD DE PIEZAS | D7: 1 | E7: 1 | F7: 1 | H7: =SUM(J7:IV7) -> 1 | I7: Puertas | J7: 1
A8: INCOLORO = 1 ; COLOR =2 | D8: 1 | E8: 1 | F8: 1 | J8: 2
A9: C/FRENO = 1 ; S/FRENO =2 | D9: 1 | E9: 1 | F9: 2 | J9: 1
A10: Total Precio c/factura | D10: =+D44 -> 194.61 | E10: =+E44 -> 341.41674 | F10: =+F44 -> 257.60788 | H10: =SUM(J10:IV10) -> 282.85329 | I10: $us. | J10: =+J44 -> 282.85329
A11: Superficie Mt² | D11: =+D5*D6*D$7 -> 1 | E11: =+E5*E6*E$7 -> 1 | F11: =+F5*F6*F$7 -> 2.4 | H11: =SUM(J11:IV11) -> 2.121 | I11: Mt² | J11: =+J5*J6*J$7 -> 2.121
A12: Precio con factura en $us / Mt² | D12: =+D10/D11 -> 194.61 | E12: =+E10/E11 -> 341.41674 | F12: =+F10/F11 -> 107.33662 | H12: =+H10/H11 -> 133.35846 | I12: $us./Mt² | J12: =+J10/J11 -> 133.35846
A13: Total Precio s/factura | D13: =+D69 -> 181.77 | E13: =+E69 -> 320.24226 | F13: =+F69 -> 235.19492 | H13: =SUM(J13:IV13) -> 263.7574 | I13: $us. | J13: =+J69 -> 263.7574
A14: Precio sin factura en $us / Mt² | D14: =+D13/D11 -> 181.77 | E14: =+E13/E11 -> 320.24226 | F14: =+F13/F11 -> 97.997883 | H14: =+H13/H11 -> 124.35521 | I14: $us./Mt² | J14: =+J13/J11 -> 124.35521
A15: Total Kgr.
A16: % descuento del con al sin | D16: =+(D10-D13)/D10 -> 0.06597811 | E16: =+(E10-E13)/E10 -> 0.062019455 | F16: =+(F10-F13)/F10 -> 0.087004171 | H16: =+(H10-H13)/H10 -> 0.067511642 | J16: =+(J10-J13)/J10 -> 0.067511642
A18: DETALLE DE MATERIALES A UTILIZAR
A19: MATERIAL | C19: Unidad | D19: PB1H | E19: PB2H | F19: PB4H | H19: Cantidad | I19: Unidad | J19: PB1H
A20: Vidrio Templado 10mm Incoloro | C20: Mt² | D20: =IF(D8=1,D$5*D$6*D$7,0) -> 1 | E20: =IF(E8=1,E$5*E$6*E$7,0) -> 1 | F20: =IF(F8=1,F$5*F$6*F$7,0) -> 2.4 | H20: =ROUNDUP(SUM(J20:IV20),1) -> 0 | I20: Mt² | J20: =IF(J8=1,J$5*J$6*J$7,0) -> 0
A21: Vidrio Templado 10mm Color | C21: Mt² | D21: =IF(D8=2,D$5*D$6*D$7,0) -> 0 | E21: =IF(E8=2,E$5*E$6*E$7,0) -> 0 | F21: =IF(F8=2,F$5*F$6*F$7,0) -> 0 | H21: =ROUNDUP(SUM(J21:IV21),1) -> 2.2 | I21: Mt² | J21: =IF(J8=2,J$5*J$6*J$7,0) -> 2.121
A22: Mano de obra | C22: Mt² | D22: =+D11 -> 1 | E22: =+E11 -> 1 | F22: =+F11 -> 2.4 | H22: =ROUNDUP(SUM(J22:IV22),1) -> 2.2 | I22: Mt² | J22: =+J11 -> 2.121
A23: Silicona transp., blanca o negra | C23: Tubo | F23: =((2*F$6+F$5)/6)*F$7 -> 0.86666667 | H23: =ROUNDUP(SUM(J23:IV23),1) -> 0 | I23: Tubo
A24: Cinta masking 1/2 " (rollo de 20) | C24: Rollo | F24: =2*(2*F$6+F$5)*F$7/20 -> 0.52 | H24: =ROUNDUP(SUM(J24:IV24),1) -> 0 | I24: Rollo
A25: "U" 15x25 - Kg/Mt lineal. | B25: 0.2 | C25: Kgr | F25: =(2*F$6+F$5)*$B25*F$7 -> 1.04 | H25: =ROUNDUP(SUM(J25:IV25)/(B25*6),1) -> 0 | I25: Barras
A26: Felpa | C26: Mt lineal | E26: =+E$6*E$7 -> 1 | F26: =+F$6*F$7 -> 2 | H26: =ROUNDUP(SUM(J26:IV26),1) -> 0 | I26: Mt lineal
A27: Tarugos No. 6 | C27: Pza. | F27: =F$7*((2*F$6+F$5)/0.4) -> 13 | H27: =ROUNDUP(SUM(J27:IV27),1) -> 0 | I27: Pza.
A28: Tornillos 8 x 1 1/2 | C28: Pza. | F28: =F$7*((2*F$6+F$5)/0.4) -> 13 | H28: =ROUNDUP(SUM(J28:IV28),1) -> 0 | I28: Pza.
A29: Vedapres 001 - h - Kg/Mt l. | B29: 0.257 | C29: Kgr | E29: =(E$6)*$B29*E$7 -> 0.257 | F29: =(F$6)*$B29*F$7 -> 0.514 | H29: =ROUNDUP(SUM(J29:IV29),1) -> 0 | I29: Barra
A30: Freno Hidráulico HyH | C30: Pza. | D30: =IF(D$9=1,D$7,0) -> 1 | E30: =IF(E$9=1,2*E$7,0) -> 2 | F30: =IF(F$9=1,2*F$7,0) -> 0 | H30: =ROUNDUP(SUM(J30:IV30),1) -> 1 | I30: Pza. | J30: =IF(J$9=1,J$7,0) -> 1
A31: Manijones de vidrio | C31: Pza. | D31: =2*D$7 -> 2 | E31: =4*E$7 -> 4 | F31: =4*F$7 -> 4 | H31: =ROUNDUP(SUM(J31:IV31),1) -> 2 | I31: Pza. | J31: =2*J$7 -> 2
A32: 1335 | C32: Pza. | E32: =E$7*2 -> 2 | F32: =F$7*2 -> 2 | H32: =ROUNDUP(SUM(J32:IV32),1) -> 0 | I32: Pza.
A33: 1103 | C33: Pza. | D33: =D$7 -> 1 | E33: =E$7*2 -> 2 | F33: =F$7*2 -> 2 | H33: =ROUNDUP(SUM(J33:IV33),1) -> 1 | I33: Pza. | J33: =J$7 -> 1
A34: 1101 | C34: Pza. | D34: =D$7 -> 1 | E34: =E$7*2 -> 2 | F34: =F$7*2 -> 2 | H34: =ROUNDUP(SUM(J34:IV34),1) -> 1 | I34: Pza. | J34: =J$7 -> 1
A35: 1636 | C35: Pza. | D35: =D$7*2 -> 2 | E35: =E$7*4 -> 4 | F35: =F$7*4 -> 4 | H35: =ROUNDUP(SUM(J35:IV35),1) -> 2 | I35: Pza. | J35: =J$7*2 -> 2
A36: 1520 | C36: Pza. | D36: =D$7 -> 1 | E36: =E$7 -> 1 | F36: =F$7 -> 1 | H36: =ROUNDUP(SUM(J36:IV36),1) -> 1 | I36: Pza. | J36: =J$7 -> 1
A37: 1531 | C37: Pza. | E37: =E$7 -> 1 | F37: =F$7 -> 1 | H37: =ROUNDUP(SUM(J37:IV37),1) -> 0 | I37: Pza.
A38: 1038 | C38: Pza. | E38: =E$7*4 -> 4 | F38: =F$7*4 -> 4 | H38: =ROUNDUP(SUM(J38:IV38),1) -> 0 | I38: Pza.
A39: 1013 | C39: Pza. | D39: =D$7 -> 1 | E39: =E$7*2 -> 2 | F39: =F$7*2 -> 2 | H39: =ROUNDUP(SUM(J39:IV39),1) -> 1 | I39: Pza. | J39: =J$7 -> 1
A40: 1201 | C40: Pza. | D40: =+D$7 -> 1 | E40: =E$7*4 -> 4 | F40: =F$7*4 -> 4 | H40: =ROUNDUP(SUM(J40:IV40),1) -> 1 | I40: Pza. | J40: =+J$7 -> 1
A41: 1504a | C41: Pza. | D41: =D$7 -> 1 | H41: =ROUNDUP(SUM(J41:IV41),1) -> 1 | I41: Pza. | J41: =J$7 -> 1
A44: COSTO CON FACTURA | D44: =SUM(D45:D66) -> 194.61 | E44: =SUM(E45:E66) -> 341.41674 | F44: =SUM(F45:F66) -> 257.60788 | J44: =SUM(J45:J66) -> 282.85329
...

Sheet Pano Fijo
D1: =ROUND(D5/0.9,0) -> 1 | H1: =ROUND(H5/0.9,0) -> 1 | I1: =ROUND(I5/0.9,0) -> 2
A2: PANO FIJO | D2: PF | F2: Total | H2: PF | I2: PF
A3: 8 o 10 mm. c/PERFIL U 15x15 DE ALUMINIO | D3: =IF(D10=8,"8 mm.","10 mm.") -> 10 mm. | H3: =IF(H10=8,"8 mm.","10 mm.") -> 10 mm. | I3: =IF(I10=8,"8 mm.","10 mm.") -> 10 mm.
A4: DATOS BASE PARA EL ANALISIS | D4: =IF(D9=1,"INCOLORO","COLOR") -> INCOLORO | H4: =IF(H9=1,"INCOLORO","COLOR") -> INCOLORO | I4: =IF(I9=1,"INCOLORO","COLOR") -> INCOLORO
A5: BASE ( Metros ) | D5: 1 | H5: 1.01 | I5: 1.72
A6: ALTURA ( Metros ) | D6: 1 | H6: 0.555 | I6: 0.545
A7: CANTIDAD DE PIEZAS | D7: 1 | F7: =SUM(H7:IV7) -> 2 | G7: Pzas. | H7: 1 | I7: 1
A8: CANTIDAD DE VANOS | D8: 1 | H8: 1 | I8: 1
A9: INCOLORO = 1 ; COLOR =2 | D9: 1 | H9: 1 | I9: 1
A10: ESPESOR DEL VIDRIO = 8 ó 10 mm. | D10: 10 | H10: 10 | I10: 10
A11: ESMERILADO = E
A12: Total Precio c/factura | C12: pn | D12: =+D49 -> 62.499 | F12: =SUM(H12:IV12) -> 97.956233 | G12: $us. | H12: =+H49 -> 37.717282 | I12: =+I49 -> 60.238951
A13: Superficie Mt² | D13: =+D5*D6*D$7 -> 1 | F13: =SUM(H13:IV13) -> 1.49795 | G13: Mt² | H13: =+H5*H6*H$7 -> 0.56055 | I13: =+I5*I6*I$7 -> 0.9374
A14: Precio con factura en $us / Mt² | D14: =+D12/D13 -> 62.499 | F14: =+F12/F13 -> 65.393526 | G14: $us./Mt² | H14: =+H12/H13 -> 67.286205 | I14: =+I12/I13 -> 64.261736
A15: Total Precio s/factura | D15: =+D76 -> 57.642 | F15: =SUM(H15:IV15) -> 90.68948 | G15: $us. | H15: =+H76 -> 34.96369 | I15: =+I76 -> 55.72579
A16: Precio sin factura en $us / Mt² | D16: =+D15/D13 -> 57.642 | F16: =+F15/F13 -> 60.542395 | G16: $us./Mt² | H16: =+H15/H13 -> 62.373901 | I16: =+I15/I13 -> 59.447184
A17: Total Kgr.
A18: % descuento del con al sin | D18: =+(D12-D15)/D12 -> 0.077713243 | F18: =+(F12-F15)/F12 -> 0.074183671 | H18: =+(H12-H15)/H12 -> 0.073006109 | I18: =+(I12-I15)/I12 -> 0.074920976
A20: DETALLE DE MATERIALES A UTILIZAR
A21: MATERIAL | C21: Unidad | D21: =+D2 -> PF | F21: Cantidad | G21: Unidad | H21: =+H2 -> PF | I21: =+I2 -> PF
A22: Vidrio Templado 10mm Incoloro | C22: Mt² | D22: =IF(D$9=1,IF(D$10=10,((D$6*0.05)+(D$5*D$6))*D$7,0),0) -> 1.05 | F22: =ROUNDUP(SUM(H22:IV22),1) -> 1.6 | G22: Mt² | H22: =IF(H$9=1,IF(H$10=10,((H$6*0.05)+(H$5*H$6))*H$7,0),0) -> 0.5883 | I22: =IF(I$9=1,IF(I$10=10,((I$6*0.05)+(I$5*I$6))*I$7,0),0) -> 0.96465
A23: Vidrio Templado 10mm Color | C23: Mt² | D23: =IF(D$9=2,IF(D$10=10,((D$6*0.05)+(D$5*D$6))*D$7,0),0) -> 0 | F23: =ROUNDUP(SUM(H23:IV23),1) -> 0 | G23: Mt² | H23: =IF(H$9=2,IF(H$10=10,((H$6*0.05)+(H$5*H$6))*H$7,0),0) -> 0 | I23: =IF(I$9=2,IF(I$10=10,((I$6*0.05)+(I$5*I$6))*I$7,0),0) -> 0
A24: Vidrio Templado 8mm Incoloro | C24: Mt² | D24: =IF(D$9=1,IF(D$10=8,((D$6*0.05)+(D$5*D$6))*D$7,0),0) -> 0 | F24: =ROUNDUP(SUM(H24:IV24),1) -> 0 | G24: Mt² | H24: =IF(H$9=1,IF(H$10=8,((H$6*0.05)+(H$5*H$6))*H$7,0),0) -> 0 | I24: =IF(I$9=1,IF(I$10=8,((I$6*0.05)+(I$5*I$6))*I$7,0),0) -> 0
A25: Vidrio Templado 8mm Color | C25: Mt² | D25: =IF(D$9=2,IF(D$10=8,((D$5*D$6))*D$7,0),0) -> 0 | F25: =ROUNDUP(SUM(H25:IV25),1) -> 0 | G25: Mt² | H25: =IF(H$9=2,IF(H$10=8,((H$5*H$6))*H$7,0),0) -> 0 | I25: =IF(I$9=2,IF(I$10=8,((I$5*I$6))*I$7,0),0) -> 0
A26: Mano de obra | C26: Mt² | D26: =+D13 -> 1 | F26: =ROUNDUP(SUM(H26:IV26),1) -> 1.5 | G26: Mt² | H26: =+H13 -> 0.56055 | I26: =+I13 -> 0.9374
A27: Silicona transp., blanca o negra | C27: Tubo | D27: =D7*(4*D5+4*D6+(D8-1)*D6)/6 -> 1.3333333 | F27: =ROUNDUP(SUM(H27:IV27),1) -> 2.6 | G27: Tubo | H27: =H7*(4*H5+4*H6+(H8-1)*H6)/6 -> 1.0433333 | I27: =I7*(4*I5+4*I6+(I8-1)*I6)/6 -> 1.51
A28: Cinta masking 1/2 " (rollo de 20) | C28: Rollo | D28: =+D27*12/20 -> 0.8 | F28: =ROUNDUP(SUM(H28:IV28),1) -> 1.6 | G28: Rollo | H28: =+H27*12/20 -> 0.626 | I28: =+I27*12/20 -> 0.906
A29: "U" 15x25 - Kg/Mt lineal. | B29: 0.2 | C29: Kgr | D29: =(2*D$6+2*D5)*$B29*D$7 -> 0.8 | F29: =ROUNDUP(SUM(H29:IV29)/(6*B29),1) -> 1.3 | G29: Barras | H29: =(2*H$6+2*H5)*$B29*H$7 -> 0.626 | I29: =(2*I$6+2*I5)*$B29*I$7 -> 0.906
A30: Esmerilado | C30: Mt² | D30: =IF((D11="e"),D13,IF( (D11="E"),D13,0)) -> 0 | F30: =ROUNDUP(SUM(H30:IV30),1) -> 0 | G30: Mt lineal | H30: =IF((H11="e"),H13,IF( (H11="E"),H13,0)) -> 0 | I30: =IF((I11="e"),I13,IF( (I11="E"),I13,0)) -> 0
A31: Tarugos No. 6 | C31: Pza. | D31: =D$7*(2*D$5+2*D$6)/0.4 -> 10 | F31: =ROUNDUP(SUM(H31:IV31),1) -> 19.2 | G31: Pza. | H31: =H$7*(2*H$5+2*H$6)/0.4 -> 7.825 | I31: =I$7*(2*I$5+2*I$6)/0.4 -> 11.325
A32: Tornillos 8 x 1 1/2 | C32: Pza. | D32: =D$7*(2*D$5+2*D$6)/0.4 -> 10 | F32: =ROUNDUP(SUM(H32:IV32),1) -> 19.2 | G32: Pza. | H32: =H$7*(2*H$5+2*H$6)/0.4 -> 7.825 | I32: =I$7*(2*I$5+2*I$6)/0.4 -> 11.325
A33: Vedapres 001 - u (2,10mt/barra) | C33: Barra | F33: =ROUNDUP(SUM(H33:IV33),1) -> 0 | G33: Barra
A34: Vedapres 001 - h (2,10mt/barra) | C34: Barra | F34: =ROUNDUP(SUM(H34:IV34),1) -> 0 | G34: Barra
A35: Cabezal 7313 - Kg/Mt l. | B35: 1.013 | C35: Kgr | F35: =ROUNDUP(SUM(H35:IV35)/(6*B35),1) -> 0 | G35: Barras
A36: Tapa 7312 - Kg/Mt l. | B36: 0.408 | C36: Kgr | F36: =ROUNDUP(SUM(H36:IV36)/(6*B36),1) -> 0 | G36: Barras
A37: Trillo 7314 - Kg/Mt l. | B37: 0.478 | C37: Kgr | F37: =ROUNDUP(SUM(H37:IV37)/(6*B37),1) -> 0 | G37: Barras
A38: TapaTrillo Rev. - Kg/Mt l. | B38: 0.125 | C38: Kgr | F38: =ROUNDUP(SUM(H38:IV38)/(6*B38),1) -> 0 | G38: Barras
A39: 1510 | C39: Pza. | F39: =ROUNDUP(SUM(H39:IV39),1) -> 0 | G39: Pza.
A40: 1511 | C40: Pza. | F40: =ROUNDUP(SUM(H40:IV40),1) -> 0 | G40: Pza.
A41: 1511a | C41: Pza. | F41: =ROUNDUP(SUM(H41:IV41),1) -> 0 | G41: Pza.
...

Sheet Hoja3
