Workbook

Sheet 1erT
A2: UNIDAD EDUCATIVA: COLEGIO DESPERTAD | M2: INICIO DE BIMESTRE : | T2: 45323 | AD2: No. TOTAL DE APROBADOS | AL2: =COUNTIF(BF15:BF56,">51") -> 11 | BC2: DIAS RESTANTES PARA FIN DE TRIMESTRE
A3: EDUCACION SECUNDARIA COMUNITARIA PRODUCTIVA | M3: FIN DE BIMESTRE : | T3: 45418 | AD3: No. TOTAL DE REPROBADOS | AL3: =COUNTIF(BF15:BF56,"<=51") -> 2 | BC3: =+T3-S8 -> 33
A4: CURSO: 2ndo A Secundaria | R4: =T3-T2 -> 95 | Z4: Días
A5: DIRECTORA : EUGENIA CONDORI MOYA
A6: MAESTRO : MARCELO A. RODRIGUEZ GRACIA
A7: CAMPO : COMUNIDAD Y SOCIEDAD
A8: MATERIA : HISTORIA | M8: FECHA ACTUAL : | S8: =TODAY() -> 45385
E9: EVALUACION DEL MAESTRO DIMENSIONES | BC9: AUTO EVALUACION DIMENSIONES (5) | BF9: TOTAL BIMESTRAL | BG9: SITUACION BIMESTRAL
A10: Nº | B10: Nombre completo | C10: ACUMULADA | D10: BIMESTRE | E10: SER (5) | M10: SABER (45) | AD10: HACER (40) | AU10: DECIDIR (5) | BC10: SER (2.5) | BD10: DECIDIR (2.5) | BE10: TOTAL
E11: EXPRESA ACTITUDES DE RESPETO EN PALABRAS Y ACCIONES HACIA EL Y CON LOS DEMAS | F11: ES RESPONSIBLE Y PUNTUAL AL LLEGAR A CLASE Y AL ENTREGAR TRABAJOS | G11: DEMUESTRA SOLIDARIDAD EN SUS ACTIVIDADES Y RELACIONES INTERPERSONALES | H11: FORTALEZCO MI IDENTIDAD PERSONAL SIN RECURRIR A COPIAS DE IDENTIDADES | I11: PRACTICO EL EQUILIBRIO EMOCIONAL QUE ES EL REFLEJO DE LO QUE VEO EN MI HOGAR | J11: OTROS VALORES | K11: 50%S - 50%H | L11: TOTAL | M11: Test Troy Movie | N11: Test Ancient Greece | AB11: EVALUACION PROMEDIO MAESTRO - 5 | AC11: TOTAL | AD11: 1 Early people of the Aegean | AE11: 2 The Rise of Greek City States | AF11: 3 Victory and Defeat in the Greek World | AG11: 4 The Glory That Was Greece | AH11: 5 Alexander and the Hellenistic Age | AS11: EVALUACION PROMEDIO MAESTRO - 5 | AT11: TOTAL | AU11: DEMUESTRO INICIATIVA DURANTE LAS ACTIVIDADES DEL AULA | AV11: RESPETO LAS NORMAS DE CONVIVENCIA ENTRE LOS COMPA;EROS | AW11: ME HAGO CARGO DE LAS PERTENENCIAS QUE TRAIGO AL COLEGIO | AX11: HAGO USO APROPIADO DEL LENGUAJE SIN USAR INSULTOS O APODOS OFENSIVOS | AY11: SOY PERSEVERANTE Y RESPONSABLEAL ASUMIR UN TRABAJO GRUPAL | AZ11: OTROS VALORES | BA11: 50%S - 50%H | BB11: TOTAL | BC11: HAGO USO APROPIADO DEL LENGUAJE SIN USAR INSULTOS O APODOS OFENSIVOS | BD11: SOY PERSEVERANTE Y RESPONSABLEAL ASUMIR UN TRABAJO GRUPAL
B12: FECHA ENCARGADA | L12: =IFERROR(AVERAGE(L15:L56),"") -> 3.5836939 | M12: 45331 | N12: 45365 | AC12: =IFERROR(AVERAGE(AC15:AC56),"") -> 31.776923 | AD12: 45331 | AE12: 45345 | AF12: 45352 | AG12: 45363 | AH12: 45366 | AT12: =IFERROR(AVERAGE(AT15:AT56),"") -> 28.915385 | BB12: =IFERROR(AVERAGE(BB15:BB56),"") -> 3.5836939 | BE12: =IFERROR(AVERAGE(BE15:BE56),"") | BF12: =IF(SUM(BB12,AT12,AC12,L12)=0,"",SUM(BB12,AT12,AC12,L12)) -> 67.859696 | BG12: /
B13: FECHA DE ENTREGA | M13: 45342 | N13: 45372 | AD13: 45338 | AE13: 45349 | AF13: 45356 | AG13: 45365 | AH13: 45370
B14: TIEMPO ( DIAS ) | E14: =+E13-E12 -> 0 | F14: =+F13-F12 -> 0 | G14: =+G13-G12 -> 0 | H14: =+H13-H12 -> 0 | I14: =+I13-I12 -> 0 | J14: =+J13-J12 -> 0 | K14: =+K13-K12 -> 0 | M14: =+M13-M12 -> 11 | N14: =+N13-N12 -> 7 | O14: =+O13-O12 -> 0 | P14: =+P13-P12 -> 0 | Q14: =+Q13-Q12 -> 0 | R14: =+R13-R12 -> 0 | S14: =+S13-S12 -> 0 | T14: =+T13-T12 -> 0 | ... AA14: =+AA13-AA12 -> 0 | AD14: =+AD13-AD12 -> 7 | AE14: =+AE13-AE12 -> 4 | AF14: =+AF13-AF12 -> 4 | AG14: =+AG13-AG12 -> 2 | AH14: =+AH13-AH12 -> 4 | AI14: =+AI13-AI12 -> 0 | AJ14: =+AJ13-AJ12 -> 0 | AK14: =+AK13-AK12 -> 0 | ... AR14: =+AR13-AR12 -> 0 | AU14: =+AU13-AU12 -> 0 | AV14: =+AV13-AV12 -> 0 | AW14: =+AW13-AW12 -> 0 | AX14: =+AX13-AX12 -> 0 | AY14: =+AY13-AY12 -> 0 | AZ14: =+AZ13-AZ12 -> 0 | BA14: =+BA13-BA12 -> 0 | BC14: =+BC13-BC12 -> 0 | BD14: =+BD13-BD12 -> 0
A15: 1 | B15: AGUILA SEJAS MATIAS HERNAN | C15: =IF(B15<>"",IFERROR(EVAL.ANUAL!X9,""),"") -> 26 | D15: =IF(B15<>"",IFERROR(EVAL.ANUAL!I9,""),"") -> 77 | K15: =IFERROR((AVERAGE(M15:AB15,AD15:AS15)),"") -> 85.666667 | L15: =IFERROR((AVERAGE(E15:K15)*0.05),"") -> 4.2833333 | M15: 100 | N15: 30 | AB15: =IFERROR(AVERAGE(M15:AA15),"") -> 65 | AC15: =IFERROR((AVERAGE(M15:AA15)*0.4)+(AB15*0.05),"") -> 29.25 | AD15: 85 | AE15: 100 | AF15: 100 | AG15: 100 | AH15: 95 | AS15: =IFERROR(AVERAGE(AD15:AR15),"") -> 96 | AT15: =IFERROR((AVERAGE(AD15:AR15)*0.35)+(AS15*0.05),"") -> 38.4 | BA15: =IFERROR(AVERAGE(M15:AB15,AD15:AS15),"") -> 85.666667 | BB15: =IFERROR((AVERAGE(AU15:BA15)*0.05),"") -> 4.2833333 | BE15: =IFERROR((AVERAGE(BC15)*0.025)+(BD15*0.025),"") | BF15: =IF(SUM(BB15,AT15,AC15,L15,BE15)=0,"",SUM(BB15,AT15,AC15,L15,BE15)) -> 76.216667 | BG15: =IF(BF15="","",IF(BF15<51,"REPROBADO",IF(BF15>=51,"APROBADO"," "))) -> APROBADO
A16: 2 | B16: ANTEZANA ARANIBAR JAVIER LEANDRO | C16: =IF(B16<>"",IFERROR(EVAL.ANUAL!X10,""),"") -> 30 | D16: =IF(B16<>"",IFERROR(EVAL.ANUAL!I10,""),"") -> 88 | K16: =IFERROR((AVERAGE(M16:AB16,AD16:AS16)),"") -> 94 | L16: =IFERROR((AVERAGE(E16:K16)*0.05),"") -> 4.7 | M16: 100 | N16: 68 | AB16: =IFERROR(AVERAGE(M16:AA16),"") -> 84 | AC16: =IFERROR((AVERAGE(M16:AA16)*0.4)+(AB16*0.05),"") -> 37.8 | AD16: 100 | AE16: 100 | AF16: 100 | AG16: 100 | AS16: =IFERROR(AVERAGE(AD16:AR16),"") -> 100 | AT16: =IFERROR((AVERAGE(AD16:AR16)*0.35)+(AS16*0.05),"") -> 40 | BA16: =IFERROR(AVERAGE(M16:AB16,AD16:AS16),"") -> 94 | BB16: =IFERROR((AVERAGE(AU16:BA16)*0.05),"") -> 4.7 | BE16: =IFERROR((AVERAGE(BC16)*0.025)+(BD16*0.025),"") | BF16: =IF(SUM(BB16,AT16,AC16,L16,BE16)=0,"",SUM(BB16,AT16,AC16,L16,BE16)) -> 87.2 | BG16: =IF(BF16="","",IF(BF16<51,"REPROBADO",IF(BF16>=51,"APROBADO"," "))) -> APROBADO
A17: 3 | B17: ANTEZANA TORREZ MATIAS ANDRE | C17: =IF(B17<>"",IFERROR(EVAL.ANUAL!X11,""),"") -> 29 | D17: =IF(B17<>"",IFERROR(EVAL.ANUAL!I11,""),"") -> 87 | K17: =IFERROR((AVERAGE(M17:AB17,AD17:AS17)),"") -> 92 | L17: =IFERROR((AVERAGE(E17:K17)*0.05),"") -> 4.6 | M17: 100 | N17: 76 | AB17: =IFERROR(AVERAGE(M17:AA17),"") -> 88 | AC17: =IFERROR((AVERAGE(M17:AA17)*0.4)+(AB17*0.05),"") -> 39.6 | AD17: 100 | AE17: 100 | AF17: 70 | AG17: 100 | AH17: 100 | AS17: =IFERROR(AVERAGE(AD17:AR17),"") -> 94 | AT17: =IFERROR((AVERAGE(AD17:AR17)*0.35)+(AS17*0.05),"") -> 37.6 | BA17: =IFERROR(AVERAGE(M17:AB17,AD17:AS17),"") -> 92 | BB17: =IFERROR((AVERAGE(AU17:BA17)*0.05),"") -> 4.6 | BE17: =IFERROR((AVERAGE(BC17)*0.025)+(BD17*0.025),"") | BF17: =IF(SUM(BB17,AT17,AC17,L17,BE17)=0,"",SUM(BB17,AT17,AC17,L17,BE17)) -> 86.4 | BG17: =IF(BF17="","",IF(BF17<51,"REPROBADO",IF(BF17>=51,"APROBADO"," "))) -> APROBADO
A18: 4 | B18: CARDOZO FRANCO JOHNNY LEONARDO | C18: =IF(B18<>"",IFERROR(EVAL.ANUAL!X12,""),"") -> 30 | D18: =IF(B18<>"",IFERROR(EVAL.ANUAL!I12,""),"") -> 89 | K18: =IFERROR((AVERAGE(M18:AB18,AD18:AS18)),"") -> 94.6875 | L18: =IFERROR((AVERAGE(E18:K18)*0.05),"") -> 4.734375 | M18: 100 | N18: 80 | AB18: =IFERROR(AVERAGE(M18:AA18),"") -> 90 | AC18: =IFERROR((AVERAGE(M18:AA18)*0.4)+(AB18*0.05),"") -> 40.5 | AD18: 100 | AE18: 100 | AF18: 90 | AG18: 100 | AS18: =IFERROR(AVERAGE(AD18:AR18),"") -> 97.5 | AT18: =IFERROR((AVERAGE(AD18:AR18)*0.35)+(AS18*0.05),"") -> 39 | BA18: =IFERROR(AVERAGE(M18:AB18,AD18:AS18),"") -> 94.6875 | BB18: =IFERROR((AVERAGE(AU18:BA18)*0.05),"") -> 4.734375 | BE18: =IFERROR((AVERAGE(BC18)*0.025)+(BD18*0.025),"") | BF18: =IF(SUM(BB18,AT18,AC18,L18,BE18)=0,"",SUM(BB18,AT18,AC18,L18,BE18)) -> 88.96875 | BG18: =IF(BF18="","",IF(BF18<51,"REPROBADO",IF(BF18>=51,"APROBADO"," "))) -> APROBADO
A19: 5 | B19: ESPINOZA MUÑOZ RUBEN SEBASTIAN | C19: =IF(B19<>"",IFERROR(EVAL.ANUAL!X13,""),"") -> 10 | D19: =IF(B19<>"",IFERROR(EVAL.ANUAL!I13,""),"") -> 29 | K19: =IFERROR((AVERAGE(M19:AB19,AD19:AS19)),"") -> 28.34375 | L19: =IFERROR((AVERAGE(E19:K19)*0.05),"") -> 1.4171875 | M19: 60 | N19: 12 | AB19: =IFERROR(AVERAGE(M19:AA19),"") -> 36 | AC19: =IFERROR((AVERAGE(M19:AA19)*0.4)+(AB19*0.05),"") -> 16.2 | AD19: 60 | AE19: 0 | AF19: 0 | AG19: 35 | AS19: =IFERROR(AVERAGE(AD19:AR19),"") -> 23.75 | AT19: =IFERROR((AVERAGE(AD19:AR19)*0.35)+(AS19*0.05),"") -> 9.5 | BA19: =IFERROR(AVERAGE(M19:AB19,AD19:AS19),"") -> 28.34375 | BB19: =IFERROR((AVERAGE(AU19:BA19)*0.05),"") -> 1.4171875 | BE19: =IFERROR((AVERAGE(BC19)*0.025)+(BD19*0.025),"") | BF19: =IF(SUM(BB19,AT19,AC19,L19,BE19)=0,"",SUM(BB19,AT19,AC19,L19,BE19)) -> 28.534375 | BG19: =IF(BF19="","",IF(BF19<51,"REPROBADO",IF(BF19>=51,"APROBADO"," "))) -> REPROBADO
A20: 6 | B20: HUANCA AMURRIO VALENTINA RAFAELA | C20: =IF(B20<>"",IFERROR(EVAL.ANUAL!X14,""),"") -> 22 | D20: =IF(B20<>"",IFERROR(EVAL.ANUAL!I14,""),"") -> 64 | K20: =IFERROR((AVERAGE(M20:AB20,AD20:AS20)),"") -> 72.6875 | L20: =IFERROR((AVERAGE(E20:K20)*0.05),"") -> 3.634375 | M20: 40 | N20: 56 | AB20: =IFERROR(AVERAGE(M20:AA20),"") -> 48 | AC20: =IFERROR((AVERAGE(M20:AA20)*0.4)+(AB20*0.05),"") -> 21.6 | AD20: 100 | AE20: 90 | AF20: 100 | AG20: 60 | AS20: =IFERROR(AVERAGE(AD20:AR20),"") -> 87.5 | AT20: =IFERROR((AVERAGE(AD20:AR20)*0.35)+(AS20*0.05),"") -> 35 | BA20: =IFERROR(AVERAGE(M20:AB20,AD20:AS20),"") -> 72.6875 | BB20: =IFERROR((AVERAGE(AU20:BA20)*0.05),"") -> 3.634375 | BE20: =IFERROR((AVERAGE(BC20)*0.025)+(BD20*0.025),"") | BF20: =IF(SUM(BB20,AT20,AC20,L20,BE20)=0,"",SUM(BB20,AT20,AC20,L20,BE20)) -> 63.86875 | BG20: =IF(BF20="","",IF(BF20<51,"REPROBADO",IF(BF20>=51,"APROBADO"," "))) -> APROBADO
A21: 7 | B21: MERCADO ROJAS MARIA BELEN | C21: =IF(B21<>"",IFERROR(EVAL.ANUAL!X15,""),"") -> 52 | D21: =IF(B21<>"",IFERROR(EVAL.ANUAL!I15,""),"") -> 78 | K21: =IFERROR((AVERAGE(M21:AB21,AD21:AS21)),"") -> 79.0625 | L21: =IFERROR((AVERAGE(E21:K21)*0.05),"") -> 3.953125 | M21: 100 | N21: 80 | AB21: =IFERROR(AVERAGE(M21:AA21),"") -> 90 | AC21: =IFERROR((AVERAGE(M21:AA21)*0.4)+(AB21*0.05),"") -> 40.5 | AD21: 100 | AE21: 0 | AF21: 100 | AG21: 90 | AS21: =IFERROR(AVERAGE(AD21:AR21),"") -> 72.5 | AT21: =IFERROR((AVERAGE(AD21:AR21)*0.35)+(AS21*0.05),"") -> 29 | BA21: =IFERROR(AVERAGE(M21:AB21,AD21:AS21),"") -> 79.0625 | BB21: =IFERROR((AVERAGE(AU21:BA21)*0.05),"") -> 3.953125 | BE21: =IFERROR((AVERAGE(BC21)*0.025)+(BD21*0.025),"") | BF21: =IF(SUM(BB21,AT21,AC21,L21,BE21)=0,"",SUM(BB21,AT21,AC21,L21,BE21)) -> 77.40625 | BG21: =IF(BF21="","",IF(BF21<51,"REPROBADO",IF(BF21>=51,"APROBADO"," "))) -> APROBADO
A22: 8 | B22: NUMBELA SAAVEDRA RAFAEL | C22: =IF(B22<>"",IFERROR(EVAL.ANUAL!X16,""),"") -> 27 | D22: =IF(B22<>"",IFERROR(EVAL.ANUAL!I16,""),"") -> 80 | K22: =IFERROR((AVERAGE(M22:AB22,AD22:AS22)),"") -> 85.666667 | L22: =IFERROR((AVERAGE(E22:K22)*0.05),"") -> 4.2833333 | M22: 100 | N22: 54 | AB22: =IFERROR(AVERAGE(M22:AA22),"") -> 77 | AC22: =IFERROR((AVERAGE(M22:AA22)*0.4)+(AB22*0.05),"") -> 34.65 | AD22: 100 | AE22: 100 | AF22: 90 | AG22: 90 | AH22: 70 | AS22: =IFERROR(AVERAGE(AD22:AR22),"") -> 90 | AT22: =IFERROR((AVERAGE(AD22:AR22)*0.35)+(AS22*0.05),"") -> 36 | BA22: =IFERROR(AVERAGE(M22:AB22,AD22:AS22),"") -> 85.666667 | BB22: =IFERROR((AVERAGE(AU22:BA22)*0.05),"") -> 4.2833333 | BE22: =IFERROR((AVERAGE(BC22)*0.025)+(BD22*0.025),"") | BF22: =IF(SUM(BB22,AT22,AC22,L22,BE22)=0,"",SUM(BB22,AT22,AC22,L22,BE22)) -> 79.216667 | BG22: =IF(BF22="","",IF(BF22<51,"REPROBADO",IF(BF22>=51,"APROBADO"," "))) -> APROBADO
A23: 9 | B23: PEÑALOZA PRADO RAFAEL ANDRES | C23: =IF(B23<>"",IFERROR(EVAL.ANUAL!X17,""),"") -> 18 | D23: =IF(B23<>"",IFERROR(EVAL.ANUAL!I17,""),"") -> 53 | K23: =IFERROR((AVERAGE(M23:AB23,AD23:AS23)),"") -> 48.333333 | L23: =IFERROR((AVERAGE(E23:K23)*0.05),"") -> 2.4166667 | M23: 80 | N23: 66 | AB23: =IFERROR(AVERAGE(M23:AA23),"") -> 73 | AC23: =IFERROR((AVERAGE(M23:AA23)*0.4)+(AB23*0.05),"") -> 32.85 | AD23: 0 | AE23: 0 | AF23: 0 | AG23: 80 | AH23: 100 | AS23: =IFERROR(AVERAGE(AD23:AR23),"") -> 36 | AT23: =IFERROR((AVERAGE(AD23:AR23)*0.35)+(AS23*0.05),"") -> 14.4 | BA23: =IFERROR(AVERAGE(M23:AB23,AD23:AS23),"") -> 48.333333 | BB23: =IFERROR((AVERAGE(AU23:BA23)*0.05),"") -> 2.4166667 | BE23: =IFERROR((AVERAGE(BC23)*0.025)+(BD23*0.025),"") | BF23: =IF(SUM(BB23,AT23,AC23,L23,BE23)=0,"",SUM(BB23,AT23,AC23,L23,BE23)) -> 52.083333 | BG23: =IF(BF23="","",IF(BF23<51,"REPROBADO",IF(BF23>=51,"APROBADO"," "))) -> APROBADO
A24: 10 | B24: PARDO LOPEZ ABIGAIL | C24: =IF(B24<>"",IFERROR(EVAL.ANUAL!X18,""),"") -> 11 | D24: =IF(B24<>"",IFERROR(EVAL.ANUAL!I18,""),"") -> 32 | K24: =IFERROR((AVERAGE(M24:AB24,AD24:AS24)),"") -> 32.333333 | L24: =IFERROR((AVERAGE(E24:K24)*0.05),"") -> 1.6166667 | M24: 10 | N24: 64 | AB24: =IFERROR(AVERAGE(M24:AA24),"") -> 37 | AC24: =IFERROR((AVERAGE(M24:AA24)*0.4)+(AB24*0.05),"") -> 16.65 | AD24: 0 | AE24: 0 | AF24: 0 | AG24: 50 | AH24: 100 | AS24: =IFERROR(AVERAGE(AD24:AR24),"") -> 30 | AT24: =IFERROR((AVERAGE(AD24:AR24)*0.35)+(AS24*0.05),"") -> 12 | BA24: =IFERROR(AVERAGE(M24:AB24,AD24:AS24),"") -> 32.333333 | BB24: =IFERROR((AVERAGE(AU24:BA24)*0.05),"") -> 1.6166667 | BE24: =IFERROR((AVERAGE(BC24)*0.025)+(BD24*0.025),"") | BF24: =IF(SUM(BB24,AT24,AC24,L24,BE24)=0,"",SUM(BB24,AT24,AC24,L24,BE24)) -> 31.883333 | BG24: =IF(BF24="","",IF(BF24<51,"REPROBADO",IF(BF24>=51,"APROBADO"," "))) -> REPROBADO
A25: 11 | B25: ROCABADO ANDIA MARIANA | C25: =IF(B25<>"",IFERROR(EVAL.ANUAL!X19,""),"") -> 26 | D25: =IF(B25<>"",IFERROR(EVAL.ANUAL!I19,""),"") -> 77 | K25: =IFERROR((AVERAGE(M25:AB25,AD25:AS25)),"") -> 82 | L25: =IFERROR((AVERAGE(E25:K25)*0.05),"") -> 4.1 | M25: 100 | N25: 56 | AB25: =IFERROR(AVERAGE(M25:AA25),"") -> 78 | AC25: =IFERROR((AVERAGE(M25:AA25)*0.4)+(AB25*0.05),"") -> 35.1 | AD25: 100 | AE25: 40 | AF25: 90 | AG25: 90 | AH25: 100 | AS25: =IFERROR(AVERAGE(AD25:AR25),"") -> 84 | AT25: =IFERROR((AVERAGE(AD25:AR25)*0.35)+(AS25*0.05),"") -> 33.6 | BA25: =IFERROR(AVERAGE(M25:AB25,AD25:AS25),"") -> 82 | BB25: =IFERROR((AVERAGE(AU25:BA25)*0.05),"") -> 4.1 | BE25: =IFERROR((AVERAGE(BC25)*0.025)+(BD25*0.025),"") | BF25: =IF(SUM(BB25,AT25,AC25,L25,BE25)=0,"",SUM(BB25,AT25,AC25,L25,BE25)) -> 76.9 | BG25: =IF(BF25="","",IF(BF25<51,"REPROBADO",IF(BF25>=51,"APROBADO"," "))) -> APROBADO
A26: 12 | B26: SEJAS CAMPOS ZULMA | C26: =IF(B26<>"",IFERROR(EVAL.ANUAL!X20,""),"") -> 26 | D26: =IF(B26<>"",IFERROR(EVAL.ANUAL!I20,""),"") -> 77 | K26: =IFERROR((AVERAGE(M26:AB26,AD26:AS26)),"") -> 78.3125 | L26: =IFERROR((AVERAGE(E26:K26)*0.05),"") -> 3.915625 | M26: 100 | N26: 76 | AB26: =IFERROR(AVERAGE(M26:AA26),"") -> 88 | AC26: =IFERROR((AVERAGE(M26:AA26)*0.4)+(AB26*0.05),"") -> 39.6 | AD26: 0 | AE26: 100 | AF26: 90 | AG26: 100 | AS26: =IFERROR(AVERAGE(AD26:AR26),"") -> 72.5 | AT26: =IFERROR((AVERAGE(AD26:AR26)*0.35)+(AS26*0.05),"") -> 29 | BA26: =IFERROR(AVERAGE(M26:AB26,AD26:AS26),"") -> 78.3125 | BB26: =IFERROR((AVERAGE(AU26:BA26)*0.05),"") -> 3.915625 | BE26: =IFERROR((AVERAGE(BC26)*0.025)+(BD26*0.025),"") | BF26: =IF(SUM(BB26,AT26,AC26,L26,BE26)=0,"",SUM(BB26,AT26,AC26,L26,BE26)) -> 76.43125 | BG26: =IF(BF26="","",IF(BF26<51,"REPROBADO",IF(BF26>=51,"APROBADO"," "))) -> APROBADO
A27: 13 | B27: VARGAS REQUEZ ZOE | C27: =IF(B27<>"",IFERROR(EVAL.ANUAL!X21,""),"") -> 20 | D27: =IF(B27<>"",IFERROR(EVAL.ANUAL!I21,""),"") -> 58 | K27: =IFERROR((AVERAGE(M27:AB27,AD27:AS27)),"") -> 58.666667 | L27: =IFERROR((AVERAGE(E27:K27)*0.05),"") -> 2.9333333 | M27: 70 | N27: 58 | AB27: =IFERROR(AVERAGE(M27:AA27),"") -> 64 | AC27: =IFERROR((AVERAGE(M27:AA27)*0.4)+(AB27*0.05),"") -> 28.8 | AD27: 100 | AE27: 0 | AF27: 0 | AG27: 90 | AH27: 90 | AS27: =IFERROR(AVERAGE(AD27:AR27),"") -> 56 | AT27: =IFERROR((AVERAGE(AD27:AR27)*0.35)+(AS27*0.05),"") -> 22.4 | BA27: =IFERROR(AVERAGE(M27:AB27,AD27:AS27),"") -> 58.666667 | BB27: =IFERROR((AVERAGE(AU27:BA27)*0.05),"") -> 2.9333333 | BE27: =IFERROR((AVERAGE(BC27)*0.025)+(BD27*0.025),"") | BF27: =IF(SUM(BB27,AT27,AC27,L27,BE27)=0,"",SUM(BB27,AT27,AC27,L27,BE27)) -> 57.066667 | BG27: =IF(BF27="","",IF(BF27<51,"REPROBADO",IF(BF27>=51,"APROBADO"," "))) -> APROBADO
A28: 14 | C28: =IF(B28<>"",IFERROR(EVAL.ANUAL!X22,""),"") | D28: =IF(B28<>"",IFERROR(EVAL.ANUAL!I22,""),"") | K28: =IFERROR((AVERAGE(M28:AB28,AD28:AS28)),"") | L28: =IFERROR((AVERAGE(E28:K28)*0.05),"") | AB28: =IFERROR(AVERAGE(M28:AA28),"") | AC28: =IFERROR((AVERAGE(M28:AA28)*0.4)+(AB28*0.05),"") | AS28: =IFERROR(AVERAGE(AD28:AR28),"") | AT28: =IFERROR((AVERAGE(AD28:AR28)*0.35)+(AS28*0.05),"") | BA28: =IFERROR(AVERAGE(M28:AB28,AD28:AS28),"") | BB28: =IFERROR((AVERAGE(AU28:BA28)*0.05),"") | BE28: =IFERROR((AVERAGE(BC28)*0.025)+(BD28*0.025),"") | BF28: =IF(SUM(BB28,AT28,AC28,L28,BE28)=0,"",SUM(BB28,AT28,AC28,L28,BE28)) | BG28: =IF(BF28="","",IF(BF28<51,"REPROBADO",IF(BF28>=51,"APROBADO"," ")))
A29: 15 | C29: =IF(B29<>"",IFERROR(EVAL.ANUAL!X23,""),"") | D29: =IF(B29<>"",IFERROR(EVAL.ANUAL!I23,""),"") | K29: =IFERROR((AVERAGE(M29:AB29,AD29:AS29)),"") | L29: =IFERROR((AVERAGE(E29:K29)*0.05),"") | AB29: =IFERROR(AVERAGE(M29:AA29),"") | AC29: =IFERROR((AVERAGE(M29:AA29)*0.4)+(AB29*0.05),"") | AS29: =IFERROR(AVERAGE(AD29:AR29),"") | AT29: =IFERROR((AVERAGE(AD29:AR29)*0.35)+(AS29*0.05),"") | BA29: =IFERROR(AVERAGE(M29:AB29,AD29:AS29),"") | BB29: =IFERROR((AVERAGE(AU29:BA29)*0.05),"") | BE29: =IFERROR((AVERAGE(BC29)*0.025)+(BD29*0.025),"") | BF29: =IF(SUM(BB29,AT29,AC29,L29,BE29)=0,"",SUM(BB29,AT29,AC29,L29,BE29)) | BG29: =IF(BF29="","",IF(BF29<51,"REPROBADO",IF(BF29>=51,"APROBADO"," ")))
A30: 16 | C30: =IF(B30<>"",IFERROR(EVAL.ANUAL!X24,""),"") | D30: =IF(B30<>"",IFERROR(EVAL.ANUAL!I24,""),"") | K30: =IFERROR((AVERAGE(M30:AB30,AD30:AS30)),"") | L30: =IFERROR((AVERAGE(E30:K30)*0.05),"") | AB30: =IFERROR(AVERAGE(M30:AA30),"") | AC30: =IFERROR((AVERAGE(M30:AA30)*0.4)+(AB30*0.05),"") | AS30: =IFERROR(AVERAGE(AD30:AR30),"") | AT30: =IFERROR((AVERAGE(AD30:AR30)*0.35)+(AS30*0.05),"") | BA30: =IFERROR(AVERAGE(M30:AB30,AD30:AS30),"") | BB30: =IFERROR((AVERAGE(AU30:BA30)*0.05),"") | BE30: =IFERROR((AVERAGE(BC30)*0.025)+(BD30*0.025),"") | BF30: =IF(SUM(BB30,AT30,AC30,L30,BE30)=0,"",SUM(BB30,AT30,AC30,L30,BE30)) | BG30: =IF(BF30="","",IF(BF30<51,"REPROBADO",IF(BF30>=51,"APROBADO"," ")))
A31: 17 | C31: =IF(B31<>"",IFERROR(EVAL.ANUAL!X25,""),"") | D31: =IF(B31<>"",IFERROR(EVAL.ANUAL!I25,""),"") | K31: =IFERROR((AVERAGE(M31:AB31,AD31:AS31)),"") | L31: =IFERROR((AVERAGE(E31:K31)*0.05),"") | AB31: =IFERROR(AVERAGE(M31:AA31),"") | AC31: =IFERROR((AVERAGE(M31:AA31)*0.4)+(AB31*0.05),"") | AS31: =IFERROR(AVERAGE(AD31:AR31),"") | AT31: =IFERROR((AVERAGE(AD31:AR31)*0.35)+(AS31*0.05),"") | BA31: =IFERROR(AVERAGE(M31:AB31,AD31:AS31),"") | BB31: =IFERROR((AVERAGE(AU31:BA31)*0.05),"") | BE31: =IFERROR((AVERAGE(BC31)*0.025)+(BD31*0.025),"") | BF31: =IF(SUM(BB31,AT31,AC31,L31,BE31)=0,"",SUM(BB31,AT31,AC31,L31,BE31)) | BG31: =IF(BF31="","",IF(BF31<51,"REPROBADO",IF(BF31>=51,"APROBADO"," ")))
A32: 18 | C32: =IF(B32<>"",IFERROR(EVAL.ANUAL!X26,""),"") | D32: =IF(B32<>"",IFERROR(EVAL.ANUAL!I26,""),"") | K32: =IFERROR((AVERAGE(M32:AB32,AD32:AS32)),"") | L32: =IFERROR((AVERAGE(E32:K32)*0.05),"") | AB32: =IFERROR(AVERAGE(M32:AA32),"") | AC32: =IFERROR((AVERAGE(M32:AA32)*0.4)+(AB32*0.05),"") | AS32: =IFERROR(AVERAGE(AD32:AR32),"") | AT32: =IFERROR((AVERAGE(AD32:AR32)*0.35)+(AS32*0.05),"") | BA32: =IFERROR(AVERAGE(M32:AB32,AD32:AS32),"") | BB32: =IFERROR((AVERAGE(AU32:BA32)*0.05),"") | BE32: =IFERROR((AVERAGE(BC32)*0.025)+(BD32*0.025),"") | BF32: =IF(SUM(BB32,AT32,AC32,L32,BE32)=0,"",SUM(BB32,AT32,AC32,L32,BE32)) | BG32: =IF(BF32="","",IF(BF32<51,"REPROBADO",IF(BF32>=51,"APROBADO"," ")))
A33: 19 | C33: =IF(B33<>"",IFERROR(EVAL.ANUAL!X27,""),"") | D33: =IF(B33<>"",IFERROR(EVAL.ANUAL!I27,""),"") | K33: =IFERROR((AVERAGE(M33:AB33,AD33:AS33)),"") | L33: =IFERROR((AVERAGE(E33:K33)*0.05),"") | AC33: =IFERROR((AVERAGE(M33:AA33)*0.4)+(AB33*0.05),"") | AS33: =IFERROR(AVERAGE(AD33:AR33),"") | AT33: =IFERROR((AVERAGE(AD33:AR33)*0.35)+(AS33*0.05),"") | BB33: =IFERROR((AVERAGE(AU33:BA33)*0.05),"") | BE33: =IFERROR((AVERAGE(BC33)*0.025)+(BD33*0.025),"") | BF33: =IF(SUM(BB33,AT33,AC33,L33,BE33)=0,"",SUM(BB33,AT33,AC33,L33,BE33)) | BG33: =IF(BF33="","",IF(BF33<51,"REPROBADO",IF(BF33>=51,"APROBADO"," ")))
A34: 20 | C34: =IF(B34<>"",IFERROR(EVAL.ANUAL!X28,""),"") | D34: =IF(B34<>"",IFERROR(EVAL.ANUAL!I28,""),"") | K34: =IFERROR((AVERAGE(M34:AB34,AD34:AS34)),"") | L34: =IFERROR((AVERAGE(E34:K34)*0.05),"") | AB34: =IFERROR(AVERAGE(M34:AA34),"") | AC34: =IFERROR((AVERAGE(M34:AA34)*0.4)+(AB34*0.05),"") | AS34: =IFERROR(AVERAGE(AD34:AR34),"") | AT34: =IFERROR((AVERAGE(AD34:AR34)*0.35)+(AS34*0.05),"") | BA34: =IFERROR(AVERAGE(M34:AB34,AD34:AS34),"") | BB34: =IFERROR((AVERAGE(AU34:BA34)*0.05),"") | BE34: =IFERROR((AVERAGE(BC34)*0.025)+(BD34*0.025),"") | BF34: =IF(SUM(BB34,AT34,AC34,L34,BE34)=0,"",SUM(BB34,AT34,AC34,L34,BE34)) | BG34: =IF(BF34="","",IF(BF34<51,"REPROBADO",IF(BF34>=51,"APROBADO"," ")))
A35: 21 | C35: =IF(B35<>"",IFERROR(EVAL.ANUAL!X29,""),"") | D35: =IF(B35<>"",IFERROR(EVAL.ANUAL!I29,""),"") | K35: =IFERROR((AVERAGE(M35:AB35,AD35:AS35)),"") | L35: =IFERROR((AVERAGE(E35:K35)*0.05),"") | AB35: =IFERROR(AVERAGE(M35:AA35),"") | AC35: =IFERROR((AVERAGE(M35:AA35)*0.4)+(AB35*0.05),"") | AS35: =IFERROR(AVERAGE(AD35:AR35),"") | AT35: =IFERROR((AVERAGE(AD35:AR35)*0.35)+(AS35*0.05),"") | BA35: =IFERROR(AVERAGE(M35:AB35,AD35:AS35),"") | BB35: =IFERROR((AVERAGE(AU35:BA35)*0.05),"") | BE35: =IFERROR((AVERAGE(BC35)*0.025)+(BD35*0.025),"") | BF35: =IF(SUM(BB35,AT35,AC35,L35,BE35)=0,"",SUM(BB35,AT35,AC35,L35,BE35)) | BG35: =IF(BF35="","",IF(BF35<51,"REPROBADO",IF(BF35>=51,"APROBADO"," ")))
A36: 22 | C36: =IF(B36<>"",IFERROR(EVAL.ANUAL!X30,""),"") | D36: =IF(B36<>"",IFERROR(EVAL.ANUAL!I30,""),"") | K36: =IFERROR((AVERAGE(M36:AB36,AD36:AS36)),"") | L36: =IFERROR((AVERAGE(E36:K36)*0.05),"") | AB36: =IFERROR(AVERAGE(M36:AA36),"") | AC36: =IFERROR((AVERAGE(M36:AA36)*0.4)+(AB36*0.05),"") | AS36: =IFERROR(AVERAGE(AD36:AR36),"") | AT36: =IFERROR((AVERAGE(AD36:AR36)*0.35)+(AS36*0.05),"") | BA36: =IFERROR(AVERAGE(M36:AB36,AD36:AS36),"") | BB36: =IFERROR((AVERAGE(AU36:BA36)*0.05),"") | BE36: =IFERROR((AVERAGE(BC36)*0.025)+(BD36*0.025),"") | BF36: =IF(SUM(BB36,AT36,AC36,L36,BE36)=0,"",SUM(BB36,AT36,AC36,L36,BE36)) | BG36: =IF(BF36="","",IF(BF36<51,"REPROBADO",IF(BF36>=51,"APROBADO"," ")))
A37: 23 | C37: =IF(B37<>"",IFERROR(EVAL.ANUAL!X31,""),"") | D37: =IF(B37<>"",IFERROR(EVAL.ANUAL!I31,""),"") | K37: =IFERROR((AVERAGE(M37:AB37,AD37:AS37)),"") | L37: =IFERROR((AVERAGE(E37:K37)*0.05),"") | AB37: =IFERROR(AVERAGE(M37:AA37),"") | AC37: =IFERROR((AVERAGE(M37:AA37)*0.4)+(AB37*0.05),"") | AS37: =IFERROR(AVERAGE(AD37:AR37),"") | AT37: =IFERROR((AVERAGE(AD37:AR37)*0.35)+(AS37*0.05),"") | BA37: =IFERROR(AVERAGE(M37:AB37,AD37:AS37),"") | BB37: =IFERROR((AVERAGE(AU37:BA37)*0.05),"") | BE37: =IFERROR((AVERAGE(BC37)*0.025)+(BD37*0.025),"") | BF37: =IF(SUM(BB37,AT37,AC37,L37,BE37)=0,"",SUM(BB37,AT37,AC37,L37,BE37)) | BG37: =IF(BF37="","",IF(BF37<51,"REPROBADO",IF(BF37>=51,"APROBADO"," ")))
C38: =IF(B38<>"",IFERROR(EVAL.ANUAL!X32,""),"") | D38: =IF(B38<>"",IFERROR(EVAL.ANUAL!I32,""),"") | K38: =IFERROR((AVERAGE(M38:AB38,AD38:AS38)),"") | L38: =IFERROR((AVERAGE(E38:K38)*0.05),"") | AB38: =IFERROR(AVERAGE(M38:AA38),"") | AC38: =IFERROR((AVERAGE(M38:AA38)*0.4)+(AB38*0.05),"") | AS38: =IFERROR(AVERAGE(AD38:AR38),"") | AT38: =IFERROR((AVERAGE(AD38:AR38)*0.35)+(AS38*0.05),"") | BA38: =IFERROR(AVERAGE(M38:AB38,AD38:AS38),"") | BB38: =IFERROR((AVERAGE(AU38:BA38)*0.05),"") | BE38: =IFERROR((AVERAGE(BC38)*0.025)+(BD38*0.025),"") | BF38: =IF(SUM(BB38,AT38,AC38,L38,BE38)=0,"",SUM(BB38,AT38,AC38,L38,BE38)) | BG38: =IF(BF38="","",IF(BF38<51,"REPROBADO",IF(BF38>=51,"APROBADO"," ")))
C39: =IF(B39<>"",IFERROR(EVAL.ANUAL!X33,""),"") | D39: =IF(B39<>"",IFERROR(EVAL.ANUAL!I33,""),"") | K39: =IFERROR((AVERAGE(M39:AB39,AD39:AS39)),"") | L39: =IFERROR((AVERAGE(E39:K39)*0.05),"") | AB39: =IFERROR(AVERAGE(M39:AA39),"") | AC39: =IFERROR((AVERAGE(M39:AA39)*0.4)+(AB39*0.05),"") | AS39: =IFERROR(AVERAGE(AD39:AR39),"") | AT39: =IFERROR((AVERAGE(AD39:AR39)*0.35)+(AS39*0.05),"") | BA39: =IFERROR(AVERAGE(M39:AB39,AD39:AS39),"") | BB39: =IFERROR((AVERAGE(AU39:BA39)*0.05),"") | BE39: =IFERROR((AVERAGE(BC39)*0.025)+(BD39*0.025),"") | BF39: =IF(SUM(BB39,AT39,AC39,L39,BE39)=0,"",SUM(BB39,AT39,AC39,L39,BE39)) | BG39: =IF(BF39="","",IF(BF39<51,"REPROBADO",IF(BF39>=51,"APROBADO"," ")))
C40: =IF(B40<>"",IFERROR(EVAL.ANUAL!X34,""),"") | D40: =IF(B40<>"",IFERROR(EVAL.ANUAL!I34,""),"") | K40: =IFERROR((AVERAGE(M40:AB40,AD40:AS40)),"") | L40: =IFERROR((AVERAGE(E40:K40)*0.05),"") | AB40: =IFERROR(AVERAGE(M40:AA40),"") | AC40: =IFERROR((AVERAGE(M40:AA40)*0.4)+(AB40*0.05),"") | AS40: =IFERROR(AVERAGE(AD40:AR40),"") | AT40: =IFERROR((AVERAGE(AD40:AR40)*0.35)+(AS40*0.05),"") | BA40: =IFERROR(AVERAGE(M40:AB40,AD40:AS40),"") | BB40: =IFERROR((AVERAGE(AU40:BA40)*0.05),"") | BE40: =IFERROR((AVERAGE(BC40)*0.025)+(BD40*0.025),"") | BF40: =IF(SUM(BB40,AT40,AC40,L40,BE40)=0,"",SUM(BB40,AT40,AC40,L40,BE40)) | BG40: =IF(BF40="","",IF(BF40<51,"REPROBADO",IF(BF40>=51,"APROBADO"," ")))
C41: =IF(B41<>"",IFERROR(EVAL.ANUAL!X35,""),"") | D41: =IF(B41<>"",IFERROR(EVAL.ANUAL!I35,""),"") | K41: =IFERROR((AVERAGE(M41:AB41,AD41:AS41)),"") | L41: =IFERROR((AVERAGE(E41:K41)*0.05),"") | AB41: =IFERROR(AVERAGE(M41:AA41),"") | AC41: =IFERROR((AVERAGE(M41:AA41)*0.4)+(AB41*0.05),"") | AS41: =IFERROR(AVERAGE(AD41:AR41),"") | AT41: =IFERROR((AVERAGE(AD41:AR41)*0.35)+(AS41*0.05),"") | BA41: =IFERROR(AVERAGE(M41:AB41,AD41:AS41),"") | BB41: =IFERROR((AVERAGE(AU41:BA41)*0.05),"") | BE41: =IFERROR((AVERAGE(BC41)*0.025)+(BD41*0.025),"") | BF41: =IF(SUM(BB41,AT41,AC41,L41,BE41)=0,"",SUM(BB41,AT41,AC41,L41,BE41)) | BG41: =IF(BF41="","",IF(BF41<51,"REPROBADO",IF(BF41>=51,"APROBADO"," ")))
...

Sheet 2doT
A2: UNIDAD EDUCATIVA: COLEGIO DESPERTAD | M2: INICIO DE BIMESTRE : | T2: 45421 | AD2: No. TOTAL DE APROBADOS | AL2: =COUNTIF(BF15:BF56,">51") -> 0 | BC2: DIAS RESTANTES PARA FIN DE TRIMESTRE
A3: EDUCACION SECUNDARIA COMUNITARIA PRODUCTIVA | M3: FIN DE BIMESTRE : | T3: 45530 | AD3: No. TOTAL DE REPROBADOS | AL3: =COUNTIF(BF15:BF56,"<=51") -> 0 | BC3: =+T3-S8 -> 145
A4: =+'1erT'!A4:AC4 -> CURSO: 2ndo A Secundaria | R4: =T3-T2-10 -> 99 | Z4: Días
A5: =+'1erT'!A5:AC5 -> DIRECTORA : EUGENIA CONDORI MOYA
A6: =+'1erT'!A6:AC6 -> MAESTRO : MARCELO A. RODRIGUEZ GRACIA
A7: =+'1erT'!A7:AC7 -> CAMPO : COMUNIDAD Y SOCIEDAD
A8: =+'1erT'!A8:L8 -> MATERIA : HISTORIA | M8: FECHA ACTUAL : | S8: =TODAY() -> 45385
E9: EVALUACION DEL MAESTRO DIMENSIONES | BC9: AUTO EVALUACION DIMENSIONES (5) | BF9: TOTAL BIMESTRAL | BG9: SITUACION BIMESTRAL
A10: Nº | B10: Nombre completo | C10: ACUMULADA | D10: BIMESTRE | E10: SER (5) | M10: SABER (45) | AD10: HACER (40) | AU10: DECIDIR (5) | BC10: SER (2.5) | BD10: DECIDIR (2.5) | BE10: TOTAL
E11: EXPRESA ACTITUDES DE RESPETO EN PALABRAS Y ACCIONES HACIA EL Y CON LOS DEMAS | F11: ES RESPONSIBLE Y PUNTUAL AL LLEGAR A CLASE Y AL ENTREGAR TRABAJOS | G11: DEMUESTRA SOLIDARIDAD EN SUS ACTIVIDADES Y RELACIONES INTERPERSONALES | H11: FORTALEZCO MI IDENTIDAD PERSONAL SIN RECURRIR A COPIAS DE IDENTIDADES | I11: PRACTICO EL EQUILIBRIO EMOCIONAL QUE ES EL REFLEJO DE LO QUE VEO EN MI HOGAR | J11: OTROS VALORES | K11: OTROS VALORES 2 | L11: TOTAL | AB11: EVALUACION PROMEDIO MAESTRO - 5 | AC11: TOTAL | AS11: EVALUACION PROMEDIO MAESTRO - 5 | AT11: TOTAL | AU11: DEMUESTRO INICIATIVA DURANTE LAS ACTIVIDADES DEL AULA | AV11: RESPETO LAS NORMAS DE CONVIVENCIA ENTRE LOS COMPA;EROS | AW11: ME HAGO CARGO DE LAS PERTENENCIAS QUE TRAIGO AL COLEGIO | AX11: HAGO USO APROPIADO DEL LENGUAJE SIN USAR INSULTOS O APODOS OFENSIVOS | AY11: SOY PERSEVERANTE Y RESPONSABLEAL ASUMIR UN TRABAJO GRUPAL | AZ11: OTROS VALORES | BA11: OTROS VALORES 2 | BB11: TOTAL | BC11: HAGO USO APROPIADO DEL LENGUAJE SIN USAR INSULTOS O APODOS OFENSIVOS | BD11: SOY PERSEVERANTE Y RESPONSABLEAL ASUMIR UN TRABAJO GRUPAL
B12: FECHA ENCARGADA | L12: =IFERROR(AVERAGE(L15:L56),"") | AC12: =IFERROR(AVERAGE(AC15:AC56),"") | AT12: =IFERROR(AVERAGE(AT15:AT56),"") | BB12: =IFERROR(AVERAGE(BB15:BB56),"") | BE12: =IFERROR(AVERAGE(BE15:BE56),"") | BF12: =IF(SUM(BB12,AT12,AC12,L12)=0,"",SUM(BB12,AT12,AC12,L12)) | BG12: =IF(BF12="","",IF(BF12<=33,"Muestra muy poco interés en el proceso de aprendizaje",IF(BF12<=52,"No comprende las operaciones estudiadas",IF(BF12<=80,"Comprende las propiedades estudiadas y resuelve satisfactoriamente los problemas"," Resuelve satisfactoriamente los problemas y Relaciona lo estudiado con la realidad."))))
B13: FECHA DE ENTREGA
B14: TIEMPO ( DIAS ) | E14: =+E13-E12 -> 0 | F14: =+F13-F12 -> 0 | G14: =+G13-G12 -> 0 | H14: =+H13-H12 -> 0 | I14: =+I13-I12 -> 0 | J14: =+J13-J12 -> 0 | K14: =+K13-K12 -> 0 | M14: =+M13-M12 -> 0 | N14: =+N13-N12 -> 0 | O14: =+O13-O12 -> 0 | P14: =+P13-P12 -> 0 | Q14: =+Q13-Q12 -> 0 | R14: =+R13-R12 -> 0 | S14: =+S13-S12 -> 0 | T14: =+T13-T12 -> 0 | ... AA14: =+AA13-AA12 -> 0 | AD14: =+AD13-AD12 -> 0 | AE14: =+AE13-AE12 -> 0 | AF14: =+AF13-AF12 -> 0 | AG14: =+AG13-AG12 -> 0 | AH14: =+AH13-AH12 -> 0 | AI14: =+AI13-AI12 -> 0 | AJ14: =+AJ13-AJ12 -> 0 | AK14: =+AK13-AK12 -> 0 | ... AR14: =+AR13-AR12 -> 0 | AU14: =+AU13-AU12 -> 0 | AV14: =+AV13-AV12 -> 0 | AW14: =+AW13-AW12 -> 0 | AX14: =+AX13-AX12 -> 0 | AY14: =+AY13-AY12 -> 0 | AZ14: =+AZ13-AZ12 -> 0 | BA14: =+BA13-BA12 -> 0 | BC14: =+BC13-BC12 -> 0 | BD14: =+BD13-BD12 -> 0
A15: =IF('1erT'!A15<>"",'1erT'!A15,"") -> 1 | B15: =IF('1erT'!B15<>"",'1erT'!B15,"") -> AGUILA SEJAS MATIAS HERNAN | C15: =IF(B15<>"",IFERROR(EVAL.ANUAL!X9,""),"") -> 26 | D15: =IF(B15<>"",IFERROR(EVAL.ANUAL!P9,""),"") -> 0 | K15: =IFERROR((AVERAGE(M15:AB15,AD15:AS15)),"") | L15: =IFERROR((AVERAGE(E15:K15)*0.05),"") | AB15: =IFERROR(AVERAGE(M15:AA15),"") | AC15: =IFERROR((AVERAGE(M15:AA15)*0.4)+(AB15*0.05),"") | AS15: =IFERROR(AVERAGE(AD15:AR15),"") | AT15: =IFERROR((AVERAGE(AD15:AR15)*0.35)+(AS15*0.05),"") | BA15: =K15 | BB15: =IFERROR((AVERAGE(AU15:BA15)*0.05),"") | BE15: =IFERROR((AVERAGE(BC15)*0.025)+(BD15*0.025),"") | BF15: =IF(SUM(BB15,AT15,AC15,L15,BE15)=0,"",SUM(BB15,AT15,AC15,L15,BE15)) | BG15: =IF(BF15="","",IF(BF15<51,"REPROBADO",IF(BF15>=51,"APROBADO"," ")))
A16: =IF('1erT'!A16<>"",'1erT'!A16,"") -> 2 | B16: =IF('1erT'!B16<>"",'1erT'!B16,"") -> ANTEZANA ARANIBAR JAVIER LEANDRO | C16: =IF(B16<>"",IFERROR(EVAL.ANUAL!X10,""),"") -> 30 | D16: =IF(B16<>"",IFERROR(EVAL.ANUAL!P10,""),"") -> 0 | K16: =IFERROR((AVERAGE(M16:AB16,AD16:AS16)),"") | L16: =IFERROR((AVERAGE(E16:K16)*0.05),"") | AB16: =IFERROR(AVERAGE(M16:AA16),"") | AC16: =IFERROR((AVERAGE(M16:AA16)*0.4)+(AB16*0.05),"") | AS16: =IFERROR(AVERAGE(AD16:AR16),"") | AT16: =IFERROR((AVERAGE(AD16:AR16)*0.35)+(AS16*0.05),"") | BA16: =K16 | BB16: =IFERROR((AVERAGE(AU16:BA16)*0.05),"") | BE16: =IFERROR((AVERAGE(BC16)*0.025)+(BD16*0.025),"") | BF16: =IF(SUM(BB16,AT16,AC16,L16,BE16)=0,"",SUM(BB16,AT16,AC16,L16,BE16)) | BG16: =IF(BF16="","",IF(BF16<51,"REPROBADO",IF(BF16>=51,"APROBADO"," ")))
A17: =IF('1erT'!A17<>"",'1erT'!A17,"") -> 3 | B17: =IF('1erT'!B17<>"",'1erT'!B17,"") -> ANTEZANA TORREZ MATIAS ANDRE | C17: =IF(B17<>"",IFERROR(EVAL.ANUAL!X11,""),"") -> 29 | D17: =IF(B17<>"",IFERROR(EVAL.ANUAL!P11,""),"") -> 0 | K17: =IFERROR((AVERAGE(M17:AB17,AD17:AS17)),"") | L17: =IFERROR((AVERAGE(E17:K17)*0.05),"") | AB17: =IFERROR(AVERAGE(M17:AA17),"") | AC17: =IFERROR((AVERAGE(M17:AA17)*0.4)+(AB17*0.05),"") | AS17: =IFERROR(AVERAGE(AD17:AR17),"") | AT17: =IFERROR((AVERAGE(AD17:AR17)*0.35)+(AS17*0.05),"") | BA17: =K17 | BB17: =IFERROR((AVERAGE(AU17:BA17)*0.05),"") | BE17: =IFERROR((AVERAGE(BC17)*0.025)+(BD17*0.025),"") | BF17: =IF(SUM(BB17,AT17,AC17,L17,BE17)=0,"",SUM(BB17,AT17,AC17,L17,BE17)) | BG17: =IF(BF17="","",IF(BF17<51,"REPROBADO",IF(BF17>=51,"APROBADO"," ")))
A18: =IF('1erT'!A18<>"",'1erT'!A18,"") -> 4 | B18: =IF('1erT'!B18<>"",'1erT'!B18,"") -> CARDOZO FRANCO JOHNNY LEONARDO | C18: =IF(B18<>"",IFERROR(EVAL.ANUAL!X12,""),"") -> 30 | D18: =IF(B18<>"",IFERROR(EVAL.ANUAL!P12,""),"") -> 0 | K18: =IFERROR((AVERAGE(M18:AB18,AD18:AS18)),"") | L18: =IFERROR((AVERAGE(E18:K18)*0.05),"") | AB18: =IFERROR(AVERAGE(M18:AA18),"") | AC18: =IFERROR((AVERAGE(M18:AA18)*0.4)+(AB18*0.05),"") | AS18: =IFERROR(AVERAGE(AD18:AR18),"") | AT18: =IFERROR((AVERAGE(AD18:AR18)*0.35)+(AS18*0.05),"") | BA18: =K18 | BB18: =IFERROR((AVERAGE(AU18:BA18)*0.05),"") | BE18: =IFERROR((AVERAGE(BC18)*0.025)+(BD18*0.025),"") | BF18: =IF(SUM(BB18,AT18,AC18,L18,BE18)=0,"",SUM(BB18,AT18,AC18,L18,BE18)) | BG18: =IF(BF18="","",IF(BF18<51,"REPROBADO",IF(BF18>=51,"APROBADO"," ")))
A19: =IF('1erT'!A19<>"",'1erT'!A19,"") -> 5 | B19: =IF('1erT'!B19<>"",'1erT'!B19,"") -> ESPINOZA MUÑOZ RUBEN SEBASTIAN | C19: =IF(B19<>"",IFERROR(EVAL.ANUAL!X13,""),"") -> 10 | D19: =IF(B19<>"",IFERROR(EVAL.ANUAL!P13,""),"") -> 0 | K19: =IFERROR((AVERAGE(M19:AB19,AD19:AS19)),"") | L19: =IFERROR((AVERAGE(E19:K19)*0.05),"") | AB19: =IFERROR(AVERAGE(M19:AA19),"") | AC19: =IFERROR((AVERAGE(M19:AA19)*0.4)+(AB19*0.05),"") | AS19: =IFERROR(AVERAGE(AD19:AR19),"") | AT19: =IFERROR((AVERAGE(AD19:AR19)*0.35)+(AS19*0.05),"") | BA19: =K19 | BB19: =IFERROR((AVERAGE(AU19:BA19)*0.05),"") | BE19: =IFERROR((AVERAGE(BC19)*0.025)+(BD19*0.025),"") | BF19: =IF(SUM(BB19,AT19,AC19,L19,BE19)=0,"",SUM(BB19,AT19,AC19,L19,BE19)) | BG19: =IF(BF19="","",IF(BF19<51,"REPROBADO",IF(BF19>=51,"APROBADO"," ")))
A20: =IF('1erT'!A20<>"",'1erT'!A20,"") -> 6 | B20: =IF('1erT'!B20<>"",'1erT'!B20,"") -> HUANCA AMURRIO VALENTINA RAFAELA | C20: =IF(B20<>"",IFERROR(EVAL.ANUAL!X14,""),"") -> 22 | D20: =IF(B20<>"",IFERROR(EVAL.ANUAL!P14,""),"") -> 0 | K20: =IFERROR((AVERAGE(M20:AB20,AD20:AS20)),"") | L20: =IFERROR((AVERAGE(E20:K20)*0.05),"") | AB20: =IFERROR(AVERAGE(M20:AA20),"") | AC20: =IFERROR((AVERAGE(M20:AA20)*0.4)+(AB20*0.05),"") | AS20: =IFERROR(AVERAGE(AD20:AR20),"") | AT20: =IFERROR((AVERAGE(AD20:AR20)*0.35)+(AS20*0.05),"") | BA20: =K20 | BB20: =IFERROR((AVERAGE(AU20:BA20)*0.05),"") | BE20: =IFERROR((AVERAGE(BC20)*0.025)+(BD20*0.025),"") | BF20: =IF(SUM(BB20,AT20,AC20,L20,BE20)=0,"",SUM(BB20,AT20,AC20,L20,BE20)) | BG20: =IF(BF20="","",IF(BF20<51,"REPROBADO",IF(BF20>=51,"APROBADO"," ")))
A21: =IF('1erT'!A21<>"",'1erT'!A21,"") -> 7 | B21: =IF('1erT'!B21<>"",'1erT'!B21,"") -> MERCADO ROJAS MARIA BELEN | C21: =IF(B21<>"",IFERROR(EVAL.ANUAL!X15,""),"") -> 52 | D21: =IF(B21<>"",IFERROR(EVAL.ANUAL!P15,""),"") -> 0 | K21: =IFERROR((AVERAGE(M21:AB21,AD21:AS21)),"") | L21: =IFERROR((AVERAGE(E21:K21)*0.05),"") | AB21: =IFERROR(AVERAGE(M21:AA21),"") | AC21: =IFERROR((AVERAGE(M21:AA21)*0.4)+(AB21*0.05),"") | AS21: =IFERROR(AVERAGE(AD21:AR21),"") | AT21: =IFERROR((AVERAGE(AD21:AR21)*0.35)+(AS21*0.05),"") | BA21: =K21 | BB21: =IFERROR((AVERAGE(AU21:BA21)*0.05),"") | BE21: =IFERROR((AVERAGE(BC21)*0.025)+(BD21*0.025),"") | BF21: =IF(SUM(BB21,AT21,AC21,L21,BE21)=0,"",SUM(BB21,AT21,AC21,L21,BE21)) | BG21: =IF(BF21="","",IF(BF21<51,"REPROBADO",IF(BF21>=51,"APROBADO"," ")))
A22: =IF('1erT'!A22<>"",'1erT'!A22,"") -> 8 | B22: =IF('1erT'!B22<>"",'1erT'!B22,"") -> NUMBELA SAAVEDRA RAFAEL | C22: =IF(B22<>"",IFERROR(EVAL.ANUAL!X16,""),"") -> 27 | D22: =IF(B22<>"",IFERROR(EVAL.ANUAL!P16,""),"") -> 0 | K22: =IFERROR((AVERAGE(M22:AB22,AD22:AS22)),"") | L22: =IFERROR((AVERAGE(E22:K22)*0.05),"") | AB22: =IFERROR(AVERAGE(M22:AA22),"") | AC22: =IFERROR((AVERAGE(M22:AA22)*0.4)+(AB22*0.05),"") | AS22: =IFERROR(AVERAGE(AD22:AR22),"") | AT22: =IFERROR((AVERAGE(AD22:AR22)*0.35)+(AS22*0.05),"") | BA22: =K22 | BB22: =IFERROR((AVERAGE(AU22:BA22)*0.05),"") | BE22: =IFERROR((AVERAGE(BC22)*0.025)+(BD22*0.025),"") | BF22: =IF(SUM(BB22,AT22,AC22,L22,BE22)=0,"",SUM(BB22,AT22,AC22,L22,BE22)) | BG22: =IF(BF22="","",IF(BF22<51,"REPROBADO",IF(BF22>=51,"APROBADO"," ")))
A23: =IF('1erT'!A23<>"",'1erT'!A23,"") -> 9 | B23: =IF('1erT'!B23<>"",'1erT'!B23,"") -> PEÑALOZA PRADO RAFAEL ANDRES | C23: =IF(B23<>"",IFERROR(EVAL.ANUAL!X17,""),"") -> 18 | D23: =IF(B23<>"",IFERROR(EVAL.ANUAL!P17,""),"") -> 0 | K23: =IFERROR((AVERAGE(M23:AB23,AD23:AS23)),"") | L23: =IFERROR((AVERAGE(E23:K23)*0.05),"") | AB23: =IFERROR(AVERAGE(M23:AA23),"") | AC23: =IFERROR((AVERAGE(M23:AA23)*0.4)+(AB23*0.05),"") | AS23: =IFERROR(AVERAGE(AD23:AR23),"") | AT23: =IFERROR((AVERAGE(AD23:AR23)*0.35)+(AS23*0.05),"") | BA23: =K23 | BB23: =IFERROR((AVERAGE(AU23:BA23)*0.05),"") | BE23: =IFERROR((AVERAGE(BC23)*0.025)+(BD23*0.025),"") | BF23: =IF(SUM(BB23,AT23,AC23,L23,BE23)=0,"",SUM(BB23,AT23,AC23,L23,BE23)) | BG23: =IF(BF23="","",IF(BF23<51,"REPROBADO",IF(BF23>=51,"APROBADO"," ")))
A24: =IF('1erT'!A24<>"",'1erT'!A24,"") -> 10 | B24: =IF('1erT'!B24<>"",'1erT'!B24,"") -> PARDO LOPEZ ABIGAIL | C24: =IF(B24<>"",IFERROR(EVAL.ANUAL!X18,""),"") -> 11 | D24: =IF(B24<>"",IFERROR(EVAL.ANUAL!P18,""),"") -> 0 | K24: =IFERROR((AVERAGE(M24:AB24,AD24:AS24)),"") | L24: =IFERROR((AVERAGE(E24:K24)*0.05),"") | AB24: =IFERROR(AVERAGE(M24:AA24),"") | AC24: =IFERROR((AVERAGE(M24:AA24)*0.4)+(AB24*0.05),"") | AS24: =IFERROR(AVERAGE(AD24:AR24),"") | AT24: =IFERROR((AVERAGE(AD24:AR24)*0.35)+(AS24*0.05),"") | BA24: =K24 | BB24: =IFERROR((AVERAGE(AU24:BA24)*0.05),"") | BE24: =IFERROR((AVERAGE(BC24)*0.025)+(BD24*0.025),"") | BF24: =IF(SUM(BB24,AT24,AC24,L24,BE24)=0,"",SUM(BB24,AT24,AC24,L24,BE24)) | BG24: =IF(BF24="","",IF(BF24<51,"REPROBADO",IF(BF24>=51,"APROBADO"," ")))
A25: =IF('1erT'!A25<>"",'1erT'!A25,"") -> 11 | B25: =IF('1erT'!B25<>"",'1erT'!B25,"") -> ROCABADO ANDIA MARIANA | C25: =IF(B25<>"",IFERROR(EVAL.ANUAL!X19,""),"") -> 26 | D25: =IF(B25<>"",IFERROR(EVAL.ANUAL!P19,""),"") -> 0 | K25: =IFERROR((AVERAGE(M25:AB25,AD25:AS25)),"") | L25: =IFERROR((AVERAGE(E25:K25)*0.05),"") | AB25: =IFERROR(AVERAGE(M25:AA25),"") | AC25: =IFERROR((AVERAGE(M25:AA25)*0.4)+(AB25*0.05),"") | AS25: =IFERROR(AVERAGE(AD25:AR25),"") | AT25: =IFERROR((AVERAGE(AD25:AR25)*0.35)+(AS25*0.05),"") | BA25: =K25 | BB25: =IFERROR((AVERAGE(AU25:BA25)*0.05),"") | BE25: =IFERROR((AVERAGE(BC25)*0.025)+(BD25*0.025),"") | BF25: =IF(SUM(BB25,AT25,AC25,L25,BE25)=0,"",SUM(BB25,AT25,AC25,L25,BE25)) | BG25: =IF(BF25="","",IF(BF25<51,"REPROBADO",IF(BF25>=51,"APROBADO"," ")))
A26: =IF('1erT'!A26<>"",'1erT'!A26,"") -> 12 | B26: =IF('1erT'!B26<>"",'1erT'!B26,"") -> SEJAS CAMPOS ZULMA | C26: =IF(B26<>"",IFERROR(EVAL.ANUAL!X20,""),"") -> 26 | D26: =IF(B26<>"",IFERROR(EVAL.ANUAL!P20,""),"") -> 0 | K26: =IFERROR((AVERAGE(M26:AB26,AD26:AS26)),"") | L26: =IFERROR((AVERAGE(E26:K26)*0.05),"") | AB26: =IFERROR(AVERAGE(M26:AA26),"") | AC26: =IFERROR((AVERAGE(M26:AA26)*0.4)+(AB26*0.05),"") | AS26: =IFERROR(AVERAGE(AD26:AR26),"") | AT26: =IFERROR((AVERAGE(AD26:AR26)*0.35)+(AS26*0.05),"") | BA26: =K26 | BB26: =IFERROR((AVERAGE(AU26:BA26)*0.05),"") | BE26: =IFERROR((AVERAGE(BC26)*0.025)+(BD26*0.025),"") | BF26: =IF(SUM(BB26,AT26,AC26,L26,BE26)=0,"",SUM(BB26,AT26,AC26,L26,BE26)) | BG26: =IF(BF26="","",IF(BF26<51,"REPROBADO",IF(BF26>=51,"APROBADO"," ")))
... A56: =IF('1erT'!A56<>"",'1erT'!A56,"") | B56: =IF('1erT'!B56<>"",'1erT'!B56,"") | C56: =IF(B56<>"",IFERROR(EVAL.ANUAL!X50,""),"") | D56: =IF(B56<>"",IFERROR(EVAL.ANUAL!P50,""),"") | K56: =IFERROR((AVERAGE(M56:AB56,AD56:AS56)),"") | L56: =IFERROR((AVERAGE(E56:K56)*0.05),"") | AB56: =IFERROR(AVERAGE(M56:AA56),"") | AC56: =IFERROR((AVERAGE(M56:AA56)*0.4)+(AB56*0.05),"") | AS56: =IFERROR(AVERAGE(AD56:AR56),"") | AT56: =IFERROR((AVERAGE(AD56:AR56)*0.35)+(AS56*0.05),"") | BA56: =K56 | BB56: =IFERROR((AVERAGE(AU56:BA56)*0.05),"") | BE56: =IFERROR((AVERAGE(BC56)*0.025)+(BD56*0.025),"") | BF56: =IF(SUM(BB56,AT56,AC56,L56,BE56)=0,"",SUM(BB56,AT56,AC56,L56,BE56)) | BG56: =IF(BF56="","",IF(BF56<51,"REPROBADO",IF(BF56>=51,"APROBADO"," ")))

Sheet 3erT
A1: REGISTRO DE VALORACION 3er TRIMESTRE
A2: UNIDAD EDUCATIVA: COLEGIO DESPERTAD | M2: INICIO DE BIMESTRE : | T2: 45533 | AD2: No. TOTAL DE APROBADOS | AL2: =COUNTIF(BF15:BF56,">51") -> 0 | BC2: DIAS RESTANTES PARA FIN DE TRIMESTRE
A3: EDUCACION SECUNDARIA COMUNITARIA PRODUCTIVA | M3: FIN DE BIMESTRE : | T3: 45626 | AD3: No. TOTAL DE REPROBADOS | AL3: =COUNTIF(BF15:BF56,"<=51") -> 0 | BC3: =+T3-S8 -> 241
A4: =+'1erT'!A4:AC4 -> CURSO: 2ndo A Secundaria | R4: =T3-T2 -> 93 | Z4: Días
A5: =+'1erT'!A5:AC5 -> DIRECTORA : EUGENIA CONDORI MOYA
A6: =+'1erT'!A6:AC6 -> MAESTRO : MARCELO A. RODRIGUEZ GRACIA
A7: =+'1erT'!A7:AC7 -> CAMPO : COMUNIDAD Y SOCIEDAD
A8: =+'1erT'!A8:L8 -> MATERIA : HISTORIA | M8: FECHA ACTUAL : | S8: =TODAY() -> 45385
E9: EVALUACION DEL MAESTRO DIMENSIONES | BC9: AUTO EVALUACION DIMENSIONES (5) | BF9: TOTAL BIMESTRAL | BG9: SITUACION BIMESTRAL
A10: Nº | B10: Nombre completo | C10: ACUMULADA | D10: BIMESTRE | E10: SER (5) | M10: SABER (45) | AD10: HACER (40) | AU10: DECIDIR (5) | BC10: SER (2.5) | BD10: DECIDIR (2.5) | BE10: TOTAL
E11: EXPRESA ACTITUDES DE RESPETO EN PALABRAS Y ACCIONES HACIA EL Y CON LOS DEMAS | F11: ES RESPONSIBLE Y PUNTUAL AL LLEGAR A CLASE Y AL ENTREGAR TRABAJOS | G11: DEMUESTRA SOLIDARIDAD EN SUS ACTIVIDADES Y RELACIONES INTERPERSONALES | H11: FORTALEZCO MI IDENTIDAD PERSONAL SIN RECURRIR A COPIAS DE IDENTIDADES | I11: PRACTICO EL EQUILIBRIO EMOCIONAL QUE ES EL REFLEJO DE LO QUE VEO EN MI HOGAR | J11: OTROS VALORES | K11: OTROS VALORES 2 | L11: TOTAL | AB11: EVALUACION PROMEDIO MAESTRO - 5 | AC11: TOTAL | AS11: EVALUACION PROMEDIO MAESTRO - 5 | AT11: TOTAL | AU11: DEMUESTRO INICIATIVA DURANTE LAS ACTIVIDADES DEL AULA | AV11: RESPETO LAS NORMAS DE CONVIVENCIA ENTRE LOS COMPA;EROS | AW11: ME HAGO CARGO DE LAS PERTENENCIAS QUE TRAIGO AL COLEGIO | AX11: HAGO USO APROPIADO DEL LENGUAJE SIN USAR INSULTOS O APODOS OFENSIVOS | AY11: SOY PERSEVERANTE Y RESPONSABLEAL ASUMIR UN TRABAJO GRUPAL | AZ11: OTROS VALORES | BA11: OTROS VALORES 2 | BB11: TOTAL | BC11: HAGO USO APROPIADO DEL LENGUAJE SIN USAR INSULTOS O APODOS OFENSIVOS | BD11: SOY PERSEVERANTE Y RESPONSABLEAL ASUMIR UN TRABAJO GRUPAL
B12: FECHA ENCARGADA | L12: =IFERROR(AVERAGE(L15:L56),"") | AC12: =IFERROR(AVERAGE(AC15:AC56),"") | AT12: =IFERROR(AVERAGE(AT15:AT56),"") | BB12: =IFERROR(AVERAGE(BB15:BB56),"") | BE12: =IFERROR(AVERAGE(BE15:BE56),"") | BF12: =IF(SUM(BB12,AT12,AC12,L12)=0,"",SUM(BB12,AT12,AC12,L12)) | BG12: =IF(BF12="","",IF(BF12<=33,"Muestra muy poco interés en el proceso de aprendizaje",IF(BF12<=52,"No comprende las operaciones estudiadas",IF(BF12<=80,"Comprende las propiedades estudiadas y resuelve satisfactoriamente los problemas"," Resuelve satisfactoriamente los problemas y Relaciona lo estudiado con la realidad."))))
B13: FECHA DE ENTREGA
B14: TIEMPO ( DIAS ) | E14: =+E13-E12 -> 0 | F14: =+F13-F12 -> 0 | G14: =+G13-G12 -> 0 | H14: =+H13-H12 -> 0 | I14: =+I13-I12 -> 0 | J14: =+J13-J12 -> 0 | K14: =+K13-K12 -> 0 | M14: =+M13-M12 -> 0 | N14: =+N13-N12 -> 0 | O14: =+O13-O12 -> 0 | P14: =+P13-P12 -> 0 | Q14: =+Q13-Q12 -> 0 | R14: =+R13-R12 -> 0 | S14: =+S13-S12 -> 0 | T14: =+T13-T12 -> 0 | ... AA14: =+AA13-AA12 -> 0 | AD14: =+AD13-AD12 -> 0 | AE14: =+AE13-AE12 -> 0 | AF14: =+AF13-AF12 -> 0 | AG14: =+AG13-AG12 -> 0 | AH14: =+AH13-AH12 -> 0 | AI14: =+AI13-AI12 -> 0 | AJ14: =+AJ13-AJ12 -> 0 | AK14: =+AK13-AK12 -> 0 | ... AR14: =+AR13-AR12 -> 0 | AU14: =+AU13-AU12 -> 0 | AV14: =+AV13-AV12 -> 0 | AW14: =+AW13-AW12 -> 0 | AX14: =+AX13-AX12 -> 0 | AY14: =+AY13-AY12 -> 0 | AZ14: =+AZ13-AZ12 -> 0 | BA14: =+BA13-BA12 -> 0 | BC14: =+BC13-BC12 -> 0 | BD14: =+BD13-BD12 -> 0
A15: =IF('1erT'!A15<>"",'1erT'!A15,"") -> 1 | B15: =IF('1erT'!B15<>"",'1erT'!B15,"") -> AGUILA SEJAS MATIAS HERNAN | C15: =IF(B15<>"",IFERROR(EVAL.ANUAL!X9,""),"") -> 26 | D15: =IF(B15<>"",IFERROR(EVAL.ANUAL!W9,""),"") -> 0 | K15: =IFERROR((AVERAGE(M15:AB15,AD15:AS15)),"") | L15: =IFERROR((AVERAGE(E15:K15)*0.05),"") | AB15: =IFERROR(AVERAGE(M15:AA15),"") | AC15: =IFERROR((AVERAGE(M15:AA15)*0.4)+(AB15*0.05),"") | AS15: =IFERROR(AVERAGE(AD15:AR15),"") | AT15: =IFERROR((AVERAGE(AD15:AR15)*0.35)+(AS15*0.05),"") | BA15: =K15 | BB15: =IFERROR((AVERAGE(AU15:BA15)*0.05),"") | BE15: =IFERROR((AVERAGE(BC15)*0.025)+(BD15*0.025),"") | BF15: =IF(SUM(BB15,AT15,AC15,L15,BE15)=0,"",SUM(BB15,AT15,AC15,L15,BE15)) | BG15: =IF(BF15="","",IF(BF15<51,"REPROBADO",IF(BF15>=51,"APROBADO"," ")))
A16: =IF('1erT'!A16<>"",'1erT'!A16,"") -> 2 | B16: =IF('1erT'!B16<>"",'1erT'!B16,"") -> ANTEZANA ARANIBAR JAVIER LEANDRO | C16: =IF(B16<>"",IFERROR(EVAL.ANUAL!X10,""),"") -> 30 | D16: =IF(B16<>"",IFERROR(EVAL.ANUAL!W10,""),"") -> 0 | K16: =IFERROR((AVERAGE(M16:AB16,AD16:AS16)),"") | L16: =IFERROR((AVERAGE(E16:K16)*0.05),"") | AB16: =IFERROR(AVERAGE(M16:AA16),"") | AC16: =IFERROR((AVERAGE(M16:AA16)*0.4)+(AB16*0.05),"") | AS16: =IFERROR(AVERAGE(AD16:AR16),"") | AT16: =IFERROR((AVERAGE(AD16:AR16)*0.35)+(AS16*0.05),"") | BA16: =K16 | BB16: =IFERROR((AVERAGE(AU16:BA16)*0.05),"") | BE16: =IFERROR((AVERAGE(BC16)*0.025)+(BD16*0.025),"") | BF16: =IF(SUM(BB16,AT16,AC16,L16,BE16)=0,"",SUM(BB16,AT16,AC16,L16,BE16)) | BG16: =IF(BF16="","",IF(BF16<51,"REPROBADO",IF(BF16>=51,"APROBADO"," ")))
A17: =IF('1erT'!A17<>"",'1erT'!A17,"") -> 3 | B17: =IF('1erT'!B17<>"",'1erT'!B17,"") -> ANTEZANA TORREZ MATIAS ANDRE | C17: =IF(B17<>"",IFERROR(EVAL.ANUAL!X11,""),"") -> 29 | D17: =IF(B17<>"",IFERROR(EVAL.ANUAL!W11,""),"") -> 0 | K17: =IFERROR((AVERAGE(M17:AB17,AD17:AS17)),"") | L17: =IFERROR((AVERAGE(E17:K17)*0.05),"") | AB17: =IFERROR(AVERAGE(M17:AA17),"") | AC17: =IFERROR((AVERAGE(M17:AA17)*0.4)+(AB17*0.05),"") | AS17: =IFERROR(AVERAGE(AD17:AR17),"") | AT17: =IFERROR((AVERAGE(AD17:AR17)*0.35)+(AS17*0.05),"") | BA17: =K17 | BB17: =IFERROR((AVERAGE(AU17:BA17)*0.05),"") | BE17: =IFERROR((AVERAGE(BC17)*0.025)+(BD17*0.025),"") | BF17: =IF(SUM(BB17,AT17,AC17,L17,BE17)=0,"",SUM(BB17,AT17,AC17,L17,BE17)) | BG17: =IF(BF17="","",IF(BF17<51,"REPROBADO",IF(BF17>=51,"APROBADO"," ")))
A18: =IF('1erT'!A18<>"",'1erT'!A18,"") -> 4 | B18: =IF('1erT'!B18<>"",'1erT'!B18,"") -> CARDOZO FRANCO JOHNNY LEONARDO | C18: =IF(B18<>"",IFERROR(EVAL.ANUAL!X12,""),"") -> 30 | D18: =IF(B18<>"",IFERROR(EVAL.ANUAL!W12,""),"") -> 0 | K18: =IFERROR((AVERAGE(M18:AB18,AD18:AS18)),"") | L18: =IFERROR((AVERAGE(E18:K18)*0.05),"") | AB18: =IFERROR(AVERAGE(M18:AA18),"") | AC18: =IFERROR((AVERAGE(M18:AA18)*0.4)+(AB18*0.05),"") | AS18: =IFERROR(AVERAGE(AD18:AR18),"") | AT18: =IFERROR((AVERAGE(AD18:AR18)*0.35)+(AS18*0.05),"") | BA18: =K18 | BB18: =IFERROR((AVERAGE(AU18:BA18)*0.05),"") | BE18: =IFERROR((AVERAGE(BC18)*0.025)+(BD18*0.025),"") | BF18: =IF(SUM(BB18,AT18,AC18,L18,BE18)=0,"",SUM(BB18,AT18,AC18,L18,BE18)) | BG18: =IF(BF18="","",IF(BF18<51,"REPROBADO",IF(BF18>=51,"APROBADO"," ")))
A19: =IF('1erT'!A19<>"",'1erT'!A19,"") -> 5 | B19: =IF('1erT'!B19<>"",'1erT'!B19,"") -> ESPINOZA MUÑOZ RUBEN SEBASTIAN | C19: =IF(B19<>"",IFERROR(EVAL.ANUAL!X13,""),"") -> 10 | D19: =IF(B19<>"",IFERROR(EVAL.ANUAL!W13,""),"") -> 0 | K19: =IFERROR((AVERAGE(M19:AB19,AD19:AS19)),"") | L19: =IFERROR((AVERAGE(E19:K19)*0.05),"") | AB19: =IFERROR(AVERAGE(M19:AA19),"") | AC19: =IFERROR((AVERAGE(M19:AA19)*0.4)+(AB19*0.05),"") | AS19: =IFERROR(AVERAGE(AD19:AR19),"") | AT19: =IFERROR((AVERAGE(AD19:AR19)*0.35)+(AS19*0.05),"") | BA19: =K19 | BB19: =IFERROR((AVERAGE(AU19:BA19)*0.05),"") | BE19: =IFERROR((AVERAGE(BC19)*0.025)+(BD19*0.025),"") | BF19: =IF(SUM(BB19,AT19,AC19,L19,BE19)=0,"",SUM(BB19,AT19,AC19,L19,BE19)) | BG19: =IF(BF19="","",IF(BF19<51,"REPROBADO",IF(BF19>=51,"APROBADO"," ")))
A20: =IF('1erT'!A20<>"",'1erT'!A20,"") -> 6 | B20: =IF('1erT'!B20<>"",'1erT'!B20,"") -> HUANCA AMURRIO VALENTINA RAFAELA | C20: =IF(B20<>"",IFERROR(EVAL.ANUAL!X14,""),"") -> 22 | D20: =IF(B20<>"",IFERROR(EVAL.ANUAL!W14,""),"") -> 0 | K20: =IFERROR((AVERAGE(M20:AB20,AD20:AS20)),"") | L20: =IFERROR((AVERAGE(E20:K20)*0.05),"") | AB20: =IFERROR(AVERAGE(M20:AA20),"") | AC20: =IFERROR((AVERAGE(M20:AA20)*0.4)+(AB20*0.05),"") | AS20: =IFERROR(AVERAGE(AD20:AR20),"") | AT20: =IFERROR((AVERAGE(AD20:AR20)*0.35)+(AS20*0.05),"") | BA20: =K20 | BB20: =IFERROR((AVERAGE(AU20:BA20)*0.05),"") | BE20: =IFERROR((AVERAGE(BC20)*0.025)+(BD20*0.025),"") | BF20: =IF(SUM(BB20,AT20,AC20,L20,BE20)=0,"",SUM(BB20,AT20,AC20,L20,BE20)) | BG20: =IF(BF20="","",IF(BF20<51,"REPROBADO",IF(BF20>=51,"APROBADO"," ")))
A21: =IF('1erT'!A21<>"",'1erT'!A21,"") -> 7 | B21: =IF('1erT'!B21<>"",'1erT'!B21,"") -> MERCADO ROJAS MARIA BELEN | C21: =IF(B21<>"",IFERROR(EVAL.ANUAL!X15,""),"") -> 52 | D21: =IF(B21<>"",IFERROR(EVAL.ANUAL!W15,""),"") -> 78 | K21: =IFERROR((AVERAGE(M21:AB21,AD21:AS21)),"") | L21: =IFERROR((AVERAGE(E21:K21)*0.05),"") | AB21: =IFERROR(AVERAGE(M21:AA21),"") | AC21: =IFERROR((AVERAGE(M21:AA21)*0.4)+(AB21*0.05),"") | AS21: =IFERROR(AVERAGE(AD21:AR21),"") | AT21: =IFERROR((AVERAGE(AD21:AR21)*0.35)+(AS21*0.05),"") | BA21: =K21 | BB21: =IFERROR((AVERAGE(AU21:BA21)*0.05),"") | BE21: =IFERROR((AVERAGE(BC21)*0.025)+(BD21*0.025),"") | BF21: =IF(SUM(BB21,AT21,AC21,L21,BE21)=0,"",SUM(BB21,AT21,AC21,L21,BE21)) | BG21: =IF(BF21="","",IF(BF21<51,"REPROBADO",IF(BF21>=51,"APROBADO"," ")))
A22: =IF('1erT'!A22<>"",'1erT'!A22,"") -> 8 | B22: =IF('1erT'!B22<>"",'1erT'!B22,"") -> NUMBELA SAAVEDRA RAFAEL | C22: =IF(B22<>"",IFERROR(EVAL.ANUAL!X16,""),"") -> 27 | D22: =IF(B22<>"",IFERROR(EVAL.ANUAL!W16,""),"") -> 0 | K22: =IFERROR((AVERAGE(M22:AB22,AD22:AS22)),"") | L22: =IFERROR((AVERAGE(E22:K22)*0.05),"") | AB22: =IFERROR(AVERAGE(M22:AA22),"") | AC22: =IFERROR((AVERAGE(M22:AA22)*0.4)+(AB22*0.05),"") | AS22: =IFERROR(AVERAGE(AD22:AR22),"") | AT22: =IFERROR((AVERAGE(AD22:AR22)*0.35)+(AS22*0.05),"") | BA22: =K22 | BB22: =IFERROR((AVERAGE(AU22:BA22)*0.05),"") | BE22: =IFERROR((AVERAGE(BC22)*0.025)+(BD22*0.025),"") | BF22: =IF(SUM(BB22,AT22,AC22,L22,BE22)=0,"",SUM(BB22,AT22,AC22,L22,BE22)) | BG22: =IF(BF22="","",IF(BF22<51,"REPROBADO",IF(BF22>=51,"APROBADO"," ")))
A23: =IF('1erT'!A23<>"",'1erT'!A23,"") -> 9 | B23: =IF('1erT'!B23<>"",'1erT'!B23,"") -> PEÑALOZA PRADO RAFAEL ANDRES | C23: =IF(B23<>"",IFERROR(EVAL.ANUAL!X17,""),"") -> 18 | D23: =IF(B23<>"",IFERROR(EVAL.ANUAL!W17,""),"") -> 0 | K23: =IFERROR((AVERAGE(M23:AB23,AD23:AS23)),"") | L23: =IFERROR((AVERAGE(E23:K23)*0.05),"") | AB23: =IFERROR(AVERAGE(M23:AA23),"") | AC23: =IFERROR((AVERAGE(M23:AA23)*0.4)+(AB23*0.05),"") | AS23: =IFERROR(AVERAGE(AD23:AR23),"") | AT23: =IFERROR((AVERAGE(AD23:AR23)*0.35)+(AS23*0.05),"") | BA23: =K23 | BB23: =IFERROR((AVERAGE(AU23:BA23)*0.05),"") | BE23: =IFERROR((AVERAGE(BC23)*0.025)+(BD23*0.025),"") | BF23: =IF(SUM(BB23,AT23,AC23,L23,BE23)=0,"",SUM(BB23,AT23,AC23,L23,BE23)) | BG23: =IF(BF23="","",IF(BF23<51,"REPROBADO",IF(BF23>=51,"APROBADO"," ")))
A24: =IF('1erT'!A24<>"",'1erT'!A24,"") -> 10 | B24: =IF('1erT'!B24<>"",'1erT'!B24,"") -> PARDO LOPEZ ABIGAIL | C24: =IF(B24<>"",IFERROR(EVAL.ANUAL!X18,""),"") -> 11 | D24: =IF(B24<>"",IFERROR(EVAL.ANUAL!W18,""),"") -> 0 | K24: =IFERROR((AVERAGE(M24:AB24,AD24:AS24)),"") | L24: =IFERROR((AVERAGE(E24:K24)*0.05),"") | AB24: =IFERROR(AVERAGE(M24:AA24),"") | AC24: =IFERROR((AVERAGE(M24:AA24)*0.4)+(AB24*0.05),"") | AS24: =IFERROR(AVERAGE(AD24:AR24),"") | AT24: =IFERROR((AVERAGE(AD24:AR24)*0.35)+(AS24*0.05),"") | BA24: =K24 | BB24: =IFERROR((AVERAGE(AU24:BA24)*0.05),"") | BE24: =IFERROR((AVERAGE(BC24)*0.025)+(BD24*0.025),"") | BF24: =IF(SUM(BB24,AT24,AC24,L24,BE24)=0,"",SUM(BB24,AT24,AC24,L24,BE24)) | BG24: =IF(BF24="","",IF(BF24<51,"REPROBADO",IF(BF24>=51,"APROBADO"," ")))
A25: =IF('1erT'!A25<>"",'1erT'!A25,"") -> 11 | B25: =IF('1erT'!B25<>"",'1erT'!B25,"") -> ROCABADO ANDIA MARIANA | C25: =IF(B25<>"",IFERROR(EVAL.ANUAL!X19,""),"") -> 26 | D25: =IF(B25<>"",IFERROR(EVAL.ANUAL!W19,""),"") -> 0 | K25: =IFERROR((AVERAGE(M25:AB25,AD25:AS25)),"") | L25: =IFERROR((AVERAGE(E25:K25)*0.05),"") | AB25: =IFERROR(AVERAGE(M25:AA25),"") | AC25: =IFERROR((AVERAGE(M25:AA25)*0.4)+(AB25*0.05),"") | AS25: =IFERROR(AVERAGE(AD25:AR25),"") | AT25: =IFERROR((AVERAGE(AD25:AR25)*0.35)+(AS25*0.05),"") | BA25: =K25 | BB25: =IFERROR((AVERAGE(AU25:BA25)*0.05),"") | BE25: =IFERROR((AVERAGE(BC25)*0.025)+(BD25*0.025),"") | BF25: =IF(SUM(BB25,AT25,AC25,L25,BE25)=0,"",SUM(BB25,AT25,AC25,L25,BE25)) | BG25: =IF(BF25="","",IF(BF25<51,"REPROBADO",IF(BF25>=51,"APROBADO"," ")))
A26: =IF('1erT'!A26<>"",'1erT'!A26,"") -> 12 | B26: =IF('1erT'!B26<>"",'1erT'!B26,"") -> SEJAS CAMPOS ZULMA | C26: =IF(B26<>"",IFERROR(EVAL.ANUAL!X20,""),"") -> 26 | D26: =IF(B26<>"",IFERROR(EVAL.ANUAL!W20,""),"") -> 0 | K26: =IFERROR((AVERAGE(M26:AB26,AD26:AS26)),"") | L26: =IFERROR((AVERAGE(E26:K26)*0.05),"") | AB26: =IFERROR(AVERAGE(M26:AA26),"") | AC26: =IFERROR((AVERAGE(M26:AA26)*0.4)+(AB26*0.05),"") | AS26: =IFERROR(AVERAGE(AD26:AR26),"") | AT26: =IFERROR((AVERAGE(AD26:AR26)*0.35)+(AS26*0.05),"") | BA26: =K26 | BB26: =IFERROR((AVERAGE(AU26:BA26)*0.05),"") | BE26: =IFERROR((AVERAGE(BC26)*0.025)+(BD26*0.025),"") | BF26: =IF(SUM(BB26,AT26,AC26,L26,BE26)=0,"",SUM(BB26,AT26,AC26,L26,BE26)) | BG26: =IF(BF26="","",IF(BF26<51,"REPROBADO",IF(BF26>=51,"APROBADO"," ")))
... A56: =IF('1erT'!A56<>"",'1erT'!A56,"") | B56: =IF('1erT'!B56<>"",'1erT'!B56,"") | C56: =IF(B56<>"",IFERROR(EVAL.ANUAL!X50,""),"") | D56: =IF(B56<>"",IFERROR(EVAL.ANUAL!W50,""),"") | K56: =IFERROR((AVERAGE(M56:AB56,AD56:AS56)),"") | L56: =IFERROR((AVERAGE(E56:K56)*0.05),"") | AB56: =IFERROR(AVERAGE(M56:AA56),"") | AC56: =IFERROR((AVERAGE(M56:AA56)*0.4)+(AB56*0.05),"") | AS56: =IFERROR(AVERAGE(AD56:AR56),"") | AT56: =IFERROR((AVERAGE(AD56:AR56)*0.35)+(AS56*0.05),"") | BA56: =K56 | BB56: =IFERROR((AVERAGE(AU56:BA56)*0.05),"") | BE56: =IFERROR((AVERAGE(BC56)*0.025)+(BD56*0.025),"") | BF56: =IF(SUM(BB56,AT56,AC56,L56,BE56)=0,"",SUM(BB56,AT56,AC56,L56,BE56)) | BG56: =IF(BF56="","",IF(BF56<51,"REPROBADO",IF(BF56>=51,"APROBADO"," ")))

Sheet EVAL.ANUAL
A2: CENTRALIZADOR DE REGISTROS DE VALORACION PEDAGOGICA TRIMESTRAL
A3: =+'1erT'!A4:BG4 -> CURSO: 2ndo A Secundaria
A4: =+'1erT'!A8:BG8 -> MATERIA : HISTORIA
A5: Nº | B5: Nombre completo | C5: 1er. TRIMESTRE | J5: 2do. TRIMESTRE | Q5: 3er. TRIMESTRE | X5: NOTA FINAL | Y5: EVALUACION CUALITATIVA
C6: MAESTRO | G6: AUTOE.(5) | J6: MAESTRO | N6: AUTOE.(5) | Q6: MAESTRO | U6: AUTOE.(5)
C7: SER (5) | D7: SABER (45) | E7: HACER (40) | F7: DECIDIR (5) | G7: SER ( 2,5 ) | H7: DECIDIR (2,5) | I7: TOTAL | J7: SER (5) | K7: SABER (45) | L7: HACER (40) | M7: DECIDIR (5) | N7: SER ( 2,5 ) | O7: DECIDIR (2,5) | P7: TOTAL | Q7: SER (5) | R7: SABER (45) | S7: HACER (40) | T7: DECIDIR (5) | U7: SER ( 2,5 ) | V7: DECIDIR (2,5) | W7: TOTAL
C8: =IFERROR(AVERAGE(C9:C50),"") -> 3.5836939 | D8: =IFERROR(AVERAGE(D9:D50),"") -> 31.776923 | E8: =IFERROR(AVERAGE(E9:E50),"") -> 28.915385 | F8: =IFERROR(AVERAGE(F9:F50),"") -> 3.5836939 | G8: =IFERROR(AVERAGE(G9:G50),"") -> 0 | H8: =IFERROR(AVERAGE(H9:H50),"") -> 0 | I8: =ROUNDUP(SUM(C8:H8),0) -> 68 | J8: =IFERROR(AVERAGE(J9:J50),"") | K8: =IFERROR(AVERAGE(K9:K50),"") | L8: =IFERROR(AVERAGE(L9:L50),"") | M8: =IFERROR(AVERAGE(M9:M50),"") | N8: =IFERROR(AVERAGE(N9:N50),"") -> 0 | O8: =IFERROR(AVERAGE(O9:O50),"") -> 0 | P8: =ROUNDUP(SUM(J8:O8),0) -> 0 | Q8: =IFERROR(AVERAGE(Q9:Q50),"") | R8: =IFERROR(AVERAGE(R9:R50),"") | S8: =IFERROR(AVERAGE(S9:S50),"") | T8: =IFERROR(AVERAGE(T9:T50),"") | U8: =IFERROR(AVERAGE(U9:U50),"") -> 0 | V8: =IFERROR(AVERAGE(V9:V50),"") -> 0 | W8: =ROUNDUP(SUM(Q8:V8),0) -> 0 | X8: =IF(I8="","",ROUNDUP(AVERAGE(W8,P8,I8),0)) -> 23
A9: =+'1erT'!A15 -> 1 | B9: =+'1erT'!B15 -> AGUILA SEJAS MATIAS HERNAN | C9: =IFERROR('1erT'!L15,"") -> 4.2833333 | D9: =+'1erT'!AC15 -> 29.25 | E9: =+'1erT'!AT15 -> 38.4 | F9: =IFERROR('1erT'!BB15,"") -> 4.2833333 | G9: =+('1erT'!BC15*0.05) -> 0 | H9: =+'1erT'!BD15*0.05 -> 0 | I9: =ROUNDUP(SUM(C9:H9),0) -> 77 | J9: =IFERROR('2doT'!L15,"") | K9: =+'2doT'!AC15 | L9: =+'2doT'!AT15 | M9: =IFERROR('2doT'!BB15,"") | N9: =+(0.05*'2doT'!BC15) -> 0 | O9: =+(0.05*'2doT'!BD15) -> 0 | P9: =ROUNDUP(SUM(J9:O9),0) -> 0 | Q9: =IFERROR('3erT'!L15,"") | R9: =+'3erT'!AC15 | S9: =+'3erT'!AT15 | T9: =IFERROR('3erT'!BB15,"") | U9: =+(0.05*'3erT'!BC15) -> 0 | V9: =+(0.05*'3erT'!BD15) -> 0 | W9: =ROUNDUP(SUM(Q9:V9),0) -> 0 | X9: =IF(I9="","",ROUNDUP(AVERAGE(W9,P9,I9),0)) -> 26 | Y9: =IF(I9="","",IF(X9<51,"REPROBADO",IF(X9>=51,"APROBADO"," "))) -> REPROBADO
A10: =+'1erT'!A16 -> 2 | B10: =+'1erT'!B16 -> ANTEZANA ARANIBAR JAVIER LEANDRO | C10: =IFERROR('1erT'!L16,"") -> 4.7 | D10: =+'1erT'!AC16 -> 37.8 | E10: =+'1erT'!AT16 -> 40 | F10: =IFERROR('1erT'!BB16,"") -> 4.7 | G10: =+('1erT'!BC16*0.05) -> 0 | H10: =+'1erT'!BD16*0.05 -> 0 | I10: =ROUNDUP(SUM(C10:H10),0) -> 88 | J10: =IFERROR('2doT'!L16,"") | K10: =+'2doT'!AC16 | L10: =+'2doT'!AT16 | M10: =IFERROR('2doT'!BB16,"") | N10: =+(0.05*'2doT'!BC16) -> 0 | O10: =+(0.05*'2doT'!BD16) -> 0 | P10: =ROUNDUP(SUM(J10:O10),0) -> 0 | Q10: =IFERROR('3erT'!L16,"") | R10: =+'3erT'!AC16 | S10: =+'3erT'!AT16 | T10: =IFERROR('3erT'!BB16,"") | U10: =+(0.05*'3erT'!BC16) -> 0 | V10: =+(0.05*'3erT'!BD16) -> 0 | W10: =ROUNDUP(SUM(Q10:V10),0) -> 0 | X10: =IF(I10="","",ROUNDUP(AVERAGE(W10,P10,I10),0)) -> 30 | Y10: =IF(I10="","",IF(X10<51,"REPROBADO",IF(X10>=51,"APROBADO"," "))) -> REPROBADO
A11: =+'1erT'!A17 -> 3 | B11: =+'1erT'!B17 -> ANTEZANA TORREZ MATIAS ANDRE | C11: =IFERROR('1erT'!L17,"") -> 4.6 | D11: =+'1erT'!AC17 -> 39.6 | E11: =+'1erT'!AT17 -> 37.6 | F11: =IFERROR('1erT'!BB17,"") -> 4.6 | G11: =+('1erT'!BC17*0.05) -> 0 | H11: =+'1erT'!BD17*0.05 -> 0 | I11: =ROUNDUP(SUM(C11:H11),0) -> 87 | J11: =IFERROR('2doT'!L17,"") | K11: =+'2doT'!AC17 | L11: =+'2doT'!AT17 | M11: =IFERROR('2doT'!BB17,"") | N11: =+(0.05*'2doT'!BC17) -> 0 | O11: =+(0.05*'2doT'!BD17) -> 0 | P11: =ROUNDUP(SUM(J11:O11),0) -> 0 | Q11: =IFERROR('3erT'!L17,"") | R11: =+'3erT'!AC17 | S11: =+'3erT'!AT17 | T11: =IFERROR('3erT'!BB17,"") | U11: =+(0.05*'3erT'!BC17) -> 0 | V11: =+(0.05*'3erT'!BD17) -> 0 | W11: =ROUNDUP(SUM(Q11:V11),0) -> 0 | X11: =IF(I11="","",ROUNDUP(AVERAGE(W11,P11,I11),0)) -> 29 | Y11: =IF(I11="","",IF(X11<51,"REPROBADO",IF(X11>=51,"APROBADO"," "))) -> REPROBADO
A12: =+'1erT'!A18 -> 4 | B12: =+'1erT'!B18 -> CARDOZO FRANCO JOHNNY LEONARDO | C12: =IFERROR('1erT'!L18,"") -> 4.734375 | D12: =+'1erT'!AC18 -> 40.5 | E12: =+'1erT'!AT18 -> 39 | F12: =IFERROR('1erT'!BB18,"") -> 4.734375 | G12: =+('1erT'!BC18*0.05) -> 0 | H12: =+'1erT'!BD18*0.05 -> 0 | I12: =ROUNDUP(SUM(C12:H12),0) -> 89 | J12: =IFERROR('2doT'!L18,"") | K12: =+'2doT'!AC18 | L12: =+'2doT'!AT18 | M12: =IFERROR('2doT'!BB18,"") | N12: =+(0.05*'2doT'!BC18) -> 0 | O12: =+(0.05*'2doT'!BD18) -> 0 | P12: =ROUNDUP(SUM(J12:O12),0) -> 0 | Q12: =IFERROR('3erT'!L18,"") | R12: =+'3erT'!AC18 | S12: =+'3erT'!AT18 | T12: =IFERROR('3erT'!BB18,"") | U12: =+(0.05*'3erT'!BC18) -> 0 | V12: =+(0.05*'3erT'!BD18) -> 0 | W12: =ROUNDUP(SUM(Q12:V12),0) -> 0 | X12: =IF(I12="","",ROUNDUP(AVERAGE(W12,P12,I12),0)) -> 30 | Y12: =IF(I12="","",IF(X12<51,"REPROBADO",IF(X12>=51,"APROBADO"," "))) -> REPROBADO
A13: =+'1erT'!A19 -> 5 | B13: =+'1erT'!B19 -> ESPINOZA MUÑOZ RUBEN SEBASTIAN | C13: =IFERROR('1erT'!L19,"") -> 1.4171875 | D13: =+'1erT'!AC19 -> 16.2 | E13: =+'1erT'!AT19 -> 9.5 | F13: =IFERROR('1erT'!BB19,"") -> 1.4171875 | G13: =+('1erT'!BC19*0.05) -> 0 | H13: =+'1erT'!BD19*0.05 -> 0 | I13: =ROUNDUP(SUM(C13:H13),0) -> 29 | J13: =IFERROR('2doT'!L19,"") | K13: =+'2doT'!AC19 | L13: =+'2doT'!AT19 | M13: =IFERROR('2doT'!BB19,"") | N13: =+(0.05*'2doT'!BC19) -> 0 | O13: =+(0.05*'2doT'!BD19) -> 0 | P13: =ROUNDUP(SUM(J13:O13),0) -> 0 | Q13: =IFERROR('3erT'!L19,"") | R13: =+'3erT'!AC19 | S13: =+'3erT'!AT19 | T13: =IFERROR('3erT'!BB19,"") | U13: =+(0.05*'3erT'!BC19) -> 0 | V13: =+(0.05*'3erT'!BD19) -> 0 | W13: =ROUNDUP(SUM(Q13:V13),0) -> 0 | X13: =IF(I13="","",ROUNDUP(AVERAGE(W13,P13,I13),0)) -> 10 | Y13: =IF(I13="","",IF(X13<51,"REPROBADO",IF(X13>=51,"APROBADO"," "))) -> REPROBADO
A14: =+'1erT'!A20 -> 6 | B14: =+'1erT'!B20 -> HUANCA AMURRIO VALENTINA RAFAELA | C14: =IFERROR('1erT'!L20,"") -> 3.634375 | D14: =+'1erT'!AC20 -> 21.6 | E14: =+'1erT'!AT20 -> 35 | F14: =IFERROR('1erT'!BB20,"") -> 3.634375 | G14: =+('1erT'!BC20*0.05) -> 0 | H14: =+'1erT'!BD20*0.05 -> 0 | I14: =ROUNDUP(SUM(C14:H14),0) -> 64 | J14: =IFERROR('2doT'!L20,"") | K14: =+'2doT'!AC20 | L14: =+'2doT'!AT20 | M14: =IFERROR('2doT'!BB20,"") | N14: =+(0.05*'2doT'!BC20) -> 0 | O14: =+(0.05*'2doT'!BD20) -> 0 | P14: =ROUNDUP(SUM(J14:O14),0) -> 0 | Q14: =IFERROR('3erT'!L20,"") | R14: =+'3erT'!AC20 | S14: =+'3erT'!AT20 | T14: =IFERROR('3erT'!BB20,"") | U14: =+(0.05*'3erT'!BC20) -> 0 | V14: =+(0.05*'3erT'!BD20) -> 0 | W14: =ROUNDUP(SUM(Q14:V14),0) -> 0 | X14: =IF(I14="","",ROUNDUP(AVERAGE(W14,P14,I14),0)) -> 22 | Y14: =IF(I14="","",IF(X14<51,"REPROBADO",IF(X14>=51,"APROBADO"," "))) -> REPROBADO
