Workbook

Sheet proforma
A5: FACTURA PROFORMA | M5: No. : | N5: RAC-105/2014
A6: OBRA : | C6: Edificio LUSSO | L6: Fecha : | M6: 41957
A7: CLIENTE : | C7: Sr. Henry Maldonado | L7: Teléfono:
A8: Item | B8: Cant. | C8: Medidas | F8: Superficie | H8: Tipo de | I8: Material | M8: P R E C I O $us
C9: Ancho | D9: x | E9: Alto | F9: Cant. | G9: Unid. | H9: Cerramiento | M9: x Mt² | N9: T O T A L
A10: 1 | B10: 1 | F10: 269.98 | G10: Mt² | H10: Puerta / Ventanas Corredizas | I10: PUERTA/VENTANAS CORREDIZAS DE 4 HOJAS: Montadas sobre carpintería de aluminio natural con vidrio Templado de Seguridad Incoloro de 10mm de espesor en puerta/ventanas corredizas de 4 hojas, accesorios y mano de obra altamente calificada. | M10: =+N10/F10 -> 70.597674 | N10: 19059.96
A11: 2 | B11: 1 | F11: 55.92 | G11: Mt² | H11: Ventanas Corredizas | I11: VENTANAS CORREDIZAS DE 2 HOJAS: Montadas sobre carpintería de aluminio natural con vidrio Templado de Seguridad Incoloro de 8mm de espesor en ventanas corredizas de 2 hojas, accesorios y mano de obra altamente calificada. | M11: =+N11/F11 -> 89.521638 | N11: 5006.05
A12: 3 | B12: 1 | F12: 18.52 | G12: Mt² | H12: Ventanas Corredizas | I12: PANOS FIJOS 10 MM: Montados sobre carpintería de aluminio natural con vidrio Templado de Seguridad Incoloro de 10mm de espesor en panos fijos, accesorios y mano de obra altamente calificada. | M12: =+N12/F12 -> 51.467063 | N12: 953.17
A13: 4 | B13: 1 | F13: 67.98 | G13: Mt² | H13: Fachada tipo piel de vidrio | I13: PANOS FIJOS 8 MM: Montados sobre carpintería de aluminio natural con vidrio Templado de Seguridad Incoloro de 8mm de espesor en panos fijos, accesorios y mano de obra altamente calificada. | M13: =+N13/F13 -> 53.781259 | N13: 3656.05
A14: 5 | B14: 1 | F14: 16.97 | G14: Mt² | H14: Fachada tipo celosia | I14: PUERTAS BATIENTES DOBLES : Montadas sobre carpintería de aluminio natural con vidrio Templado de Seguridad Incoloro de 10mm de espesor en puertabatientes dobles, accesorios y mano de obra altamente calificada. | M14: =+N14/F14 -> 85.923984 | N14: 1458.13
A17: TOTAL | F17: =SUM(F10:F16) -> 429.37 | G17: Mt² | H17: PRECIO CON IMPUESTOS DE LEY | L17: $us | M17: =+N17/F17 -> 70.180404 | N17: =SUM(N10:N16) -> 30133.36
A18: Forma de pago: | E18: 80% a la firma del contrato, | J18: Son : Treinta Mil Ciento Treinta y Tres 36/100 DOLARES AMERICANOS
E19: 20% a la entrega de la obra
A21: Plazo de Entrega: | E21: 30 días calendario
E22: Plazo computable a partir de la
E23: entrega de vanos terminados. | J23: Ing. Rafael Antequera Caballero
A24: Validez de la oferta: | E24: 30 días | J24: GERENTE

Sheet Costo M.P.yMat.
C1: ANALISIS DE COSTOS Y DETERMINACION DE PRECIOS DE VENTA (/i1,1/,84)
A3: CODIGO | B3: CODIGO | C3: PRODUCTO | D3: cod | E3: Unidad | F3: Precio de | G3: Precio de | H3: Costo oper. | J3: Proveedor
B4: ORIGEN | F4: venta CF | G4: venta SF | H4: CF | I4: SF
F5: $us/unid. | G5: $us/unid. | H5: $us/unid. | I5: $us/unid.
C6: MATERIALES COMUNES PARA EL VIDRIO TEMPLADO Y LA CARPINTERIA DE ALUMINIO
A7: M1 | C7: Silicona transparente, blanca o negra | D7: 1 | E7: Tubo | F7: =ROUNDUP(H7*0.87*1.1/0.84,2) -> 3.31 | G7: =ROUNDUP(I7*1.1,2) -> 3.19 | H7: 2.9 | I7: 2.9 | J7: MAROL 20 Bs. | K7: =(-G7+F7)/F7 -> 0.036253776
A8: M2 | C8: Silicona estructural | D8: 2 | E8: Tubo | F8: =ROUNDUP(H8*0.87*1.1/0.84,2) -> 7.11 | G8: =ROUNDUP(I8*1.1,2) -> 6.59 | H8: 6.24 | I8: =+H8*0.96 -> 5.9904 | J8: MAROL 20 Bs. | K8: =(-G8+F8)/F8 -> 0.073136428
A9: M3 | C9: Cinta masking 1/2 " (rollo de 20) | D9: 3 | E9: Rollo | F9: =ROUNDUP(H9*0.87*1.1/0.84,2) -> 0.75 | G9: =ROUNDUP(I9*1.1,2) -> 0.72 | H9: 0.65 | I9: 0.65 | J9: Ribepar | K9: =(-G9+F9)/F9 -> 0.04
A10: M4 | C10: "U" 15 x 15 ( 16x16 ) - 0,159 Kg/Mt. | D10: 4 | E10: Mt lineal | F10: =ROUNDUP(H10*0.87*1.1/0.84,2) -> 0.9 | G10: =ROUNDUP(I10*1.1,2) -> 0.87 | H10: =+N10/6 -> 0.78583333 | I10: =+H10 -> 0.78583333 | J10: Alvicruz 4,1 + 15% | K10: =(-G10+F10)/F10 -> 0.033333333 | L10: =6*0.159 -> 0.954 | M10: Kgr./barra | N10: =4.1*1.15 -> 4.715 | O10: $us./barra | P10: 4 puesto S.C.
A11: M5 | C11: "U" 15 x 25 - 0,20 Kg/Mt. | D11: 5 | E11: Mt lineal | F11: =ROUNDUP(H11*0.87*1.1/0.84,2) -> 1.29 | G11: =ROUNDUP(I11*1.1,2) -> 1.25 | H11: =+N11/6 -> 1.1308333 | I11: =+H11 -> 1.1308333 | J11: Alvicruz 5,9 + 15% | K11: =(-G11+F11)/F11 -> 0.031007752 | L11: =6*0.2 -> 1.2 | M11: Kgr./barra | N11: =5.9*1.15 -> 6.785 | O11: $us./barra | P11: 5,8 puesto S.C.
A12: M6 | C12: Tubo 50 x 50 - 1,037 Kg/Mt. | D12: 6 | E12: Mt lineal | F12: =ROUNDUP(H12*0.87*1.1/0.84,2) -> 9.15 | G12: =ROUNDUP(I12*1.1,2) -> 8.48 | H12: =+N12/6 -> 8.0258615 | I12: =0.96*H12 -> 7.704827 | J12: Alcoa 6,73 + 15% | K12: =(-G12+F12)/F12 -> 0.073224044 | L12: =6*1.037 -> 6.222 | M12: Kgr./barra | N12: =6.73*1.15*L12 -> 48.155169 | O12: $us./barra
A13: M7 | C13: Tubo 40 x 40 - 0,624 Kg/Mt. | D13: 7 | E13: Mt lineal | F13: =ROUNDUP(H13*0.87*1.1/0.84,2) -> 5.51 | G13: =ROUNDUP(I13*1.1,2) -> 5.1 | H13: =+N13/6 -> 4.829448 | I13: =0.96*H13 -> 4.6362701 | J13: Alcoa 6,73 + 15% | K13: =(-G13+F13)/F13 -> 0.074410163 | L13: =6*0.624 -> 3.744 | M13: Kgr./barra | N13: =6.73*1.15*L13 -> 28.976688 | O13: $us./barra
A14: M8 | C14: Tubo 80 x 40 - 0,948 Kg/Mt. | D14: 8 | E14: Mt lineal | F14: =ROUNDUP(H14*0.87*1.1/0.84,2) -> 5.97 | G14: =ROUNDUP(I14*1.1,2) -> 5.76 | H14: =+N14/6 -> 5.2325 | I14: =+H14 -> 5.2325 | J14: Alvicruz 27,30 + 15% | K14: =(-G14+F14)/F14 -> 0.035175879 | L14: =6*0.948 -> 5.688 | M14: Kgr./barra | N14: =27.3*1.15 -> 31.395 | O14: $us./barra | P14: 26,80 puesto S.C.
A15: M9 | C15: Tubo 60 x 30 - 0,705 Kg/Mt. | D15: 9 | E15: Mt lineal | F15: =ROUNDUP(H15*0.87*1.1/0.84,2) -> 4.02 | G15: =ROUNDUP(I15*1.1,2) -> 3.88 | H15: =+N15/6 -> 3.5266667 | I15: =+H15 -> 3.5266667 | J15: Alvicruz 18,4 + 15% | K15: =(-G15+F15)/F15 -> 0.034825871 | L15: =6*0.705 -> 4.23 | M15: Kgr./barra | N15: =18.4*1.15 -> 21.16 | O15: $us./barra | P15: 18 puesto S.C.
A16: M10 | C16: Tubo 100 x 50 - 1,560 Kg/Mt. | D16: 10 | E16: Mt lineal | F16: =ROUNDUP(H16*0.87*1.1/0.84,2) -> 8.3 | G16: =ROUNDUP(I16*1.1,2) -> 8.02 | H16: =+N16/6 -> 7.2833333 | I16: =+H16 -> 7.2833333 | J16: Alvicruz 38 + 15% | K16: =(-G16+F16)/F16 -> 0.03373494 | L16: =6*0.786 -> 4.716 | M16: Kgr./barra | N16: =38*1.15 -> 43.7 | O16: $us./barra | P16: 37,50 puesto S.C.
A17: M11 | C17: Felpa | D17: 11 | E17: Mt lineal | F17: =ROUNDUP(H17*0.87*1.1/0.84,2) -> 0.18 | G17: =ROUNDUP(I17*1.1,2) -> 0.17 | H17: 0.15 | I17: 0.15 | J17: Indalum | K17: =(-G17+F17)/F17 -> 0.055555556
A18: M12 | C18: Remache 4 x 10 | D18: 12 | E18: Pza. | F18: =ROUNDUP(H18*0.87*1.1/0.84,2) -> 0.04 | G18: =ROUNDUP(I18*1.1,2) -> 0.04 | H18: 0.03 | I18: 0.03 | J18: Perbol | K18: =(-G18+F18)/F18 -> 0
A19: M13 | C19: Tarugos No. 6 | D19: 13 | E19: Pza. | F19: =ROUNDUP(H19*0.87*1.1/0.84,2) -> 0.04 | G19: =ROUNDUP(I19*1.1,2) -> 0.04 | H19: 0.03 | I19: 0.03 | J19: Perbol | K19: =(-G19+F19)/F19 -> 0
A20: M14 | C20: Tornillos 8 x 1 1/2 | D20: 14 | E20: Pza. | F20: =ROUNDUP(H20*0.87*1.1/0.84,2) -> 0.04 | G20: =ROUNDUP(I20*1.1,2) -> 0.04 | H20: 0.03 | I20: 0.03 | J20: Perbol | K20: =(-G20+F20)/F20 -> 0
A21: M15 | C21: Tornillos 8 x 1/2 | D21: 15 | E21: Pza. | F21: =ROUNDUP(H21*0.87*1.1/0.84,2) -> 0.03 | G21: =ROUNDUP(I21*1.1,2) -> 0.03 | H21: 0.02 | I21: 0.02 | J21: Perbol | K21: =(-G21+F21)/F21 -> 0
A22: M16 | C22: Tubo Galvanizado de 4" | D22: 16 | E22: Mt lineal | F22: =ROUNDUP(H22*0.87*1.1/0.84,2) -> 29.91 | G22: =ROUNDUP(I22*1.1,2) -> 27.72 | H22: =150*1.05/6 -> 26.25 | I22: =+H22*0.96 -> 25.2 | J22: Las Lomas ( 150+5%uniones) | K22: =(-G22+F22)/F22 -> 0.073219659
C23: PARA EL VIDRIO TEMPLADO | N23: COCHABAMBA | P23: SANTA PUEJ
A24: V1 | C24: Vidrio Templado 10mm Incoloro | D24: 17 | E24: Mt² | F24: =ROUNDUP(H24*0.87*1.1/0.84,2) -> 35.89 | G24: =ROUNDUP(I24*1.1,2) -> 34.65 | H24: =30*1.05 -> 31.5 | I24: =30*1.05 -> 31.5 | J24: MURANO 26 + 5%desp. | K24: =(-G24+F24)/F24 -> 0.034550014 | M24: =ROUNDUP(N24/6.97,2) -> 25.83 | N24: 180 | O24: 175+4caloi | P24: =+Q24*6.97 -> 209.1 | Q24: 30
A25: V2 | C25: Vidrio Templado 8mm Incoloro | D25: 18 | E25: Mt² | F25: =ROUNDUP(H25*0.87*1.1/0.84,2) -> 34.7 | G25: =ROUNDUP(I25*1.1,2) -> 33.5 | H25: =29*1.05 -> 30.45 | I25: =29*1.05 -> 30.45 | J25: MURANO 25 + 5% desp | K25: =(-G25+F25)/F25 -> 0.034582133 | M25: =ROUNDUP(N25/6.97,2) -> 25.11 | N25: 175 | O25: 170+4caloi | P25: =+Q25*6.97 -> 202.13 | Q25: 29
A26: V3 | C26: Vidrio Templado 6mm Incoloro | D26: 19 | E26: Mt² | F26: =ROUNDUP(H26*0.87*1.1/0.84,2) -> 29.63 | G26: =ROUNDUP(I26*1.1,2) -> 27.5 | H26: 26 | I26: 25 | J26: Revibol | K26: =(-G26+F26)/F26 -> 0.071886601
A27: V4 | C27: Vidrio Templado 5mm Incoloro | D27: 20 | E27: Mt² | F27: =ROUNDUP(H27*0.87*1.1/0.84,2) -> 27.35 | G27: =ROUNDUP(I27*1.1,2) -> 26.4 | H27: 24 | I27: 24 | J27: Revibol | K27: =(-G27+F27)/F27 -> 0.034734918
A28: V5 | C28: Vidrio Templado 4mm Incoloro | D28: 21 | E28: Mt² | F28: =ROUNDUP(H28*0.87*1.1/0.84,2) -> 23.93 | G28: =ROUNDUP(I28*1.1,2) -> 23.1 | H28: 21 | I28: 21 | J28: Revibol | K28: =(-G28+F28)/F28 -> 0.034684496
A29: V6 | C29: Vidrio Templado 10mm Color | D29: 22 | E29: Mt² | F29: =ROUNDUP(H29*0.87*1.1/0.84,2) -> 46.66 | G29: =ROUNDUP(I29*1.1,2) -> 45.05 | H29: =39*1.05 -> 40.95 | I29: =39*1.05 -> 40.95 | J29: MURANO 39 + 5% desp. | K29: =(-G29+F29)/F29 -> 0.034504929 | M29: =+N29/6.96 -> 38.793103 | N29: 270
A30: V7 | C30: Vidrio Templado 8mm Color | D30: 23 | E30: Mt² | F30: =ROUNDUP(H30*0.87*1.1/0.84,2) -> 45.46 | G30: =ROUNDUP(I30*1.1,2) -> 43.89 | H30: =38*1.05 -> 39.9 | I30: =38*1.05 -> 39.9 | J30: MURANO 38 + 5% desp. | K30: =(-G30+F30)/F30 -> 0.034535856 | M30: =+N30/6.96 -> 37.356322 | N30: 260
A31: V8 | C31: Vidrio Templado 6mm Color | D31: 24 | E31: Mt² | F31: =ROUNDUP(H31*0.87*1.1/0.84,2) -> 47.85 | G31: =ROUNDUP(I31*1.1,2) -> 44 | H31: 42 | I31: 40 | J31: Revibol | K31: =(-G31+F31)/F31 -> 0.08045977
A32: V9 | C32: Vidrio Templado 5mm Color | D32: 25 | E32: Mt² | F32: =ROUNDUP(H32*0.87*1.1/0.84,2) -> 45.58 | G32: =ROUNDUP(I32*1.1,2) -> 41.8 | H32: 40 | I32: 38 | J32: Revibol | K32: =(-G32+F32)/F32 -> 0.08293111
A33: V10 | C33: Vidrio Templado 4mm Color | D33: 26 | E33: Mt² | F33: =ROUNDUP(H33*0.87*1.1/0.84,2) -> 43.3 | G33: =ROUNDUP(I33*1.1,2) -> 39.6 | H33: 38 | I33: 36 | J33: Revibol | K33: =(-G33+F33)/F33 -> 0.085450346
A34: V11 | C34: Vidrio Templado Catedral 10mm Incoloro | D34: 27 | E34: Mt² | F34: =ROUNDUP(H34*0.87*1.1/0.84,2) -> 50.13 | G34: =ROUNDUP(I34*1.1,2) -> 48.4 | H34: 44 | I34: 44 | J34: Revibol | K34: =(-G34+F34)/F34 -> 0.034510273
A35: V12 | C35: Vidrio Templado Catedral 10mm Color | D35: 28 | E35: Mt² | F35: =ROUNDUP(H35*0.87*1.1/0.84,2) -> 52.41 | G35: =ROUNDUP(I35*1.1,2) -> 50.6 | H35: 46 | I35: 46 | J35: Revibol | K35: =(-G35+F35)/F35 -> 0.034535394 | P35: nuevos
A36: V13 | C36: Cabezal, Tapa, Guia, Tapa-guia 1.998 Kg/Mt | D36: 29 | E36: Juego | F36: =ROUNDUP(H36*0.87*1.1/0.84,2) -> 10.8 | G36: =ROUNDUP(I36*1.1,2) -> 10.43 | H36: =+N36/6 -> 9.4779167 | I36: =+H36 -> 9.4779167 | J36: Alvicruz 49,45+ 15%desp. | K36: =(-G36+F36)/F36 -> 0.034259259 | L36: =6*1.998 -> 11.988 | M36: Kgr./juego | N36: =49.45*1.15 -> 56.8675 | O36: $us./barra | P36: 47,45 puesto S.C.
A37: V14 | C37: Vedapres 001 - h de aluminio | D37: 30 | E37: Barra | F37: =ROUNDUP(H37*0.87*1.1/0.84,2) -> 9.83 | G37: =ROUNDUP(I37*1.1,2) -> 9.49 | H37: =+N37 -> 8.625 | I37: =+H37 -> 8.625 | J37: Alvicruz 7,25+ 15%desp. | K37: =(-G37+F37)/F37 -> 0.034587996 | L37: =6*0.257 -> 1.542 | M37: Kgr./barra | N37: =7.5*1.15 -> 8.625 | O37: $us./barra | P37: 7,15 puesto S.C.
A38: V15 | C38: Vedapres 002 - u de aluminio | D38: 31 | E38: Barra | F38: =ROUNDUP(H38*0.87*1.1/0.84,2) -> 5.9 | G38: =ROUNDUP(I38*1.1,2) -> 5.7 | H38: =+N38 -> 5.175 | I38: =+H38 -> 5.175 | J38: Alvicruz 4,30+ 15%desp. | K38: =(-G38+F38)/F38 -> 0.033898305 | L38: =6*0.151 -> 0.906 | M38: Kgr./barra | N38: =4.5*1.15 -> 5.175 | O38: $us./barra | P38: 4,20 puesto S.C.
A39: V16 | C39: Vedapres 003 - H (2,10mt/barra) Inc. | D39: 32 | E39: Barra | F39: =ROUNDUP(H39*0.87*1.1/0.84,2) -> 5.99 | G39: =ROUNDUP(I39*1.1,2) -> 5.5 | H39: =+I39*1.05 -> 5.25 | I39: 5 | J39: Florencio Rivero | K39: =(-G39+F39)/F39 -> 0.081803005
A40: V17 | C40: Vedapres 001 - h (2,10mt/barra) Bce. | D40: 33 | E40: Barra | F40: =ROUNDUP(H40*0.87*1.1/0.84,2) -> 5.99 | G40: =ROUNDUP(I40*1.1,2) -> 5.5 | H40: =+I40*1.05 -> 5.25 | I40: 5 | J40: Florencio Rivero | K40: =(-G40+F40)/F40 -> 0.081803005
A41: V18 | C41: Vedapres 002 - Uc (2,10mt/barra) Bce. | D41: 34 | E41: Barra | F41: =ROUNDUP(H41*0.87*1.1/0.84,2) -> 5.99 | G41: =ROUNDUP(I41*1.1,2) -> 5.5 | H41: =+I41*1.05 -> 5.25 | I41: 5 | J41: Florencio Rivero | K41: =(-G41+F41)/F41 -> 0.081803005
...

Sheet Fachada tub.herr.
A2: FACHADA EN VIDRIO TEMPLADO | D2: PF | F2: Total | H2: PF | I2: PF
A3: HERRAJES Y VIENTOS VIDRIO o TUBULAR 4" CON ARANA | D3: =IF(D11=8,"8 mm.","10 mm.") -> 8 mm. | H3: =IF(H11=8,"8 mm.","10 mm.") -> 10 mm. | I3: =IF(I11=8,"8 mm.","10 mm.") -> 10 mm.
A4: DATOS BASE PARA EL ANALISIS | D4: =IF(D10=1,"INCOLORO","COLOR") -> INCOLORO | H4: =IF(H10=1,"INCOLORO","COLOR") -> INCOLORO | I4: =IF(I10=1,"INCOLORO","COLOR") -> INCOLORO
A5: BASE ( Metros ) | D5: 5 | H5: 6 | I5: 6
A6: ALTURA ( Metros ) | D6: 6 | H6: 6 | I6: 6
A7: CANTIDAD DE PIEZAS | D7: 3 | F7: =SUM(H7:IU7) -> 2 | G7: Pzas. | H7: 1 | I7: 1
A8: n = div. Verticales | D8: 5 | H8: 5 | I8: 5
A9: m = div. Horizontales | D9: 6 | H9: 3 | I9: 3
A10: INCOLORO = 1 ; COLOR =2 | D10: 1 | H10: 1 | I10: 1
A11: ESPESOR DEL VIDRIO = 8 ó 10 mm. | D11: 8 | H11: 10 | I11: 10
A12: ESMERILADO = E
A13: VIENTOS VIDRIO ( 1 ) o TUBULAR + ARANA ( 2 ) | D13: 2 | H13: 1 | I13: 2
A14: MODULOS
A15: ANCHO ( metros ) | D15: =+D5/D8 -> 1 | H15: =+H5/H8 -> 1.2 | I15: =+I5/I8 -> 1.2
A16: ALTO ( metros ) | D16: =+D6/D9 -> 1 | H16: =+H6/H9 -> 2 | I16: =+I6/I9 -> 2
A17: Total Precio c/factura | C17: pn | D17: =+D51 -> 13860.894 | F17: =SUM(H17:IU17) -> 6745.438 | G17: $us. | H17: =+H51 -> 2832.455 | I17: =+I51 -> 3912.983
A18: Superficie Mt² | D18: =+D5*D6*D$7+IF(D13=1,D7*D6*(D8-1)*0.2,0) -> 90 | F18: =SUM(H18:IU18) -> 76.8 | G18: Mt² | H18: =+H5*H6*H$7+IF(H13=1,H7*H6*(H8-1)*0.2,0) -> 40.8 | I18: =+I5*I6*I$7+IF(I13=1,I7*I6*(I8-1)*0.2,0) -> 36
A19: Precio con factura en $us / Mt² | D19: =+D17/D18 -> 154.00993 | F19: =+F17/F18 -> 87.831224 | G19: $us./Mt² | H19: =+H17/H18 -> 69.422917 | I19: =+I17/I18 -> 108.69397
A20: Total Precio s/factura | D20: =+D72 -> 13360.197 | F20: =SUM(H20:IU20) -> 6500.558 | G20: $us. | H20: =+H72 -> 2739.399 | I20: =+I72 -> 3761.159
A21: Precio sin factura en $us / Mt² | D21: =+D20/D18 -> 148.44663 | F21: =+F20/F18 -> 84.642682 | G21: $us./Mt² | H21: =+H20/H18 -> 67.142132 | I21: =+I20/I18 -> 104.47664
A22: Materia Prima ( Vidrio ) | D22: =0.9*SUM(D52:D55) -> 2838.807 | F22: =SUM(H22:IU22) -> 2500.0974 | G22: $us. | H22: =0.9*SUM(H52:H55) -> 1327.5711 | I22: =0.9*SUM(I52:I55) -> 1172.5263
A23: Materia Prima ( materiales ) | D23: =0.9*SUM(D57:D69) -> 7789.1976 | F23: =SUM(H23:IU23) -> 1994.8608 | G23: $us. | H23: =0.9*SUM(H57:H69) -> 384.4224 | I23: =0.9*SUM(I57:I69) -> 1610.4384
A24: Mano de obra | D24: =0.9*D56 -> 1846.8 | F24: =SUM(H24:IU24) -> 1575.936 | G24: $us. | H24: =0.9*H56 -> 837.216 | I24: =0.9*I56 -> 738.72
A25: Otros Gastos + Util | D25: =+D17-D24-D23-D22 -> 1386.0894 | F25: =SUM(H25:IU25) -> 674.5438 | G25: $us. | H25: =+H17-H24-H23-H22 -> 283.2455 | I25: =+I17-I24-I23-I22 -> 391.2983
A26: TOTAL | D26: =SUM(D22:D25) -> 13860.894 | F26: =SUM(H26:IU26) -> 6745.438 | G26: $us. | H26: =SUM(H22:H25) -> 2832.455 | I26: =SUM(I22:I25) -> 3912.983
A27: % descuento del con al sin | D27: =+(D17-D20)/D17 -> 0.036122995 | F27: =+(F17-F20)/F17 -> 0.036303054 | H27: =+(H17-H20)/H17 -> 0.032853479 | I27: =+(I17-I20)/I17 -> 0.038800066
A29: DETALLE DE MATERIALES A UTILIZAR
A30: MATERIAL | C30: Unidad | D30: =+D2 -> PF | F30: Cantidad | G30: Unidad | H30: =+H2 -> PF | I30: =+I2 -> PF
A31: Vidrio Templado 10mm Incoloro | C31: Mt² | D31: =IF(D$10=1,IF(D$11=10,((D$6*0.05)+(D$5*D$6))*D$7+IF(D13=1,D$7*D6*(D8-1)*0.2,0),0),0) -> 0 | E31: 17 | F31: =ROUNDUP(SUM(H31:IU31),1) -> 77.4 | G31: Mt² | H31: =IF(H$10=1,IF(H$11=10,((H$6*0.05)+(H$5*H$6))*H$7+IF(H13=1,H$7*H6*(H8-1)*0.2,0),0),0) -> 41.1 | I31: =IF(I$10=1,IF(I$11=10,((I$6*0.05)+(I$5*I$6))*I$7+IF(I13=1,I$7*I6*(I8-1)*0.2,0),0),0) -> 36.3
A32: Vidrio Templado 10mm Color | C32: Mt² | D32: =IF(D$10=2,IF(D$11=10,((D$6*0.05)+(D$5*D$6))*D$7+IF(D13=1,D7*D6*(D8-1)*0.2,0),0),0) -> 0 | E32: 22 | F32: =ROUNDUP(SUM(H32:IU32),1) -> 0 | G32: Mt² | H32: =IF(H$10=2,IF(H$11=10,((H$6*0.05)+(H$5*H$6))*H$7+IF(H13=1,H7*H6*(H8-1)*0.2,0),0),0) -> 0 | I32: =IF(I$10=2,IF(I$11=10,((I$6*0.05)+(I$5*I$6))*I$7+IF(I13=1,I7*I6*(I8-1)*0.2,0),0),0) -> 0
A33: Vidrio Templado 8mm Incoloro | C33: Mt² | D33: =IF(D$10=1,IF(D$11=8,((D$6*0.05)+(D$5*D$6))*D$7+IF(D13=1,D7*D6*(D8-1)*0.2,0),0),0) -> 90.9 | E33: 18 | F33: =ROUNDUP(SUM(H33:IU33),1) -> 0 | G33: Mt² | H33: =IF(H$10=1,IF(H$11=8,((H$6*0.05)+(H$5*H$6))*H$7+IF(H13=1,H7*H6*(H8-1)*0.2,0),0),0) -> 0 | I33: =IF(I$10=1,IF(I$11=8,((I$6*0.05)+(I$5*I$6))*I$7+IF(I13=1,I7*I6*(I8-1)*0.2,0),0),0) -> 0
A34: Vidrio Templado 8mm Color | C34: Mt² | D34: =IF(D$10=2,IF(D$11=8,((D$5*D$6))*D$7+IF(D13=1,D7*D6*(D8-1)*0.2,0),0),0) -> 0 | E34: 23 | F34: =ROUNDUP(SUM(H34:IU34),1) -> 0 | G34: Mt² | H34: =IF(H$10=2,IF(H$11=8,((H$5*H$6))*H$7+IF(H13=1,H7*H6*(H8-1)*0.2,0),0),0) -> 0 | I34: =IF(I$10=2,IF(I$11=8,((I$5*I$6))*I$7+IF(I13=1,I7*I6*(I8-1)*0.2,0),0),0) -> 0
A35: Mano de obra | C35: Mt² | D35: =+D18 -> 90 | E35: 75 | F35: =ROUNDUP(SUM(H35:IU35),1) -> 76.8 | G35: Mt² | H35: =+H18 -> 40.8 | I35: =+I18 -> 36
A36: Silicona transparente, blanca o negra | C36: Tubo | D36: =D7*(4*D5+4*D6+(D8-1)*D6+(D9-1)*D5)/6 -> 46.5 | E36: 1 | F36: =ROUNDUP(SUM(H36:IU36),1) -> 28 | G36: Tubo | H36: =H7*(4*H5+4*H6+(H8-1)*H6+(H9-1)*H5)/6 -> 14 | I36: =I7*(4*I5+4*I6+(I8-1)*I6+(I9-1)*I5)/6 -> 14
A37: Cinta masking 1/2 " (rollo de 20) | C37: Rollo | D37: =+D36*12/20 -> 27.9 | E37: 3 | F37: =ROUNDUP(SUM(H37:IU37),1) -> 16.8 | G37: Rollo | H37: =+H7*H36*12/20 -> 8.4 | I37: =+I7*I36*12/20 -> 8.4
A38: "U" 15x25 - Kg/Mt lineal. | B38: 0.2 | C38: Kgr | D38: =(2*D$6+2*D5)*$B38*D$7 -> 13.2 | E38: 5 | F38: =ROUNDUP(SUM(H38:IU38)/(6*B38),1) -> 8 | G38: BARRAS | H38: =(2*H$6+2*H5)*$B38*H$7 -> 4.8 | I38: =(2*I$6+2*I5)*$B38*I$7 -> 4.8
A39: Esmerilado | C39: Mt² | D39: =IF((D12="e"),D18*D7,IF( (D12="E"),D18*D7,0)) -> 0 | E39: 186 | F39: =ROUNDUP(SUM(H39:IU39),1) -> 0 | G39: Mt² | H39: =IF((H12="e"),H18*H7,IF( (H12="E"),H18*H7,0)) -> 0 | I39: =IF((I12="e"),I18*I7,IF( (I12="E"),I18*I7,0)) -> 0
A40: Tarugos No. 6 | C40: Pza. | D40: =D$7*(2*D$5+2*D$6)/0.4 -> 165 | E40: 13 | F40: =ROUNDUP(SUM(H40:IU40),1) -> 120 | G40: Pza. | H40: =H$7*(2*H$5+2*H$6)/0.4 -> 60 | I40: =I$7*(2*I$5+2*I$6)/0.4 -> 60
A41: Tornillos 8 x 1 1/2 | C41: Pza. | D41: =D$7*(2*D$5+2*D$6)/0.4 -> 165 | E41: 14 | F41: =ROUNDUP(SUM(H41:IU41),1) -> 120 | G41: Pza. | H41: =H$7*(2*H$5+2*H$6)/0.4 -> 60 | I41: =I$7*(2*I$5+2*I$6)/0.4 -> 60
A42: Tubo galvanizado de 4" | C42: Mt.lin. | D42: =IF(D13=2,D7*(D8-1)*D6,0) -> 72 | E42: 16 | F42: =ROUNDUP(SUM(H42:IU42),1) -> 24 | G42: Mt.lin. | H42: =IF(H13=2,H7*(H8-1)*H6,0) -> 0 | I42: =IF(I13=2,I7*(I8-1)*I6,0) -> 24
...

Sheet Pano Fijo
D1: =ROUNDUP(D5/1.5,0) -> 6 | F1: =+F12+#REF! -> #REF!
A2: PANO FIJO | D2: PF | F2: Total | H2: piso1 | I2: piso1 | J2: piso1 | K2: piso1
A3: 8 o 10 mm. c/PERFIL U 15x15 DE ALUMINIO | D3: =IF(D10=8,"8 mm.","10 mm.") -> 10 mm. | H3: =IF(H10=8,"8 mm.","10 mm.") -> 10 mm. | I3: =IF(I10=8,"8 mm.","10 mm.") -> 10 mm. | J3: =IF(J10=8,"8 mm.","10 mm.") -> 10 mm. | K3: =IF(K10=8,"8 mm.","10 mm.") -> 10 mm.
A4: DATOS BASE PARA EL ANALISIS | D4: =IF(D9=1,"INCOLORO","COLOR") -> INCOLORO | H4: =IF(H9=1,"INCOLORO","COLOR") -> INCOLORO | I4: =IF(I9=1,"INCOLORO","COLOR") -> INCOLORO | J4: =IF(J9=1,"INCOLORO","COLOR") -> INCOLORO | K4: =IF(K9=1,"INCOLORO","COLOR") -> INCOLORO
A5: BASE ( Metros ) | D5: 8 | H5: 4.4 | I5: 4 | J5: 4.3 | K5: 5
A6: ALTURA ( Metros ) | D6: 0.7 | H6: 2.7 | I6: 2.7 | J6: 2.7 | K6: 2.7
A7: CANTIDAD DE PIEZAS | D7: 1 | F7: =SUM(H7:HZ7) -> 4 | G7: Pzas. | H7: 1 | I7: 1 | J7: 1 | K7: 1
A8: CANTIDAD DE VANOS | D8: 6 | H8: 4 | I8: 4 | J8: 4 | K8: 4
A9: INCOLORO = 1 ; COLOR =2 | D9: 1 | H9: 1 | I9: 1 | J9: 1 | K9: 1
A10: ESPESOR DEL VIDRIO = 8 ó 10 mm. | D10: 10 | H10: 10 | I10: 10 | J10: 10 | K10: 10
A11: ESMERILADO = E
A12: Total Precio c/factura | C12: pn | D12: =+D53 -> 324.25508 | F12: =SUM(H12:HZ12) -> 2483.0617 | G12: $us. | H12: =+H53 -> 617.41248 | I12: =+I53 -> 563.76542 | J12: =+J53 -> 604.00072 | K12: =+K53 -> 697.88308
A13: Superficie Mt² | D13: =+D5*D6*D$7 -> 5.6 | F13: =SUM(H13:HZ13) -> 47.79 | G13: Mt² | H13: =+H5*H6*H$7 -> 11.88 | I13: =+I5*I6*I$7 -> 10.8 | J13: =+J5*J6*J$7 -> 11.61 | K13: =+K5*K6*K$7 -> 13.5
A14: Precio con factura en $us / Mt² | D14: =+D12/D13 -> 57.902693 | F14: =+F12/F13 -> 51.957767 | G14: $us./Mt² | H14: =+H12/H13 -> 51.970748 | I14: =+I12/I13 -> 52.200502 | J14: =+J12/J13 -> 52.024179 | K14: =+K12/K13 -> 51.695043
A15: Total Precio s/factura | D15: =+D80 -> 314.14678 | F15: =SUM(H15:HZ15) -> 2400.6493 | G15: $us. | H15: =+H80 -> 596.92238 | I15: =+I80 -> 545.08332 | J15: =+J80 -> 583.96262 | K15: =+K80 -> 674.68098
A16: Precio sin factura en $us / Mt² | D16: =+D15/D13 -> 56.09764 | F16: =+F15/F13 -> 50.233298 | G16: $us./Mt² | H16: =+H15/H13 -> 50.245992 | I16: =+I15/I13 -> 50.470677 | J16: =+J15/J13 -> 50.298244 | K16: =+K15/K13 -> 49.976369
A17: Materia Prima ( Vidrio ) | D17: =0.9*SUM(D54:D57) -> 182.01613 | F17: =SUM(H17:HZ17) -> 1561.1073 | G17: $us. | H17: =0.9*SUM(H54:H57) -> 388.09652 | I17: =0.9*SUM(I54:I57) -> 353.21143 | J17: =0.9*SUM(J54:J57) -> 379.37524 | K17: =0.9*SUM(K54:K57) -> 440.42413
A18: Materia Prima ( materiales ) | D18: =0.9*SUM(D59:D77) -> 52.35744 | F18: =SUM(H18:HZ18) -> 183.3228 | G18: $us. | H18: =0.9*SUM(H59:H77) -> 45.68592 | I18: =0.9*SUM(I59:I77) -> 43.36944 | J18: =0.9*SUM(J59:J77) -> 45.1068 | K18: =0.9*SUM(K59:K77) -> 49.16064
A19: Mano de obra | D19: =+D58*0.9 -> 57.456 | F19: =SUM(H19:HZ19) -> 490.3254 | G19: $us. | H19: =+H58*0.9 -> 121.8888 | I19: =+I58*0.9 -> 110.808 | J19: =+J58*0.9 -> 119.1186 | K19: =+K58*0.9 -> 138.51
A20: Otros Gastos + Util | D20: =+D12-D19-D18-D17 -> 32.425508 | F20: =SUM(H20:HZ20) -> 248.30617 | G20: $us. | H20: =+H12-H19-H18-H17 -> 61.741248 | I20: =+I12-I19-I18-I17 -> 56.376542 | J20: =+J12-J19-J18-J17 -> 60.400072 | K20: =+K12-K19-K18-K17 -> 69.788308
A21: TOTAL | D21: =SUM(D17:D20) -> 324.25508 | F21: =SUM(H21:HZ21) -> 2483.0617 | G21: $us. | H21: =SUM(H17:H20) -> 617.41248 | I21: =SUM(I17:I20) -> 563.76542 | J21: =SUM(J17:J20) -> 604.00072 | K21: =SUM(K17:K20) -> 697.88308
A22: % descuento del con al sin | D22: =+(D12-D15)/D12 -> 0.031173914 | F22: =+(F12-F15)/F12 -> 0.033189832 | H22: =+(H12-H15)/H12 -> 0.033187052 | I22: =+(I12-I15)/I12 -> 0.033138074 | J22: =+(J12-J15)/J12 -> 0.033175623 | K22: =+(K12-K15)/K12 -> 0.0332464
A24: DETALLE DE MATERIALES A UTILIZAR
A25: MATERIAL | C25: Unidad | D25: =+D2 -> PF | F25: Cantidad | G25: Unidad | H25: =+H2 -> piso1 | I25: =+I2 -> piso1 | J25: =+J2 -> piso1 | K25: =+K2 -> piso1
A26: Vidrio Templado 10mm Incoloro | C26: Mt² | D26: =IF(D$9=1,IF(D$10=10,((D$6*0.05)+(D$5*D$6))*D$7,0),0) -> 5.635 | E26: =VLOOKUP(A26,'Costo M.P.yMat.'!C7:D203,2,FALSE) -> 17 | F26: =ROUNDUP(SUM(H26:HZ26),1) -> 48.4 | G26: Mt² | H26: =IF(H$9=1,IF(H$10=10,((H$6*0.05)+(H$5*H$6))*H$7,0),0) -> 12.015 | I26: =IF(I$9=1,IF(I$10=10,((I$6*0.05)+(I$5*I$6))*I$7,0),0) -> 10.935 | J26: =IF(J$9=1,IF(J$10=10,((J$6*0.05)+(J$5*J$6))*J$7,0),0) -> 11.745 | K26: =IF(K$9=1,IF(K$10=10,((K$6*0.05)+(K$5*K$6))*K$7,0),0) -> 13.635
A27: Vidrio Templado 10mm Color | C27: Mt² | D27: =IF(D$9=2,IF(D$10=10,((D$6*0.05)+(D$5*D$6))*D$7,0),0) -> 0 | E27: =VLOOKUP(A27,'Costo M.P.yMat.'!C8:D204,2,FALSE) -> 22 | F27: =ROUNDUP(SUM(H27:HZ27),1) -> 0 | G27: Mt² | H27: =IF(H$9=2,IF(H$10=10,((H$6*0.05)+(H$5*H$6))*H$7,0),0) -> 0 | I27: =IF(I$9=2,IF(I$10=10,((I$6*0.05)+(I$5*I$6))*I$7,0),0) -> 0 | J27: =IF(J$9=2,IF(J$10=10,((J$6*0.05)+(J$5*J$6))*J$7,0),0) -> 0 | K27: =IF(K$9=2,IF(K$10=10,((K$6*0.05)+(K$5*K$6))*K$7,0),0) -> 0
A28: Vidrio Templado 8mm Incoloro | C28: Mt² | D28: =IF(D$9=1,IF(D$10=8,((D$6*0.05)+(D$5*D$6))*D$7,0),0) -> 0 | E28: =VLOOKUP(A28,'Costo M.P.yMat.'!C9:D205,2,FALSE) -> 18 | F28: =ROUNDUP(SUM(H28:HZ28),1) -> 0 | G28: Mt² | H28: =IF(H$9=1,IF(H$10=8,((H$6*0.05)+(H$5*H$6))*H$7,0),0) -> 0 | I28: =IF(I$9=1,IF(I$10=8,((I$6*0.05)+(I$5*I$6))*I$7,0),0) -> 0 | J28: =IF(J$9=1,IF(J$10=8,((J$6*0.05)+(J$5*J$6))*J$7,0),0) -> 0 | K28: =IF(K$9=1,IF(K$10=8,((K$6*0.05)+(K$5*K$6))*K$7,0),0) -> 0
A29: Vidrio Templado 8mm Color | C29: Mt² | D29: =IF(D$9=2,IF(D$10=8,((D$5*D$6))*D$7,0),0) -> 0 | E29: =VLOOKUP(A29,'Costo M.P.yMat.'!C10:D206,2,FALSE) -> 23 | F29: =ROUNDUP(SUM(H29:HZ29),1) -> 0 | G29: Mt² | H29: =IF(H$9=2,IF(H$10=8,((H$5*H$6))*H$7,0),0) -> 0 | I29: =IF(I$9=2,IF(I$10=8,((I$5*I$6))*I$7,0),0) -> 0 | J29: =IF(J$9=2,IF(J$10=8,((J$5*J$6))*J$7,0),0) -> 0 | K29: =IF(K$9=2,IF(K$10=8,((K$5*K$6))*K$7,0),0) -> 0
A30: Mano de obra | C30: Mt² | D30: =+D13 -> 5.6 | E30: 75 | F30: =ROUNDUP(SUM(H30:HZ30),1) -> 47.8 | G30: Mt² | H30: =+H13 -> 11.88 | I30: =+I13 -> 10.8 | J30: =+J13 -> 11.61 | K30: =+K13 -> 13.5
A31: Silicona transparente, blanca o negra | C31: Tubo | D31: =D7*(4*D5+4*D6+(D8-1)*D6)/6 -> 6.3833333 | E31: 1 | F31: =ROUNDUP(SUM(H31:HZ31),1) -> 24.4 | G31: Tubo | H31: =H7*(4*H5+4*H6+(H8-1)*H6)/6 -> 6.0833333 | I31: =I7*(4*I5+4*I6+(I8-1)*I6)/6 -> 5.8166667 | J31: =J7*(4*J5+4*J6+(J8-1)*J6)/6 -> 6.0166667 | K31: =K7*(4*K5+4*K6+(K8-1)*K6)/6 -> 6.4833333
A32: Cinta masking 1/2 " (rollo de 20) | C32: Rollo | D32: =+D31*12/20 -> 3.83 | E32: 3 | F32: =ROUNDUP(SUM(H32:HZ32),1) -> 14.7 | G32: Rollo | H32: =+H31*12/20 -> 3.65 | I32: =+I31*12/20 -> 3.49 | J32: =+J31*12/20 -> 3.61 | K32: =+K31*12/20 -> 3.89
A33: "U" 15x25 - Kg/Mt lineal. | B33: 0.2 | C33: Kgr | D33: =(2*D$6+2*D5)*$B33*D$7 -> 3.48 | E33: 5 | F33: =ROUNDUP(SUM(H33:HZ33)/(6*B33),1) -> 9.5 | G33: Barras | H33: =(2*H$6+2*H5)*$B33*H$7 -> 2.84 | I33: =(2*I$6+2*I5)*$B33*I$7 -> 2.68 | J33: =(2*J$6+2*J5)*$B33*J$7 -> 2.8 | K33: =(2*K$6+2*K5)*$B33*K$7 -> 3.08
A34: Esmerilado | C34: Mt² | D34: =IF((D11="e"),D13,IF( (D11="E"),D13,0)) -> 0 | E34: 186 | F34: =ROUNDUP(SUM(H34:HZ34),1) -> 0 | G34: Mt lineal | H34: =IF((H11="e"),H13,IF( (H11="E"),H13,0)) -> 0 | I34: =IF((I11="e"),I13,IF( (I11="E"),I13,0)) -> 0 | J34: =IF((J11="e"),J13,IF( (J11="E"),J13,0)) -> 0 | K34: =IF((K11="e"),K13,IF( (K11="E"),K13,0)) -> 0
A35: Tarugos No. 6 | C35: Pza. | D35: =D$7*(2*D$5+2*D$6)/0.4 -> 43.5 | E35: =VLOOKUP(A35,'Costo M.P.yMat.'!C16:D212,2,FALSE) -> 13 | F35: =ROUNDUP(SUM(H35:HZ35),1) -> 142.5 | G35: Pza. | H35: =H$7*(2*H$5+2*H$6)/0.4 -> 35.5 | I35: =I$7*(2*I$5+2*I$6)/0.4 -> 33.5 | J35: =J$7*(2*J$5+2*J$6)/0.4 -> 35 | K35: =K$7*(2*K$5+2*K$6)/0.4 -> 38.5
A36: Tornillos 8 x 1 1/2 | C36: Pza. | D36: =D$7*(2*D$5+2*D$6)/0.4 -> 43.5 | E36: =VLOOKUP(A36,'Costo M.P.yMat.'!C17:D213,2,FALSE) -> 14 | F36: =ROUNDUP(SUM(H36:HZ36),1) -> 142.5 | G36: Pza. | H36: =H$7*(2*H$5+2*H$6)/0.4 -> 35.5 | I36: =I$7*(2*I$5+2*I$6)/0.4 -> 33.5 | J36: =J$7*(2*J$5+2*J$6)/0.4 -> 35 | K36: =K$7*(2*K$5+2*K$6)/0.4 -> 38.5
A37: Vedapres 001 - u (2,10mt/barra) | C37: Barra | F37: =ROUNDUP(SUM(H37:HZ37),1) -> 0 | G37: Barra
A38: Vedapres 001 - h (2,10mt/barra) | C38: Barra | F38: =ROUNDUP(SUM(H38:HZ38),1) -> 0 | G38: Barra
A39: Cabezal 7313 - Kg/Mt l. | B39: 1.013 | C39: Kgr | F39: =ROUNDUP(SUM(H39:HZ39)/(6*B39),1) -> 0 | G39: Barras
A40: Tapa 7312 - Kg/Mt l. | B40: 0.408 | C40: Kgr | F40: =ROUNDUP(SUM(H40:HZ40)/(6*B40),1) -> 0 | G40: Barras
A41: Trillo 7314 - Kg/Mt l. | B41: 0.478 | C41: Kgr | F41: =ROUNDUP(SUM(H41:HZ41)/(6*B41),1) -> 0 | G41: Barras
...

Sheet P-V.Corrediza
A2: PUERTA / VENTANA CORREDIZA | D2: =IF(D8=1,"PC2H","VC2H") -> VC2H | E2: =IF(E8=1,"PC4H","VC4H") -> VC4H | G2: Total | I2: piso1 | J2: piso1 | K2: piso12 | L2: piso12
A3: 8 o 10 mm. c/PERFIL U 15x15 DE ALUMINIO | D3: =IF(D10=8,"8 mm.","10 mm.") -> 10 mm. | E3: =IF(E10=8,"8 mm.","10 mm.") -> 10 mm. | I3: =IF(I10=8,"8 mm.","10 mm.") -> 10 mm. | J3: =IF(J10=8,"8 mm.","10 mm.") -> 10 mm. | K3: =IF(K10=8,"8 mm.","10 mm.") -> 10 mm. | L3: =IF(L10=8,"8 mm.","10 mm.") -> 10 mm.
A4: DATOS BASE PARA EL ANALISIS | D4: =IF(D9=1,"INCOLORO","COLOR") -> INCOLORO | E4: =IF(E9=1,"INCOLORO","COLOR") -> INCOLORO | I4: =IF(I9=1,"INCOLORO","COLOR") -> INCOLORO | J4: =IF(J9=1,"INCOLORO","COLOR") -> INCOLORO | K4: =IF(K9=1,"INCOLORO","COLOR") -> INCOLORO | L4: =IF(L9=1,"INCOLORO","COLOR") -> INCOLORO
A5: BASE ( Metros ) | D5: 2 | E5: 3.5 | I5: 5.8 | J5: 5.3 | K5: 4.1 | L5: 4.1
A6: ALTURA ( Metros ) | D6: 2.1 | E6: 2.3 | I6: 2.2 | J6: 2.2 | K6: 2.2 | L6: 2.2
A7: CANTIDAD DE PIEZAS | D7: 1 | E7: 1 | G7: =SUM(I7:IF7) -> 4 | H7: Pzas. | I7: 1 | J7: 1 | K7: 1 | L7: 1
A8: PUERTA = 1; VENTANA = 2 | D8: 2 | E8: 2 | I8: 1 | J8: 1 | K8: 1 | L8: 1
A9: INCOLORO = 1 ; COLOR =2 | D9: 1 | E9: 1 | I9: 1 | J9: 1 | K9: 1 | L9: 1
A10: ESPESOR DEL VIDRIO = 8 ó 10 mm. | D10: 10 | E10: 10 | I10: 10 | J10: 10 | K10: 10 | L10: 10
A11: Total Precio c/factura | C11: pn | D11: =+D57 -> 271.85393 | E11: =+E57 -> 510.50703 | G11: =SUM(I11:IF11) -> 2473.4415 | H11: $us. | I11: =+I57 -> 735.79514 | J11: =+J57 -> 661.49197 | K11: =+K57 -> 538.0772 | L11: =+L57 -> 538.0772
A12: Superficie Mt² | D12: =+D5*D6*D$7 -> 4.2 | E12: =+E5*E6*E$7 -> 8.05 | G12: =SUM(I12:IF12) -> 42.46 | H12: Mt² | I12: =+I5*I6*I$7 -> 12.76 | J12: =+J5*J6*J$7 -> 11.66 | K12: =+K5*K6*K$7 -> 9.02 | L12: =+L5*L6*L$7 -> 9.02
A13: Precio con factura en $us / Mt² | D13: =+D11/D12 -> 64.727125 | E13: =+E11/E12 -> 63.417023 | G13: =+G11/G12 -> 58.253451 | H13: $us./Mt² | I13: =+I11/I12 -> 57.664196 | J13: =+J11/J12 -> 56.73173 | K13: =+K11/K12 -> 59.653792 | L13: =+L11/L12 -> 59.653792
A14: Total Precio s/factura | D14: =+D84 -> 293.01349 | E14: =+E84 -> 525.71551 | G14: =SUM(I14:IF14) -> 2415.8741 | H14: $us. | I14: =+I84 -> 708.73954 | J14: =+J84 -> 670.23337 | K14: =+K84 -> 518.4506 | L14: =+L84 -> 518.4506
A15: Precio sin factura en $us / Mt² | D15: =+D14/D12 -> 69.765116 | E15: =+E14/E12 -> 65.306275 | G15: =+G14/G12 -> 56.897647 | H15: $us./Mt² | I15: =+I14/I12 -> 55.543851 | J15: =+J14/J12 -> 57.481421 | K15: =+K14/K12 -> 57.477894 | L15: =+L14/L12 -> 57.477894
A16: Materia Prima ( Vidrio ) | D16: =0.9*SUM(D58:D61) -> 139.05581 | E16: =0.9*SUM(E58:E61) -> 263.73766 | G16: =SUM(I16:IF16) -> 1385.7129 | H16: Sus. | I16: =0.9*SUM(I58:I61) -> 415.71387 | J16: =0.9*SUM(J58:J61) -> 380.18277 | K16: =0.9*SUM(K58:K61) -> 294.90813 | L16: =0.9*SUM(L58:L61) -> 294.90813
A17: Materia Prima ( materiales ) | D17: =0.9*SUM(D63:D81) -> 62.520728 | E17: =0.9*SUM(E63:E81) -> 113.12567 | G17: =SUM(I17:IF17) -> 404.74486 | H17: Sus. | I17: =0.9*SUM(I63:I81) -> 115.58415 | J17: =0.9*SUM(J63:J81) -> 95.528404 | K17: =0.9*SUM(K63:K81) -> 96.816152 | L17: =0.9*SUM(L63:L81) -> 96.816152
A18: Mano de obra | D18: =+D62*0.9 -> 43.092 | E18: =+E62*0.9 -> 82.593 | G18: =SUM(I18:IF18) -> 435.6396 | H18: Sus. | I18: =+I62*0.9 -> 130.9176 | J18: =+J62*0.9 -> 119.6316 | K18: =+K62*0.9 -> 92.5452 | L18: =+L62*0.9 -> 92.5452
A19: Otros Gastos + Util | D19: =+D11-SUM(D16:D18) -> 27.185393 | E19: =+E11-SUM(E16:E18) -> 51.050703 | G19: =SUM(I19:IF19) -> 247.34415 | H19: Sus. | I19: =+I11-SUM(I16:I18) -> 73.579514 | J19: =+J11-SUM(J16:J18) -> 66.149197 | K19: =+K11-SUM(K16:K18) -> 53.80772 | L19: =+L11-SUM(L16:L18) -> 53.80772
A20: TOTAL | D20: =SUM(D16:D19) -> 271.85393 | E20: =SUM(E16:E19) -> 510.50703 | G20: =SUM(I20:IF20) -> 2473.4415 | H20: Sus. | I20: =SUM(I16:I19) -> 735.79514 | J20: =SUM(J16:J19) -> 661.49197 | K20: =SUM(K16:K19) -> 538.0772 | L20: =SUM(L16:L19) -> 538.0772
A21: Materia Prima ( Vidrio ) / Mt2 | D21: =+D16/D$12 -> 33.108525 | E21: =+E16/E$12 -> 32.762443 | G21: =SUM(I21:IF21) -> 79.507726 | H21: Sus. | I21: =0.9*SUM(I63:I66) -> 18.7416 | J21: =+J16/J$12 -> 32.605726 | K21: =0.9*SUM(K63:K66) -> 14.0802 | L21: =0.9*SUM(L63:L66) -> 14.0802
A22: Materia Prima ( materiales ) / Mt2 | D22: =+D17/D$12 -> 14.885888 | E22: =+E17/E$12 -> 14.052878 | G22: =SUM(I22:IF22) -> 2808.665 | H22: Sus. | I22: =0.9*SUM(I68:I86) -> 1134.6191 | J22: =+J17/J$12 -> 8.1928305 | K22: =0.9*SUM(K68:K86) -> 832.92654 | L22: =0.9*SUM(L68:L86) -> 832.92654
A23: Mano de obra / Mt2 | D23: =+D18/D$12 -> 10.26 | E23: =+E18/E$12 -> 10.26 | G23: =SUM(I23:IF23) -> 13.968 | H23: Sus. | I23: =+I67*0.9 -> 1.44 | J23: =+J18/J$12 -> 10.26 | K23: =+K67*0.9 -> 1.134 | L23: =+L67*0.9 -> 1.134
A24: Otros Gastos + Util / Mt2 | D24: =+D19/D$12 -> 6.4727125 | E24: =+E19/E$12 -> 6.3417023 | G24: =SUM(I24:IF24) -> -1839.8789 | H24: Sus. | I24: =+I16-SUM(I21:I23) -> -739.08681 | J24: =+J19/J$12 -> 5.673173 | K24: =+K16-SUM(K21:K23) -> -553.23261 | L24: =+L16-SUM(L21:L23) -> -553.23261
A25: TOTAL | D25: =SUM(D21:D24) -> 64.727125 | E25: =SUM(E21:E24) -> 63.417023 | G25: =SUM(I25:IF25) -> 1062.2619 | H25: Sus. | I25: =SUM(I21:I24) -> 415.71387 | J25: =SUM(J21:J24) -> 56.73173 | K25: =SUM(K21:K24) -> 294.90813 | L25: =SUM(L21:L24) -> 294.90813
A26: % descuento del con al sin | D26: =+(D11-D14)/D11 -> -0.0778343 | E26: =+(E11-E14)/E11 -> -0.029790931 | G26: =ROUNDDOWN(+(G11-G14)/G11,2) -> 0.02 | I26: =+(I11-I14)/I11 -> 0.036770561 | J26: =+(J11-J14)/J11 -> -0.013214673 | K26: =+(K11-K14)/K11 -> 0.036475435 | L26: =+(L11-L14)/L11 -> 0.036475435
G27: =+G11+'Pano Fijo'!F12+('Costo M.P.yMat.'!L15*4) -> 4973.4232
A28: DETALLE DE MATERIALES A UTILIZAR
A29: MATERIAL | C29: Unidad | D29: =+D2 -> VC2H | E29: =+E2 -> VC4H | G29: Cantidad | H29: Unidad | I29: =+I2 -> piso1 | J29: =+J2 -> piso1 | K29: =+K2 -> piso12 | L29: =+L2 -> piso12
A30: Vidrio Templado 10mm Incoloro | C30: Mt² | D30: =IF(D$9=1,IF(D$10=10,((D$6*0.05)+(D$5*D$6))*D$7,0),0) -> 4.305 | E30: =IF(E$9=1,IF(E$10=10,((E$6*0.05)+(E$5*E$6))*E$7,0),0) -> 8.165 | F30: 17 | G30: =ROUNDUP(SUM(I30:IF30),1) -> 42.9 | H30: Mt² | I30: =IF(I$9=1,IF(I$10=10,((I$6*0.05)+(I$5*I$6))*I$7,0),0) -> 12.87 | J30: =IF(J$9=1,IF(J$10=10,((J$6*0.05)+(J$5*J$6))*J$7,0),0) -> 11.77 | K30: =IF(K$9=1,IF(K$10=10,((K$6*0.05)+(K$5*K$6))*K$7,0),0) -> 9.13 | L30: =IF(L$9=1,IF(L$10=10,((L$6*0.05)+(L$5*L$6))*L$7,0),0) -> 9.13
A31: Vidrio Templado 10mm Color | C31: Mt² | D31: =IF(D$9=2,IF(D$10=10,((D$6*0.05)+(D$5*D$6))*D$7,0),0) -> 0 | E31: =IF(E$9=2,IF(E$10=10,((E$6*0.05)+(E$5*E$6))*E$7,0),0) -> 0 | F31: 22 | G31: =ROUNDUP(SUM(I31:IF31),1) -> 0 | H31: Mt² | I31: =IF(I$9=2,IF(I$10=10,((I$6*0.05)+(I$5*I$6))*I$7,0),0) -> 0 | J31: =IF(J$9=2,IF(J$10=10,((J$6*0.05)+(J$5*J$6))*J$7,0),0) -> 0 | K31: =IF(K$9=2,IF(K$10=10,((K$6*0.05)+(K$5*K$6))*K$7,0),0) -> 0 | L31: =IF(L$9=2,IF(L$10=10,((L$6*0.05)+(L$5*L$6))*L$7,0),0) -> 0
A32: Vidrio Templado 8mm Incoloro | C32: Mt² | D32: =IF(D$9=1,IF(D$10=8,((D$6*0.05)+(D$5*D$6))*D$7,0),0) -> 0 | E32: =IF(E$9=1,IF(E$10=8,((E$6*0.05)+(E$5*E$6))*E$7,0),0) -> 0 | F32: 18 | G32: =ROUNDUP(SUM(I32:IF32),1) -> 0 | H32: Mt² | I32: =IF(I$9=1,IF(I$10=8,((I$6*0.05)+(I$5*I$6))*I$7,0),0) -> 0 | J32: =IF(J$9=1,IF(J$10=8,((J$6*0.05)+(J$5*J$6))*J$7,0),0) -> 0 | K32: =IF(K$9=1,IF(K$10=8,((K$6*0.05)+(K$5*K$6))*K$7,0),0) -> 0 | L32: =IF(L$9=1,IF(L$10=8,((L$6*0.05)+(L$5*L$6))*L$7,0),0) -> 0
A33: Vidrio Templado 8mm Color | C33: Mt² | D33: =IF(D$9=2,IF(D$10=8,((D$6*0.05)+(D$5*D$6))*D$7,0),0) -> 0 | E33: =IF(E$9=2,IF(E$10=8,((E$6*0.05)+(E$5*E$6))*E$7,0),0) -> 0 | F33: 23 | G33: =ROUNDUP(SUM(I33:IF33),1) -> 0 | H33: Mt² | I33: =IF(I$9=2,IF(I$10=8,((I$6*0.05)+(I$5*I$6))*I$7,0),0) -> 0 | J33: =IF(J$9=2,IF(J$10=8,((J$6*0.05)+(J$5*J$6))*J$7,0),0) -> 0 | K33: =IF(K$9=2,IF(K$10=8,((K$6*0.05)+(K$5*K$6))*K$7,0),0) -> 0 | L33: =IF(L$9=2,IF(L$10=8,((L$6*0.05)+(L$5*L$6))*L$7,0),0) -> 0
A34: Mano de obra | C34: Mt² | D34: =+D12 -> 4.2 | E34: =+E12 -> 8.05 | F34: 75 | G34: =ROUNDUP(SUM(I34:IF34),1) -> 42.5 | H34: Mt² | I34: =+I12 -> 12.76 | J34: =+J12 -> 11.66 | K34: =+K12 -> 9.02 | L34: =+L12 -> 9.02
A35: Silicona transparente, blanca o negra | C35: Tubo | D35: =D7*(4*D5+2*D6)/6 -> 2.0333333 | E35: =E7*(4*E5+2*E6)/6 -> 3.1 | F35: 1 | G35: =ROUNDUP(SUM(I35:IF35),1) -> 15.8 | H35: Tubo | I35: =I7*(4*I5+2*I6)/6 -> 4.6 | J35: =J7*(4*J5+2*J6)/6 -> 4.2666667 | K35: =K7*(4*K5+2*K6)/6 -> 3.4666667 | L35: =L7*(4*L5+2*L6)/6 -> 3.4666667
A36: Cinta masking 1/2 " (rollo de 20) | C36: Rollo | D36: =+D35*12/20 -> 1.22 | E36: =+E35*12/20 -> 1.86 | F36: 3 | G36: =ROUNDUP(SUM(I36:IF36),1) -> 9.5 | H36: Rollo | I36: =+I35*12/20 -> 2.76 | J36: =+J35*12/20 -> 2.56 | K36: =+K35*12/20 -> 2.08 | L36: =+L35*12/20 -> 2.08
A37: "U" 15x25 - Kg/Mt lineal. | C37: Mt lineal | D37: =2*D$6*D$7 -> 4.2 | E37: =2*E$6*E$7 -> 4.6 | F37: 5 | G37: =ROUNDUP(SUM(I37:IF37)/(6*B37),1) -> #DIV/0! | H37: Barras | I37: =2*I$6*$B37*I$7 -> 0 | J37: =2*J$6*J$7 -> 4.4 | K37: =2*K$6*$B37*K$7 -> 0 | L37: =2*L$6*$B37*L$7 -> 0
A38: Felpa | C38: Mt lineal | D38: =(D6+3*D5)*D7 -> 8.1 | E38: =(E6+3*E5)*E7 -> 12.8 | F38: 11 | G38: =ROUNDUP(SUM(I38:IF38),1) -> 66.7 | H38: Mt lineal | I38: =(I6+3*I5)*I7 -> 19.6 | J38: =(J6+3*J5)*J7 -> 18.1 | K38: =(K6+3*K5)*K7 -> 14.5 | L38: =(L6+3*L5)*L7 -> 14.5
A39: Tarugos No. 6 | C39: Pza. | D39: =D$7*(2*D$5+2*D$6)/0.4 -> 20.5 | E39: =E$7*(2*E$5+2*E$6)/0.4 -> 29 | F39: 13 | G39: =ROUNDUP(SUM(I39:IF39),1) -> 140.5 | H39: Pza. | I39: =I$7*(2*I$5+2*I$6)/0.4 -> 40 | J39: =J$7*(2*J$5+2*J$6)/0.4 -> 37.5 | K39: =K$7*(2*K$5+2*K$6)/0.4 -> 31.5 | L39: =L$7*(2*L$5+2*L$6)/0.4 -> 31.5
A40: Tornillos 8 x 1 1/2 | C40: Pza. | D40: =D$7*(2*D$5+2*D$6)/0.4 -> 20.5 | E40: =E$7*(2*E$5+2*E$6)/0.4 -> 29 | F40: 14 | G40: =ROUNDUP(SUM(I40:IF40),1) -> 140.5 | H40: Pza. | I40: =I$7*(2*I$5+2*I$6)/0.4 -> 40 | J40: =J$7*(2*J$5+2*J$6)/0.4 -> 37.5 | K40: =K$7*(2*K$5+2*K$6)/0.4 -> 31.5 | L40: =L$7*(2*L$5+2*L$6)/0.4 -> 31.5
A41: Vedapres 001 - u - Kg/Mt l. | B41: 0.151 | C41: Kgr | D41: =+D$6*$B41*D$7 -> 0.3171 | E41: =2*E$6*$B41*E$7 -> 0.6946 | F41: 30 | G41: =ROUNDUP(SUM(I41:IF41)/(6*B41),1) -> 2.6 | H41: Barras | I41: =2*I$6*$B41*I$7 -> 0.6644 | J41: =+J$6*$B41*J$7 -> 0.3322 | K41: =2*K$6*$B41*K$7 -> 0.6644 | L41: =2*L$6*$B41*L$7 -> 0.6644
...

Sheet P.Batiente
A2: PUERTAS DE VIDRIO TEMPLADO | D2: PB1H | E2: PB2H | F2: PB4H | G2: PB4H | H2: PB4HcV | I2: PB4HcV | J2: PB4HcV | L2: Total | N2: piso1 | O2: piso1 | P2: piso1 | Q2: piso1 | R2: piso1 | S2: piso1 | T2: piso1
A3: 8 o 10 mm. c/PERFIL U 15x15 DE ALUMINIO | D3: 10mm. | E3: 10mm. | F3: 10mm. | G3: 10 mm. | H3: 10 mm. | I3: 10mm. | J3: 10mm. | N3: 10 mm. | O3: 10 mm. | P3: 10 mm. | Q3: 10 mm. | R3: 10 mm. | S3: 10 mm. | T3: 10 mm.
A4: DATOS BASE PARA EL ANALISIS | D4: =IF(D8=1,"INCOLORO","COLOR") -> INCOLORO | E4: =IF(E8=1,"INCOLORO","COLOR") -> INCOLORO | F4: =IF(F8=1,"INCOLORO","COLOR") -> INCOLORO | G4: =IF(G8=1,"INCOLORO","COLOR") -> INCOLORO | H4: =IF(H8=1,"INCOLORO","COLOR") -> INCOLORO | I4: =IF(I8=1,"INCOLORO","COLOR") -> INCOLORO | J4: =IF(J8=1,"INCOLORO","COLOR") -> INCOLORO | N4: =IF(N8=1,"INCOLORO","COLOR") -> INCOLORO | O4: =IF(O8=1,"INCOLORO","COLOR") -> INCOLORO | P4: =IF(P8=1,"INCOLORO","COLOR") -> INCOLORO | Q4: =IF(Q8=1,"INCOLORO","COLOR") -> INCOLORO | R4: =IF(R8=1,"INCOLORO","COLOR") -> INCOLORO | S4: =IF(S8=1,"INCOLORO","COLOR") -> INCOLORO | T4: =IF(T8=1,"INCOLORO","COLOR") -> INCOLORO
A5: BASE ( Metros ) | D5: 0.84 | E5: 1.7 | F5: 7.22 | G5: 2 | H5: 4.5 | I5: 5 | J5: 4.5 | N5: 4.8 | O5: 5.94 | P5: 5.95 | Q5: 5.95 | R5: 4.07 | S5: 5.8 | T5: 1.1
A6: ALTURA ( Metros ) | D6: 2.1 | E6: 2.5 | F6: 2.25 | G6: 3 | H6: 2.7 | I6: 3 | J6: 2.7 | N6: 2.7 | O6: 2.7 | P6: 2.7 | Q6: 2.7 | R6: 2.7 | S6: 2.7 | T6: 2.7
A7: CANTIDAD DE PIEZAS | D7: 1 | E7: 1 | F7: 1 | G7: 1 | H7: 1 | I7: 1 | J7: 1 | L7: =SUM(N7:IU7) -> 7 | M7: Puertas | N7: 1 | O7: 1 | P7: 1 | Q7: 1 | R7: 1 | S7: 1 | T7: 1
A8: INCOLORO = 1 ; COLOR =2 | D8: 1 | E8: 1 | F8: 1 | G8: 1 | H8: 1 | I8: 1 | J8: 1 | N8: 1 | O8: 1 | P8: 1 | Q8: 1 | R8: 1 | S8: 1 | T8: 1
A9: C/FRENO = 1 ; S/FRENO =2 | D9: 2 | E9: 1 | F9: 1 | G9: 1 | H9: 1 | I9: 1 | J9: 1 | N9: 2 | O9: 2 | P9: 2 | Q9: 2 | R9: 2 | S9: 2 | T9: 2
A10: Total Precio c/factura | D10: =+D54 -> 154.92956 | E10: =+E54 -> 491.23935 | F10: =+F54 -> 1069.6693 | G10: =+G54 -> 604.12355 | H10: =+H54 -> 918.4012 | I10: =+I54 -> 1066.9152 | J10: =+J54 -> 776.455 | L10: =SUM(N10:IU10) -> 5568.0707 | M10: $us. | N10: =+N54 -> 797.8616 | O10: =+O54 -> 945.91112 | P10: =+P54 -> 947.2098 | Q10: =+Q54 -> 947.2098 | R10: =+R54 -> 703.05796 | S10: =+S54 -> 927.7296 | T10: =+T54 -> 299.09083
A11: Superficie Mt² | D11: =+D5*D6*D$7 -> 1.764 | E11: =+E5*E6*E$7 -> 4.25 | F11: =+F5*F6*F$7 -> 16.245 | G11: =+G5*G6*G$7 -> 6 | H11: =+H5*H6*H$7 -> 12.15 | I11: =+I5*I6*I$7 -> 15 | J11: =+J5*J6*J$7 -> 12.15 | L11: =SUM(N11:IU11) -> 90.747 | M11: Mt² | N11: =+N5*N6*N$7 -> 12.96 | O11: =+O5*O6*O$7 -> 16.038 | P11: =+P5*P6*P$7 -> 16.065 | Q11: =+Q5*Q6*Q$7 -> 16.065 | R11: =+R5*R6*R$7 -> 10.989 | S11: =+S5*S6*S$7 -> 15.66 | T11: =+T5*T6*T$7 -> 2.97
A12: Precio con factura en $us / Mt² | D12: =+D10/D11 -> 87.828549 | E12: =+E10/E11 -> 115.58573 | F12: =+F10/F11 -> 65.846066 | G12: =+G10/G11 -> 100.68726 | H12: =+H10/H11 -> 75.588576 | I12: =+I10/I11 -> 71.127681 | J12: =+J10/J11 -> 63.905761 | L12: =+L10/L11 -> 61.358179 | M12: $us./Mt² | N12: =+N10/N11 -> 61.563395 | O12: =+O10/O11 -> 58.979369 | P12: =+P10/P11 -> 58.961083 | Q12: =+Q10/Q11 -> 58.961083 | R12: =+R10/R11 -> 63.978338 | S12: =+S10/S11 -> 59.241992 | T12: =+T10/T11 -> 100.70398
A13: Total Precio s/factura | D13: =+D85 -> 143.7766 | E13: =+E85 -> 474.03315 | F13: =+F85 -> 1032.4951 | G13: =+G85 -> 583.00811 | H13: =+H85 -> 886.4113 | I13: =+I85 -> 1029.7598 | J13: =+J85 -> 749.6062 | L13: =SUM(N13:IU13) -> 5373.7859 | M13: $us. | N13: =+N85 -> 770.0217 | O13: =+O85 -> 912.94122 | P13: =+P85 -> 914.1949 | Q13: =+Q85 -> 914.1949 | R13: =+R85 -> 678.50306 | S13: =+S85 -> 895.3897 | T13: =+T85 -> 288.54044
A14: Precio sin factura en $us / Mt² | D14: =+D13/D11 -> 81.506009 | E14: =+E13/E11 -> 111.53721 | F14: =+F13/F11 -> 63.557716 | G14: =+G13/G11 -> 97.168019 | H14: =+H13/H11 -> 72.955663 | I14: =+I13/I11 -> 68.650652 | J14: =+J13/J11 -> 61.695984 | L14: =+L13/L11 -> 59.21723 | M14: $us./Mt² | N14: =+N13/N11 -> 59.415255 | O14: =+O13/O11 -> 56.923633 | P14: =+P13/P11 -> 56.906001 | Q14: =+Q13/Q11 -> 56.906001 | R14: =+R13/R11 -> 61.74384 | S14: =+S13/S11 -> 57.176865 | T14: =+T13/T11 -> 97.151662
A15: Materia Prima ( Vidrio ) | D15: =0.9*SUM(D55:D56) -> 56.978964 | E15: =0.9*SUM(E55:E56) -> 137.27925 | F15: =0.9*SUM(F55:F56) -> 524.72974 | G15: =0.9*SUM(G55:G56) -> 193.806 | H15: =0.9*SUM(H55:H56) -> 392.45715 | I15: =0.9*SUM(I55:I56) -> 484.515 | J15: =0.9*SUM(J55:J56) -> 392.45715 | L15: =SUM(N15:IU15) -> 2931.2188 | M15: $us. | N15: =0.9*SUM(N55:N56) -> 418.62096 | O15: =0.9*SUM(O55:O56) -> 518.04344 | P15: =0.9*SUM(P55:P56) -> 518.91557 | Q15: =0.9*SUM(Q55:Q56) -> 518.91557 | R15: =0.9*SUM(R55:R56) -> 354.95569 | S15: =0.9*SUM(S55:S56) -> 505.83366 | T15: =0.9*SUM(T55:T56) -> 95.93397
A16: Materia Prima ( materiales ) | D16: =0.9*SUM(D58:D82) -> 64.359 | E16: =0.9*SUM(E58:E82) -> 261.23116 | F16: =0.9*SUM(F58:F82) -> 271.29897 | G16: =0.9*SUM(G58:G82) -> 288.3452 | H16: =0.9*SUM(H58:H82) -> 309.44493 | I16: =0.9*SUM(I58:I82) -> 321.8087 | J16: =0.9*SUM(J58:J82) -> 181.69335 | L16: =SUM(N16:IU16) -> 1148.9806 | M16: $us. | N16: =0.9*SUM(N58:N82) -> 166.48488 | O16: =0.9*SUM(O58:O82) -> 168.72669 | P16: =0.9*SUM(P58:P82) -> 168.74635 | Q16: =0.9*SUM(Q58:Q82) -> 168.74635 | R16: =0.9*SUM(R58:R82) -> 165.04933 | S16: =0.9*SUM(S58:S82) -> 168.45138 | T16: =0.9*SUM(T58:T82) -> 142.77558
A17: Mano de obra | D17: =0.9*D57 -> 18.09864 | E17: =0.9*E57 -> 43.605 | F17: =0.9*F57 -> 166.6737 | G17: =0.9*G57 -> 61.56 | H17: =0.9*H57 -> 124.659 | I17: =0.9*I57 -> 153.9 | J17: =0.9*J57 -> 124.659 | L17: =SUM(N17:IU17) -> 931.06422 | M17: $us. | N17: =0.9*N57 -> 132.9696 | O17: =0.9*O57 -> 164.54988 | P17: =0.9*P57 -> 164.8269 | Q17: =0.9*Q57 -> 164.8269 | R17: =0.9*R57 -> 112.74714 | S17: =0.9*S57 -> 160.6716 | T17: =0.9*T57 -> 30.4722
A18: Otros Gastos + Util | D18: =+D10-D17-D16-D15 -> 15.492956 | E18: =+E10-E17-E16-E15 -> 49.123935 | F18: =+F10-F17-F16-F15 -> 106.96693 | G18: =+G10-G17-G16-G15 -> 60.412355 | H18: =+H10-H17-H16-H15 -> 91.84012 | I18: =+I10-I17-I16-I15 -> 106.69152 | J18: =+J10-J17-J16-J15 -> 77.6455 | L18: =SUM(N18:IU18) -> 556.80707 | M18: $us. | N18: =+N10-N17-N16-N15 -> 79.78616 | O18: =+O10-O17-O16-O15 -> 94.591112 | P18: =+P10-P17-P16-P15 -> 94.72098 | Q18: =+Q10-Q17-Q16-Q15 -> 94.72098 | R18: =+R10-R17-R16-R15 -> 70.305796 | S18: =+S10-S17-S16-S15 -> 92.77296 | T18: =+T10-T17-T16-T15 -> 29.909083
A19: TOTAL | D19: =SUM(D15:D18) -> 154.92956 | E19: =SUM(E15:E18) -> 491.23935 | F19: =SUM(F15:F18) -> 1069.6693 | G19: =SUM(G15:G18) -> 604.12355 | H19: =SUM(H15:H18) -> 918.4012 | I19: =SUM(I15:I18) -> 1066.9152 | J19: =SUM(J15:J18) -> 776.455 | L19: =SUM(N19:IU19) -> 5568.0707 | M19: $us. | N19: =SUM(N15:N18) -> 797.8616 | O19: =SUM(O15:O18) -> 945.91112 | P19: =SUM(P15:P18) -> 947.2098 | Q19: =SUM(Q15:Q18) -> 947.2098 | R19: =SUM(R15:R18) -> 703.05796 | S19: =SUM(S15:S18) -> 927.7296 | T19: =SUM(T15:T18) -> 299.09083
A20: % descuento del con al sin | D20: =+(D10-D13)/D10 -> 0.071987295 | E20: =+(E10-E13)/E10 -> 0.035026103 | F20: =+(F10-F13)/F10 -> 0.034753038 | G20: =+(G10-G13)/G10 -> 0.034952188 | H20: =+(H10-H13)/H10 -> 0.034832158 | I20: =+(I10-I13)/I10 -> 0.03482511 | J20: =+(J10-J13)/J10 -> 0.034578694 | L20: =+(L10-L13)/L10 -> 0.034892655 | N20: =+(N10-N13)/N10 -> 0.034893139 | O20: =+(O10-O13)/O10 -> 0.034855173 | P20: =+(P10-P13)/P10 -> 0.034854893 | Q20: =+(Q10-Q13)/Q10 -> 0.034854893 | R20: =+(R10-R13)/R10 -> 0.034925849 | S20: =+(S10-S13)/S10 -> 0.034859183 | T20: =+(T10-T13)/T10 -> 0.035274889
A22: DETALLE DE MATERIALES A UTILIZAR
A23: MATERIAL | C23: Unidad | D23: PB1H | E23: PB2H | F23: PB4H | G23: PB4H | H23: PB4H | I23: PB4H | J23: PB4H | L23: Cantidad | M23: Unidad | N23: PB4H | O23: PB4H | P23: PB4H | Q23: PB4H | R23: PB4H | S23: PB4H | T23: PB4H
A24: Vidrio Templado 10mm Incoloro | C24: Mt² | D24: =IF(D8=1,D$5*D$6*D$7,0) -> 1.764 | E24: =IF(E8=1,E$5*E$6*E$7,0) -> 4.25 | F24: =IF(F8=1,F$5*F$6*F$7,0) -> 16.245 | G24: =IF(G8=1,G$5*G$6*G$7,0) -> 6 | H24: =IF(H8=1,H$5*H$6*H$7,0) -> 12.15 | I24: =IF(I8=1,I$5*I$6*I$7,0) -> 15 | J24: =IF(J8=1,J$5*J$6*J$7,0) -> 12.15 | K24: 17 | L24: =ROUNDUP(SUM(N24:IU24),1) -> 90.8 | M24: Mt² | N24: =IF(N8=1,N$5*N$6*N$7,0) -> 12.96 | O24: =IF(O8=1,O$5*O$6*O$7,0) -> 16.038 | P24: =IF(P8=1,P$5*P$6*P$7,0) -> 16.065 | Q24: =IF(Q8=1,Q$5*Q$6*Q$7,0) -> 16.065 | R24: =IF(R8=1,R$5*R$6*R$7,0) -> 10.989 | S24: =IF(S8=1,S$5*S$6*S$7,0) -> 15.66 | T24: =IF(T8=1,T$5*T$6*T$7,0) -> 2.97
A25: Vidrio Templado 10mm Color | C25: Mt² | D25: =IF(D8=2,D$5*D$6*D$7,0) -> 0 | E25: =IF(E8=2,E$5*E$6*E$7,0) -> 0 | F25: =IF(F8=2,F$5*F$6*F$7,0) -> 0 | G25: =IF(G8=2,G$5*G$6*G$7,0) -> 0 | H25: =IF(H8=2,H$5*H$6*H$7,0) -> 0 | I25: =IF(I8=2,I$5*I$6*I$7,0) -> 0 | J25: =IF(J8=2,J$5*J$6*J$7,0) -> 0 | K25: 22 | L25: =ROUNDUP(SUM(N25:IU25),1) -> 0 | M25: Mt² | N25: =IF(N8=2,N$5*N$6*N$7,0) -> 0 | O25: =IF(O8=2,O$5*O$6*O$7,0) -> 0 | P25: =IF(P8=2,P$5*P$6*P$7,0) -> 0 | Q25: =IF(Q8=2,Q$5*Q$6*Q$7,0) -> 0 | R25: =IF(R8=2,R$5*R$6*R$7,0) -> 0 | S25: =IF(S8=2,S$5*S$6*S$7,0) -> 0 | T25: =IF(T8=2,T$5*T$6*T$7,0) -> 0
A26: Mano de obra | C26: Mt² | D26: =+D11 -> 1.764 | E26: =+E11 -> 4.25 | F26: =+F11 -> 16.245 | G26: =+G11 -> 6 | H26: =+H11 -> 12.15 | I26: =+I11 -> 15 | J26: =+J11 -> 12.15 | K26: 75 | L26: =ROUNDUP(SUM(N26:IU26),1) -> 90.8 | M26: Mt² | N26: =+N11 -> 12.96 | O26: =+O11 -> 16.038 | P26: =+P11 -> 16.065 | Q26: =+Q11 -> 16.065 | R26: =+R11 -> 10.989 | S26: =+S11 -> 15.66 | T26: =+T11 -> 2.97
A27: Silicona transparente, blanca o negra | C27: Tubo | F27: =((2*F$6+F$5)/6)*F$7 -> 1.9533333 | G27: =((2*G$6+G$5)/6)*G$7 -> 1.3333333 | H27: =((2*H$6+H$5)/2)*H$7 -> 4.95 | I27: =((2*I$6+I$5)/2)*I$7 -> 5.5 | J27: =((2*J$6+J$5)/2)*J$7 -> 4.95 | K27: 1 | L27: =ROUNDUP(SUM(N27:IU27),1) -> 33.6 | M27: Tubo | N27: =((2*N$6+N$5)/2)*N$7 -> 5.1 | O27: =((2*O$6+O$5)/2)*O$7 -> 5.67 | P27: =((2*P$6+P$5)/2)*P$7 -> 5.675 | Q27: =((2*Q$6+Q$5)/2)*Q$7 -> 5.675 | R27: =((2*R$6+R$5)/2)*R$7 -> 4.735 | S27: =((2*S$6+S$5)/2)*S$7 -> 5.6 | T27: =((2*T$6+T$5)/6)*T$7 -> 1.0833333
A28: Cinta masking 1/2 " (rollo de 20) | C28: Rollo | F28: =2*(2*F$6+F$5)*F$7/20 -> 1.172 | G28: =2*(2*G$6+G$5)*G$7/20 -> 0.8 | H28: =2*(2*H$6+H$5)*H$7/10 -> 1.98 | I28: =2*(2*I$6+I$5)*I$7/10 -> 2.2 | J28: =2*(2*J$6+J$5)*J$7/10 -> 1.98 | K28: 3 | L28: =ROUNDUP(SUM(N28:IU28),1) -> 13.7 | M28: Rollo | N28: =2*(2*N$6+N$5)*N$7/10 -> 2.04 | O28: =2*(2*O$6+O$5)*O$7/10 -> 2.268 | P28: =2*(2*P$6+P$5)*P$7/10 -> 2.27 | Q28: =2*(2*Q$6+Q$5)*Q$7/10 -> 2.27 | R28: =2*(2*R$6+R$5)*R$7/10 -> 1.894 | S28: =2*(2*S$6+S$5)*S$7/10 -> 2.24 | T28: =2*(2*T$6+T$5)*T$7/20 -> 0.65
A29: "U" 15x25 - Kg/Mt lineal. | B29: 0.2 | C29: Kgr | F29: =(2*F$6+F$5)*$B29*F$7 -> 2.344 | G29: =(2*G$6+G$5)*$B29*G$7 -> 1.6 | H29: =(2*H$6+H$5)*$B29*H$7 -> 1.98 | I29: =(2*I$6+I$5)*$B29*I$7 -> 2.2 | J29: =(2*J$6+J$5)*$B29*J$7 -> 1.98 | K29: 5 | L29: =ROUNDUP(SUM(N29:IU29)/(B29*6),1) -> 12 | M29: Barras | N29: =(2*N$6+N$5)*$B29*N$7 -> 2.04 | O29: =(2*O$6+O$5)*$B29*O$7 -> 2.268 | P29: =(2*P$6+P$5)*$B29*P$7 -> 2.27 | Q29: =(2*Q$6+Q$5)*$B29*Q$7 -> 2.27 | R29: =(2*R$6+R$5)*$B29*R$7 -> 1.894 | S29: =(2*S$6+S$5)*$B29*S$7 -> 2.24 | T29: =(2*T$6+T$5)*$B29*T$7 -> 1.3
A30: Felpa | C30: Mt lineal | E30: =+E$6*E$7 -> 2.5 | F30: =+F$6*F$7 -> 2.25 | G30: =+G$6*G$7 -> 3 | H30: =+H$6*H$7 -> 2.7 | I30: =+I$6*I$7 -> 3 | K30: 11 | L30: =ROUNDUP(SUM(N30:IU30),1) -> 18.9 | M30: Mt lineal | N30: =+N$6*N$7 -> 2.7 | O30: =+O$6*O$7 -> 2.7 | P30: =+P$6*P$7 -> 2.7 | Q30: =+Q$6*Q$7 -> 2.7 | R30: =+R$6*R$7 -> 2.7 | S30: =+S$6*S$7 -> 2.7 | T30: =+T$6*T$7 -> 2.7
A31: Tarugos No. 6 | C31: Pza. | F31: =F$7*((2*F$6+F$5)/0.4) -> 29.3 | G31: =G$7*((2*G$6+G$5)/0.4) -> 20 | H31: =H$7*((2*H$6+H$5)/0.4) -> 24.75 | I31: =I$7*((2*I$6+I$5)/0.4) -> 27.5 | J31: =J$7*((2*J$6+J$5)/0.4) -> 24.75 | K31: 13 | L31: =ROUNDUP(SUM(N31:IU31),1) -> 178.6 | M31: Pza. | N31: =N$7*((2*N$6+N$5)/0.4) -> 25.5 | O31: =O$7*((2*O$6+O$5)/0.4) -> 28.35 | P31: =P$7*((2*P$6+P$5)/0.4) -> 28.375 | Q31: =Q$7*((2*Q$6+Q$5)/0.4) -> 28.375 | R31: =R$7*((2*R$6+R$5)/0.4) -> 23.675 | S31: =S$7*((2*S$6+S$5)/0.4) -> 28 | T31: =T$7*((2*T$6+T$5)/0.4) -> 16.25
A32: Tornillos 8 x 1 1/2 | C32: Pza. | F32: =F$7*((2*F$6+F$5)/0.4) -> 29.3 | G32: =G$7*((2*G$6+G$5)/0.4) -> 20 | H32: =H$7*((2*H$6+H$5)/0.4) -> 24.75 | I32: =I$7*((2*I$6+I$5)/0.4) -> 27.5 | J32: =J$7*((2*J$6+J$5)/0.4) -> 24.75 | K32: 14 | L32: =ROUNDUP(SUM(N32:IU32),1) -> 178.6 | M32: Pza. | N32: =N$7*((2*N$6+N$5)/0.4) -> 25.5 | O32: =O$7*((2*O$6+O$5)/0.4) -> 28.35 | P32: =P$7*((2*P$6+P$5)/0.4) -> 28.375 | Q32: =Q$7*((2*Q$6+Q$5)/0.4) -> 28.375 | R32: =R$7*((2*R$6+R$5)/0.4) -> 23.675 | S32: =S$7*((2*S$6+S$5)/0.4) -> 28 | T32: =T$7*((2*T$6+T$5)/0.4) -> 16.25
A33: Vedapres 001 - h - Kg/Mt l. | B33: 0.257 | C33: Kgr | E33: =(E$6)*$B33*E$7 -> 0.6425 | F33: =(F$6)*$B33*F$7 -> 0.57825 | G33: =(G$6)*$B33*G$7 -> 0.771 | H33: =(H$6)*$B33*H$7 -> 0.6939 | I33: =(I$6)*$B33*I$7 -> 0.771 | K33: 31 | L33: =ROUNDUP(SUM(N33:IU33),1) -> 4.9 | M33: Barra | N33: =(N$6)*$B33*N$7 -> 0.6939 | O33: =(O$6)*$B33*O$7 -> 0.6939 | P33: =(P$6)*$B33*P$7 -> 0.6939 | Q33: =(Q$6)*$B33*Q$7 -> 0.6939 | R33: =(R$6)*$B33*R$7 -> 0.6939 | S33: =(S$6)*$B33*S$7 -> 0.6939 | T33: =(T$6)*$B33*T$7 -> 0.6939
A34: Freno Hidráulico HyH | C34: Pza. | D34: =IF(D$9=1,D$7,0) -> 0 | E34: =IF(E$9=1,2*E$7,0) -> 2 | F34: =IF(F$9=1,2*F$7,0) -> 2 | G34: =IF(G$9=1,2*G$7,0) -> 2 | H34: =IF(H$9=1,2*H$7,0) -> 2 | I34: =IF(I$9=1,2*I$7,0) -> 2 | J34: =IF(J$9=1,J$7,0) -> 1 | K34: 37 | L34: =ROUNDUP(SUM(N34:IU34),1) -> 0 | M34: Pza. | N34: =IF(N$9=1,2*N$7,0) -> 0 | O34: =IF(O$9=1,2*O$7,0) -> 0 | P34: =IF(P$9=1,2*P$7,0) -> 0 | Q34: =IF(Q$9=1,2*Q$7,0) -> 0 | R34: =IF(R$9=1,2*R$7,0) -> 0 | S34: =IF(S$9=1,2*S$7,0) -> 0 | T34: =IF(T$9=1,2*T$7,0) -> 0
A35: Manijones de vidrio | C35: Pza. | D35: =2*D$7 -> 2 | E35: =4*E$7 -> 4 | F35: =4*F$7 -> 4 | G35: =4*G$7 -> 4 | H35: =4*H$7 -> 4 | I35: =4*I$7 -> 4 | J35: 2 | K35: 38 | L35: =ROUNDUP(SUM(N35:IU35),1) -> 28 | M35: Pza. | N35: =4*N$7 -> 4 | O35: =4*O$7 -> 4 | P35: =4*P$7 -> 4 | Q35: =4*Q$7 -> 4 | R35: =4*R$7 -> 4 | S35: =4*S$7 -> 4 | T35: =4*T$7 -> 4
A36: 1335 | C36: Pza. | D36: 1 | E36: 3 | F36: 3 | G36: 3 | H36: 3 | I36: 3 | J36: 1 | K36: 61 | L36: =ROUNDUP(SUM(N36:IU36),1) -> 21 | M36: Pza. | N36: 3 | O36: 3 | P36: 3 | Q36: 3 | R36: 3 | S36: 3 | T36: 3
A37: 1103 | C37: Pza. | D37: =D$7 -> 1 | E37: =E$7*2 -> 2 | F37: =F$7*2 -> 2 | G37: =G$7*2 -> 2 | H37: =H$7*2 -> 2 | I37: =I$7*2 -> 2 | J37: =J$7 -> 1 | K37: 44 | L37: =ROUNDUP(SUM(N37:IU37),1) -> 14 | M37: Pza. | N37: =N$7*2 -> 2 | O37: =O$7*2 -> 2 | P37: =P$7*2 -> 2 | Q37: =Q$7*2 -> 2 | R37: =R$7*2 -> 2 | S37: =S$7*2 -> 2 | T37: =T$7*2 -> 2
A38: 1101 | C38: Pza. | D38: =D$7 -> 1 | E38: =E$7*2 -> 2 | F38: =F$7*2 -> 2 | G38: =G$7*2 -> 2 | H38: =H$7*2 -> 2 | I38: =I$7*2 -> 2 | J38: =J$7 -> 1 | K38: 43 | L38: =ROUNDUP(SUM(N38:IU38),1) -> 14 | M38: Pza. | N38: =N$7*2 -> 2 | O38: =O$7*2 -> 2 | P38: =P$7*2 -> 2 | Q38: =Q$7*2 -> 2 | R38: =R$7*2 -> 2 | S38: =S$7*2 -> 2 | T38: =T$7*2 -> 2
A39: 1636 | C39: Pza. | D39: =D$7*2 -> 2 | E39: =E$7*4 -> 4 | F39: =F$7*4 -> 4 | G39: =G$7*4 -> 4 | H39: =H$7*4 -> 4 | I39: =I$7*4 -> 4 | J39: =J$7*2 -> 2 | K39: 72 | L39: =ROUNDUP(SUM(N39:IU39),1) -> 28 | M39: Pza. | N39: =N$7*4 -> 4 | O39: =O$7*4 -> 4 | P39: =P$7*4 -> 4 | Q39: =Q$7*4 -> 4 | R39: =R$7*4 -> 4 | S39: =S$7*4 -> 4 | T39: =T$7*4 -> 4
A40: 1520 | C40: Pza. | D40: =D$7 -> 1 | E40: =E$7 -> 1 | F40: =F$7 -> 1 | G40: =G$7 -> 1 | H40: =H$7 -> 1 | I40: =I$7 -> 1 | J40: =J$7 -> 1 | K40: 67 | L40: =ROUNDUP(SUM(N40:IU40),1) -> 7 | M40: Pza. | N40: =N$7 -> 1 | O40: =O$7 -> 1 | P40: =P$7 -> 1 | Q40: =Q$7 -> 1 | R40: =R$7 -> 1 | S40: =S$7 -> 1 | T40: =T$7 -> 1
A41: 1531 | C41: Pza. | E41: =E$7 -> 1 | F41: =F$7 -> 1 | G41: =G$7 -> 1 | H41: =H$7 -> 1 | I41: =I$7 -> 1 | J41: 1 | K41: 69 | L41: =ROUNDUP(SUM(N41:IU41),1) -> 7 | M41: Pza. | N41: =N$7 -> 1 | O41: =O$7 -> 1 | P41: =P$7 -> 1 | Q41: =Q$7 -> 1 | R41: =R$7 -> 1 | S41: =S$7 -> 1 | T41: =T$7 -> 1
A42: 1038 | C42: Pza. | D42: 2 | E42: =E$7*4 -> 4 | F42: =F$7*4 -> 4 | G42: =G$7*4 -> 4 | H42: =H$7*4 -> 4 | I42: =I$7*4 -> 4 | J42: 2 | K42: 41 | L42: =ROUNDUP(SUM(N42:IU42),1) -> 28 | M42: Pza. | N42: =N$7*4 -> 4 | O42: =O$7*4 -> 4 | P42: =P$7*4 -> 4 | Q42: =Q$7*4 -> 4 | R42: =R$7*4 -> 4 | S42: =S$7*4 -> 4 | T42: =T$7*4 -> 4
...

Sheet resumen
A1: DETALLE DE MATERIALES A UTILIZAR | C1: puertas | D1: fijos | E1: corred | F1: total
A2: Vidrio Templado 10mm Incoloro | B2: Mt² | C2: 2429.6 | D2: 544.8 | E2: 78.5 | F2: =+E2+D2+C2 -> 3052.9 | G2: Mt²
A3: Mano de obra | B3: Mt² | C3: 2429.6 | D3: 541.1 | E3: 77.6 | F3: =+E3+D3+C3 -> 3048.3 | G3: Mt²
A4: Silicona transparente, blanca o negra | B4: Tubo | C4: 683.9 | D4: 218.3 | E4: 22.5 | F4: 925 | G4: Tubo
A5: Cinta masking 1/2 " (rollo de 20) | B5: Rollo | C5: 274.4 | D5: 131 | E5: 13.5 | F5: 419 | G5: Rollo
A6: "U" 15x25 - Kg/Mt lineal. | B6: Barras | C6: 230.9 | D6: 82.6 | E6: 6.5 | F6: =+E6+D6+C6 -> 320 | G6: Barras
A7: Vedapres 001 - u - Kg/Mt l. | B7: Barras | E7: 6.5 | F7: 7 | G7: Barras
A8: Vedapres 001 - h - Kg/Mt l. | B8: Barras | C8: 79.8 | E8: 3.3 | F8: 84 | G8: Barras
A9: Cabezal 7313 - Kg/Mt l. | B9: Barras | E9: 4 | F9: =+E9+D9+C9 -> 4 | G9: Barras
A10: Tapa 7312 - Kg/Mt l. | B10: Barras | E10: 4 | F10: =+E10+D10+C10 -> 4 | G10: Barras
A11: Trillo 7314 - Kg/Mt l. | B11: Barras | E11: 4 | F11: =+E11+D11+C11 -> 4 | G11: Barras
A12: TapaTrillo Rev. - Kg/Mt l. | B12: Barras | E12: 4 | F12: =+E12+D12+C12 -> 4 | G12: Barras
A13: Felpa | B13: Mt lineal | C13: 306.4 | E13: 91.4 | F13: 398 | G13: Mt lineal
A14: Tarugos No. 6 | B14: Pza. | C14: 3462.3 | D14: 1238.2 | E14: 216.9 | F14: 4918 | G14: Pza.
A15: Tornillos 8 x 1 1/2 | B15: Pza. | C15: 3462.3 | D15: 1238.2 | E15: 216.9 | F15: 4918 | G15: Pza.
A16: JALADORES | B16: Pza. | C16: 386 | F16: =+E16+D16+C16 -> 386 | G16: Pza.
A17: 1335 | B17: Pza. | C17: 288 | F17: =+E17+D17+C17 -> 288 | G17: Pza.
A18: 1103 | B18: Pza. | C18: 193 | F18: =+E18+D18+C18 -> 193 | G18: Pza.
A19: 1101 | B19: Pza. | C19: 193 | F19: =+E19+D19+C19 -> 193 | G19: Pza.
A20: 1125a | B20: Pza. | E20: 24 | F20: =+E20+D20+C20 -> 24 | G20: Pza.
A21: 1636 | B21: Pza. | C21: 386 | F21: =+E21+D21+C21 -> 386 | G21: Pza.
A22: 1510 | B22: Pza. | E22: 6 | F22: =+E22+D22+C22 -> 6 | G22: Pza.
A23: 1511 | B23: Pza. | E23: 6 | F23: =+E23+D23+C23 -> 6 | G23: Pza.
A24: 1520 | B24: Pza. | C24: 98 | F24: =+E24+D24+C24 -> 98 | G24: Pza.
A25: 1531 | B25: Pza. | C25: 98 | F25: 98 | G25: Pza.
A26: 1038 | B26: Pza. | C26: 386 | F26: =+E26+D26+C26 -> 386 | G26: Pza.
A27: 1013 | B27: Pza. | C27: 193 | F27: =+E27+D27+C27 -> 193 | G27: Pza.
A28: 1201 | B28: Pza. | C28: 3 | F28: =+E28+D28+C28 -> 3 | G28: Pza.
A29: 1504a | B29: Pza. | C29: 3 | F29: 0 | G29: Pza.
A30: 1335c | B30: Pza. | C30: 97 | F30: =+E30+D30+C30 -> 97 | G30: Pza.
A31: 1203 | B31: Pza. | C31: 68 | F31: =+E31+D31+C31 -> 68 | G31: Pza.
A32: 1209 | B32: Pza. | C32: 123 | F32: =+E32+D32+C32 -> 123 | G32: Pza.
A33: 1310 | B33: Pza. | C33: 3 | F33: =+E33+D33+C33 -> 3 | G33: Pza.
A34: 1302 | B34: Pza. | C34: 126 | F34: =+E34+D34+C34 -> 126 | G34: Pza.
A35: 1329 | B35: Pza. | C35: 126 | F35: =+E35+D35+C35 -> 126 | G35: Pza.
